Workbook
Name ACOES_EMITIDAS: Dashboard!$C$8
Name APLICACOES_FINANCEIRAS: 'Balanço Patrimonial'!#REF!
Name ATIVO: 'Balanço Patrimonial'!#REF!
Name ATIVO_CIRC: 'Balanço Patrimonial'!#REF!
Name ATIVO_OPERACIONAL: 'Painel de Índices'!$C$34:$J$34
Name ATIVO_REALIZAVEL_LONGO_PRAZO: 'Balanço Patrimonial'!#REF!
Name ATIVOS_NAO_OPERACIONAIS: Dashboard!$C$11
Name ATIVOS_PARTES_RELACIONADAS_CIRC: 'Balanço Patrimonial'!#REF!
Name CAIXA_E_EQUIVALENTES: 'Balanço Patrimonial'!#REF!
Name CAIXA_EXCESSO: 'Balanço Patrimonial'!#REF!
Name CAIXA_EXCESSO_2023: 'Balanço Patrimonial'!#REF!
Name CAIXA_OPERACIONAL: 'Balanço Patrimonial'!#REF!
Name CAPEX: 'DRE + DCF'!$C$108:$J$108
Name CAPEX_2024: 'DRE + DCF'!#REF!
Name CAPEX_2025: 'DRE + DCF'!#REF!
Name CAPEX_2026: 'DRE + DCF'!#REF!
Name CAPEX_AQUISICOES_2024: 'DRE + DCF'!#REF!
Name CAPEX_AQUISICOES_2025: 'DRE + DCF'!#REF!
Name CAPEX_AQUISICOES_2026: 'DRE + DCF'!#REF!
Name CAPEX_CD: 'DRE + DCF'!$C$113:$J$113
Name CAPEX_CDS_2024: 'DRE + DCF'!#REF!
Name CAPEX_CDS_2025: 'DRE + DCF'!#REF!
Name CAPEX_CDS_2026: 'DRE + DCF'!#REF!
Name CAPEX_NOVA_LOJA_2024: 'DRE + DCF'!#REF!
Name CAPEX_NOVA_LOJA_2025: 'DRE + DCF'!#REF!
Name CAPEX_NOVA_LOJA_2026: 'DRE + DCF'!#REF!
Name CAPEX_NOVAS_LOJAS: 'DRE + DCF'!$C$109:$J$109
Name CAPEX_NOVAS_LOJAS_TOTAL_2024: 'DRE + DCF'!#REF!
Name CAPEX_NOVAS_LOJAS_TOTAL_2025: 'DRE + DCF'!#REF!
Name CAPEX_NOVAS_LOJAS_TOTAL_2026: 'DRE + DCF'!#REF!
Name CAPEX_REFORMA: 'DRE + DCF'!$C$111:$J$111
Name CAPEX_REFORMAS_2024: 'DRE + DCF'!#REF!
Name CAPEX_REFORMAS_2025: 'DRE + DCF'!#REF!
Name CAPEX_REFORMAS_2026: 'DRE + DCF'!#REF!
Name CAPEX_TI: 'DRE + DCF'!$C$115:$J$115
Name CAPEX_TI_OUTROS_2024: 'DRE + DCF'!#REF!
Name CAPEX_TI_OUTROS_2025: 'DRE + DCF'!#REF!
Name CAPEX_TI_OUTROS_2026: 'DRE + DCF'!#REF!
Name CAPITAL_DE_GIRO: 'Painel de Índices'!$C$36:$J$36
Name CAPITAL_DE_GIRO_RL_2023: 'Painel de Índices'!$J$37
Name CAPITAL_GIRO_2016: 'Painel de Índices'!$C$36
Name CAPITAL_GIRO_2017: 'Painel de Índices'!$D$36
Name CAPITAL_GIRO_2018: 'Painel de Índices'!$E$36
Name CAPITAL_GIRO_2019: 'Painel de Índices'!$F$36
Name CAPITAL_GIRO_2020: 'Painel de Índices'!$G$36
Name CAPITAL_GIRO_2021: 'Painel de Índices'!$H$36
Name CAPITAL_GIRO_2022: 'Painel de Índices'!$I$36
Name CAPITAL_GIRO_2023: 'Painel de Índices'!$J$36
Name CARTEIRA_CREDITO_GUAR: 'Projeções - Receita Financeira'!#REF!
Name CARTEIRA_CREDITO_LREN: 'Projeções - Receita Financeira'!#REF!
Name CARTEIRA_CREDITO_SETORIAL: 'Projeções - Receita Financeira'!#REF!
Name CARTOES_TOTAL_2023: 'Projeções - Receita Financeira'!$J$12
Name CARTOES_TOTAL_2024: 'Projeções - Receita Financeira'!#REF!
Name CARTOES_TOTAL_2025: 'Projeções - Receita Financeira'!#REF!
Name CARTOES_TOTAL_2026: 'Projeções - Receita Financeira'!#REF!
Name CMV: 'DRE + DCF'!$C$14:$J$14
Name CONTAS_A_RECEBER: 'Balanço Patrimonial'!#REF!
Name COTACAO: Dashboard!$C$15
Name CREDITOS_TRIBUTARIOS: Dashboard!$C$12
Name CURVA_MATURACAO: 'Projeções - Receita Varejo'!$C$21:$C$24

Sheet Dashboard
B6: C&A Modas S.A | F6: =VALOR_ACAO -> 14.479339 | G6: =H6-0.005 -> -0.02 | H6: =I6-0.005 -> -0.015 | I6: =J6-0.005 -> -0.01 | J6: =K6-0.005 -> -0.005 | K6: 0 | L6: =K6+0.005 -> 0.005 | M6: =L6+0.005 -> 0.01 | N6: =M6+0.005 -> 0.015 | O6: =N6+0.005 -> 0.02
B7: Ticker | C7: CEAB3 | E7: Lojas Abertas por ano | F7: =F8+2 -> 23 | G7: 18.284661 | H7: 17.365304 | I7: 16.509127 | J7: 15.709973 | K7: 14.962454 | L7: 14.261836 | M7: 13.603947 | N7: 12.98509 | O7: 12.401981
B8: Ações Emitidas | C8: =(308245068-5880734)/1000 -> 302364.33 | F8: =F9+2 -> 21 | G8: 18.12111 | H8: 17.213611 | I8: 16.368405 | J8: 15.57942 | K8: 14.841346 | L8: 14.149518 | M8: 13.499822 | N8: 12.888614 | O8: 12.312658
B9: Valor da Firma | C9: =SUM('DRE + DCF'!M128:Q128) -> 5863118.8 | F9: =F10+2 -> 19 | G9: 17.957823 | H9: 17.06217 | I9: 16.227922 | J9: 15.449096 | K9: 14.720457 | L9: 14.037409 | M9: 13.395897 | N9: 12.79233 | O9: 12.223518
B10: Dívida Bruta | C10: ='Balanço Patrimonial'!L44+'Balanço Patrimonial'!L51+'Balanço Patrimonial'!L56+'Balanço Patrimonial'!L62+'Balanço Patrimonial'!L67 -> 3161920 | F10: =F11+2 -> 17 | G10: 17.794802 | H10: 16.910982 | I10: 16.08768 | J10: 15.319001 | K10: 14.599788 | L10: 13.92551 | M10: 13.292173 | N10: 12.696239 | O10: 12.134563
B11: Ativos Não-Operacionais | C11: ='Balanço Patrimonial'!L9+'Balanço Patrimonial'!L10+'Balanço Patrimonial'!L23+'Balanço Patrimonial'!L28-'Balanço Patrimonial'!L75 -> 913136.86 | F11: 15 | G11: 17.632047 | H11: 16.760048 | I11: 15.947681 | J11: 15.189138 | K11: 14.479339 | L11: 13.813822 | M11: 13.188651 | N11: 12.60034 | O11: 12.045793 | P11: =F11 -> 15
B12: Créditos Fiscais | C12: 763700 | F12: =F11-2 -> 13 | G12: 17.469561 | H12: 16.609369 | I12: 15.807923 | J12: 15.059505 | K12: 14.359111 | L12: 13.702345 | M12: 13.085331 | N12: 12.504635 | O12: 11.957209
B13: Valor do Equity | C13: =VALOR_FIRMA-C10+ATIVOS_NAO_OPERACIONAIS+CREDITOS_TRIBUTARIOS -> 4378035.6 | F13: =F12-2 -> 11 | G13: 17.307342 | H13: 16.458945 | I13: 15.66841 | J13: 14.930105 | K13: 14.239104 | L13: 13.59108 | M13: 12.982213 | N13: 12.409124 | O13: 11.86881
B14: Valor da Ação | C14: =VALOR_EQUITY/ACOES_EMITIDAS -> 14.479339 | F14: =F13-2 -> 9 | G14: 17.145393 | H14: 16.308777 | I14: 15.52914 | J14: 14.800938 | K14: 14.11932 | L14: 13.480027 | M14: 12.879299 | N14: 12.313808 | O14: 11.780598
B15: Cotação | C15: 11.37 | F15: =F14-2 -> 7 | G15: 16.983714 | H15: 16.158865 | I15: 15.390114 | J15: 14.672004 | K15: 13.999759 | L15: 13.369187 | M15: 12.776588 | N15: 12.218687 | O15: 11.692573
B16: Upside | C16: =IFERROR(VALOR_ACAO/COTACAO-1,0) -> 0.27346868 | G16: =H16-0.005 -> -0.02 | H16: =I16-0.005 -> -0.015 | I16: =J16-0.005 -> -0.01 | J16: =K16-0.005 -> -0.005 | K16: 0 | L16: =K16+0.005 -> 0.005 | M16: =L16+0.005 -> 0.01 | N16: =M16+0.005 -> 0.015 | O16: =N16+0.005 -> 0.02
B17: TIR | C17: 0.30086078 | G17: Variação do DI

Sheet CB_DATA_
A1: Crystal Ball Data
A3: Workbook Variables | B3: Last Var Column | C3: 0
A4: Name:
A5: Value:
A7: Worksheet Data | B7: Last Data Column Used
B8: 5
A10: Sheet Ref
A11: =CB_DATA_!#REF! -> #REF! | B11: ='DRE + DCF'!#REF! -> #REF! | C11: ='Projeções - Receita Financeira'!#REF! -> #REF! | D11: ='Projeções - Receita Varejo'!#REF! -> #REF! | E11: =Dashboard!#REF! -> #REF!
A13: Sheet Guid
A14: f06a8309-f4cc-4db3-9700-7b59148c86ce | B14: 721bbdf0-98dc-46f2-a6d5-d01614a3bb8f | C14: 2fd5d0dd-ed98-43c4-acc2-c8d54ef51158 | D14: 2f2aa0ed-12a4-4992-81dd-da990bbbf91a | E14: a78e4722-ba61-496f-8aea-7eab1baa3de2
A16: Deleted sheet count
A19: Last row used
A20: 34 | B20: 31 | C20: 31 | D20: 31 | E20: 31
A25: Data blocks
A26: CB_Block_0 | B26: CB_Block_7.0.0.0:1 | C26: CB_Block_7.0.0.0:1 | D26: CB_Block_7.0.0.0:1 | E26: CB_Block_7.0.0.0:1
A27: 㜸〱敤㕣㕢㙣ㅣ㔷ㄹ摥㌳摥㕤敦慣敤搸㡤搳㑢㑡㘹㕤㑡㈹挴挱㡤搳㠶㔲㈰〴㕦㥡㑢㜱㘲㌷㜶㔲㄰愰捤㜸昷㑣㍣捤捥㡣㍢㌳敢挴愵㔲㉢㘸戹㔳挴㔵ㄴち㔴〵㔵攲㠵换ぢ昷ㄷ㉥ㄲ〸ㄵ㠹〷㜸〰昱㔰㄰〲㈴㄰㡡挴ぢて㐸昰㝤㘷㘶㜶㘷㜶扤㘳㜷摢㠲㡢㝣搲晤㝤收摣收㥣昳㕦捦晦㥦㘹㑥攴㜲戹㝦㈳昱㉦㔳㥥㤹敢ㄶ搷晤㐰摡ㄳ㌳㙥扤㉥慢㠱攵㍡晥挴㤴攷ㄹ敢㜳㤶ㅦ昴愱㐱戱㘲愱摥㉦㔴㝣敢〱㔹慡慣㐹捦㐷愳㐲㉥㔷㉡改ㅡ敡㌹〸㝦㈳昱㠳捥㕥㠳㜹㠰愵㤹改昹攵晢㌰敡㘲攰㝡㜲晦搸搹戰敦攱挹挹㠹挹㠹㐳〷敥㌸㌸㜱㘰晦搸㑣愳ㅥ㌴㍣㜹搸㤱㡤挰㌳敡晢挷ㄶㅡ换㜵慢晡㔶戹扥攴㕥㤰捥㘱戹㝣攰戶㘵攳昶搷㑦摥㝥攸㤰㜹攷㥤慦ㅦ挴慢㜳愷㘶愶ㄷ㍣㘹晡㉦搰㤸〵㑥昹昶㔹㔹戵戸㌶㈹㍤换㌹㍦㌱㌳㡤晦ㄲ昳挷搳ㅤㄳ㡢㉢㔲〶㝣戵昴愴㔳㤵扥㡥㡥〳昶㤴敦㌷散㔵㙥㥥㙥ㅦ挵㔲慢㠶ㅦㄴ散ㄹ㔹慦敢㜶㍣㙡挹㥥挷摥搵㡤昵㐱㝢㔱㍡扥ㄵ㔸㙢㔶戰㕥戴㤷㌰㔰㙤挸㍥攳换搳㠶㜳㕥㥥㌲㙣㔹戰㡦㌵慣㕡㍥㑣戹扥㕢攲㈱㤲ㄳ㔳换㥦㤸昲敤㤹ㄵ挳㔳㌳昲戹㌱ㄹ㙤㡦㝡搵㜴摢㥢扡㡦换愹慢㌷㜰捣㥢扢户㐳捤㔹挳㙢戶ㅣ敦摥㌲㕡㝣㝡〶户㜶㙦㥦搸愳㜴㥦搷㜴敦愳戶㌲摤㕡っ㐴昴慤㜶ㄴ㡢搱㡢〴晤〴㈵〲㈲㔰㉦ㄳっ㄰っ〲㠸晣㍦挰㈵挹㡥慣搲㉡㠶㔶㔹搶㉡㔵慤㔲搳㉡㔲慢㤸㕡攵扣㔶㔹搱㉡㤶㔶戹㑦慢㕣㐰㥢㌸㤵晡晢戵㈸昵扦敥搷㕦昸搱挷㝦㍢晢挹挷昶晤攵ㅢㅦ㙡晣㝤㜰ㄷㅡ摤ㄳ㑤㙡搶㌳㉥㠲搴㕡㔴っ㡥攰扦捤戹〲㑣㘱ㅥ㌲敦㌰㈷㈷㙢㠷づㄸ户ㄹ〵㉥㉢〳昹㈹㐲ㄹ㐱摢㐱昳㕥换愹戹ㄷㄵ敥慥㥢㌶㝣搹摡戸昱愸㙥摡㙤㌸㌵晦㘵ㅢ㔷㉥〶㐶㈰慦㙤慦㙢つ搲搱㙤ㄱ㙣㈵㝤昵扥敢摢扢㥤㌵敡つ㌹㜵挹ち慢㕦摥㔶㙤㉦㜸敥㜲昷摡愳㥥扣扦㔹摢㌱愳㈹〸戵㌵㌵㜶挷㉡挳慡㜰㕥㘳㌳㉢慥㉦ㅤ㌵扤㜱㝢挱慡㕥㤰摥愲愴㐸㤴㌵戵搴㉢㔹ㄵ㜱晤昸扣㠳㠵㠲㕢㙢慦㐸㤶㥡㜷㕤ち挰捣戲㠶昹慥㑡㉦㔸㕦㌲㤶敢昲慡㔴㤳昰㥤愸搸㥢㉡㍥敡㔶ㅢ晥㡣敢〴㥥㕢㑦搷㑣搵搶っ㐸㥡摡㐹户㈶昳昹㥣ㄲち㄰戸㝤㝤㐲攴昶㜵攷〵㠵㠸〴㡡挹挸搷愴挹㙥攲㌴㔶㠷㔵搴㈵㘹㔲㝢攵㈶㠳㜱扥㑡挶㘴㜰㘰㘲㑤搴ㅦ㝣改慢㌷ㄹ戶㠹戹ㄷ户戱愶㡤㐶慢扦㙢㑤㍡挱㜱挳愹搵愵㤷愹晤〴㘷愴て〳ㄴ㉥㐳㈰㜴摤㍤慡㍡㜱㐹慣ㄷ㉥㕡戵㘰愵戸㈲慤昳㉢〱捡愰㈱㑢㈵㙥㙤㐷搲慦㐰㤱扥㥢㘰ㄴ愰㕣捥ㄵ昷戰㔱戱㡣㤴㉢㔰㍡㘵昰㜲㑡㤰戳㕦㡡㤷〷捤愳㔶㍤㤰愱㔰ㅥ㌶㠱㤱㔰慢㈹昴つ㤱㐴㍤愳ㅡ㉡㡣㍤收っ愸搴戰㥣㘰扤挵户ㅤ㕣ㄲㄲ搱㡥㉣搸㜶戲㠰愲㈰㉤て㌲㜸つ㐴搳㈶つ戲ㅢ㈷㠸㠸㙣㤰愱搹㌱㜲㥡挸搸㍥㐳㐶愰㝤㤲〸搹晡㐰㜷ㄹ㐱㘲敦㈴㔲㜶敡捡㡦㍢搲㙣㈳㕢㍥㤴㘶㔷㘲攳昴慢〸慥㈶戸㠶㘰㉦㠰昸ㄳ㈴ㅣ愵ㅣ昲改愴扦っ捦晡㜵〴㉦〷㠰㝣搲㈹㜳㈲㔱㐵ㅢ㙡㉢㜶㈴摢つ挱㑥㔶㐶㜱㈸㡡㘸ㄹ㌷敤捣㈱㕢㈱㍡戲㍡户㠷慥捤㉢ㅤ晢慡敥戴㤹㕣づ㈹㌲愳㘹㜲慤㥢㌴㑤㙥〴㥢昶愸户㙥㐰㔷㝤㡣攰㐶㠰戲晥ち㐲㈸ㄷㅡ扣㕢戳攸㘹㔲扥㈴捣愲搰ㄸ敡㔱挱㐷㠴捣㈳㐰㠶㤰敢㌸扥散搸搰㌴〷挷捤㤷扣つ扤扦㍢㝦㐷㐸㙦搳㥢㍢㝡㠷晥愲攷㘸㐵摦〴昶ㄲ扦敢慡㘳㙥㐶戵晥㉡㠲㕢〰摡㜴っ㑦摦捦搵㔳愰捣㘲㍢㠱戹摤昴扡㈸㉢㜷㘹㝤㔵㉡つ㌴㘸㉥ㄹ摥㜹ㄹ挰㠳㜱㘲ㄶ戶戰敢㜹戲㡥㐳㙤㑤ㄵ昰晣㜲㜵扡搰㍦敡戹㌶换㜷㙣㘴晦㈵愱ㄸ昲㜹慤㉦搷㘶㈳㘷搸㥡〹㥦㔳㠲㜲愸㠳㙦敢㉥㈴ㄲ㥤搲攴挵㝥搹攷换ㅤ㐹搲㠳㈴㜹つ戶㔵摦〷〰㈹㈱㝥摤㔵愲散㘷戳搷慡㘶㘹㡢㤵ㅥ扥㡣搳㐹㥢て戱㐳㡥っ㠴づ摢㘹昸て晣㈱㝢搱戲㥢挲㘲挰㕥㤰㕥ㄵ扥〵慢㉥换愱㕢㤶愲㘶㐷㔶扣㐴㘴㐵㕦㕦挷㜹㍡挳扦愶攸愴㑤㑡㘴㜲㝢㘶㘵挶㔹扣㐵㔴㜴㐳㔲愸㘴戸㠶㥡ㄲ㠸㤴挷戶㍢㈲愶〷ㄱ㜳㉢㌶㑥㍦㐰㌰㐹㜰㄰愰昰ぢ㐸㥡慤㙥㍣挳㘱晤㙢㜴㘹㔷㉡戹ㄲ搱愰㕣㠴捦㜴ㄵ㔶㠷昸㥡搷ㄱ摣〱搰㘶晥搰〱㤹㐱㠸ち攵〹㐲㔴㘱っ昳慣㈵㉦㤲〶㜶㤹〸㉣捤㌴晣挰戵ㄹ㔹ㅡ㌲㘷摤㔳㙥㌰㙢昹慢㠸㐴㡤㥡㔱收摥ㄵ改㠰扡㍣搸㍥㙤㘵敥敡慡慣改收愲摢㠰㘸㍢㌱扢ㅤづ收搸づ搸㤲敡㙣慥〹愴摥捥挷ㄸ㐲㘰愷㤵扦㤵摥搸㉤㜹扦㜹攸ㅢ㙥敤攸㤲ㄵ搴攵㠰ㄹ㌲ㅤ昳㈵ㄳ扢㠸挸㐱慤摦㕣㕡昱愴㥣ㅤ㌲㡦㜹㔶慤㙥㌹㤲挸㠰㡤挹㘰摤㥣㍣㡦㈸挱㠲换ㄸ愰敢っ㤹㑢㥥攱昸慢〶〳㡡敢扢㔳㑦㉡㉣㔲㌰愷㉤挷挷㙢ㄴㄶ㤹ㅦ㌶ㄷ㔷摣㡢㠸搸㌶㙣攷㤸戱敡㙦ぢ慣㤰攸挳愴㔰㈳㌴愱㘹愲愴㤵㝡挵てて攴戹ㅣ㜹㉦㑦愰㜰㤵㉢搰㘷㥥愱扤㘹搷㐷㌱ㅡ摡改㥣搳㈰愲㐷捤挲扥㑣㈹㑣㑥搵敦㘴㥦㌷〰摣㝤散捣㠹㔶㘴敥㜹挵慣ぢ昴昲㘷挸㜸㐵ㄶ捤㐰〸㝤㜴扢㐲㔲㘱ㄹ㈹〷ㅣ〸㡣昳愹㥤晣捡愶㙡㐳敡摢搵捡ㅥ㐵㈴㘹搰㥣㌳㤶㘵ㅤ昱㘸摢〸㜶㠵て㌴㘳㙤愳敥㐷㜵㌳慥㙤ㅢ㈴㉤㤲攵㘲搵㈰〵㑦㌵〲昷愴攵攸㈶㠰愲扦愸挸戸㠴㈲攳㤲㉡ㅡ㌴㑦㌳㌴愸昲ㅣ换㍤㙦㜸㔶戰㘲㕢搵ㄲㅦㄸ扥摢ㄶ㌴〹㈶愷攴㡤㔳㉣㌳挶摡慣昹㌳㌰搹晣〹愰㝢〲㜲㤴㕢㐷昴㠳㜲㌵㔱挴㍦搱愳㘳〹〲㐶㜹㑡昵㌷㘱戴㠲扡ㅤ〱㤱愳搲攵昸づ挶攵㠷㔰ㄲち㈱㘲㍤㠳㐴攰ㄵ㑣〸㜹扡戸㡢收ㄹ挷ち㠰㍤㘲散愸ㄵ捣晡㐰㌹〰戲敡㜸㝢慤挲㙡愲搳㜸㔳㉢摣搰㔹㤵㔲ㄳ搷㜷搶㈷昵挶㉢㌷愸づ㌵㑡㐲㤱㙣搶㐸㘹㤶つ收戸㥤㔴㡤㔰㡡㍢搶㌶㈲换㙤摡摡㜷㑡㤱攷愱㤸ㄴ捤攴昴㌷㉢㐲㐱愰㌷搲㔱昴搹㘷㤳㐷㈲㘲㐳ㅢ愰㑣㍤ㄵ㤶つ㐵㈱挱ㄳ戸㜶㔲㤳攵攸〹晣扤㉢捡捥㌷㠲㔴㡤㜱㘹㌴慡㤹慡搷攷ㅤ㔸〹㔵挳慢㙤ㄳ㤶挶摡㐲つ愳戸戳㔷敤ㅦ㙥㙦㠲ㄱ㈳㌶㘴㔸㈴挳てっ㌶〴㜳㈵㈲慡戴捥㠶戸搵捤攲ㄲ㥦㑥㑡挳㔱ㄸ㔸っ㙡戳㜲㑤㤹㘱㉤㑢㝥㔴㜵㘸㥥ㄶ㤵ㅣ搵捤愹㘵ㅦ㉡㍤愰ㅣ㡦㜲㡡挱㜵昳㌴摤㔲戸挴〰戱ㅢ攵ㄶ慡〱㐲扢捤〱㜸㌲搸㍥搸挱㡥㠴愱ㄳ㕡㘷㤴愰挵っ挲㑤㉦㠲扣搳㈳㐶㈱㐸㑤㤵晥㝥㐴㝣敥㜱愶慦ㅥ挹挵㤹㠸㠹ㄸ敥捡戰ㅥ㠰摣㘴㘴㤲㕣㌴ㅡ〷捣㐳挹愶㠴搶㘰㕣㐶ㄳ㘳㠸㈶㥦ㄷ攰ㄶて㘳㔹挳㘴㥢㍡敥戹〵ㄶ戴㘹㝤㝤㤷㜹挲愹搶ㅢ㌵愹㔴㜱㉣慢㤵㐶摥ㄶ昸㔲㔷〰㐳㙥捡搸㤷㘸㔳㑥攰㈸挵㈵ㄳ㐹扤摢摤晡ㄱ㜴㔷㐲づ㘳㠴慡㡦〱挸っ户㥣ち㠸㜵摣㔳愰㝤戸扢㜵㠱㐱㕤㥥㠳㐸敢㈸愲㉣㥢挳㝤扣㘶ㄴ㔹㜱㕢愲搹㥣㍢攷搲㘶㑦ㄴㅤ户挲愲㙤㠱㈳慣㌳ㄴ㜸挵㈲㡣㤱ㅥ戹㠳㠳攴㉥㐷搱摤换て愹挷摣㘵愰㐲㘱㐰㌰挶换㔳㔰づ扢ち㐶愲挱慤戵慣㙥挱攸㉦㉤㙦㝤ち㐰㌰っ㑣㠳ㄶ㉤㐳〳㘷〶昹捤つ㥣ㅢ搰㉡㈳㐲㥡っ愶㌲㐶㌹ち㠷㍤㤰〶㙥攲㐱㝡挹㠵ㄲち昶愸㡢㘱昱摤挴㜱ㅢ㐷㈰搷扢慡慤㜰挱〸㜰晤挵搹摢㔶㍣㔵慢搱摣㠵㝦㙥㕢㘰ㄵ㔷㌷㐲㜳㜴㑦摢愵㉣戵㈶摡㜷㌷戵㔵㐴㤷〵て捥㑥ㅣ㌷㠲敡捡㘲戰ㅥ㕥摣敡㤵㈴ち㍦㠰㍦㘲挳户搳㘶捥㍢扣㠸扡挶扤㉦㕦㜰摣㡢㡥㥡㔷挱攷慤㍦㔰〸慥㔰昶㜳㤲攵摣扦昱㑦㈵㉤㔷昸㍥㐶摣捡戴㌹㐰换㐱挲㜱㔴ち愵挱ㄸ昲ㄹ㜴〲摢扤㜹㙢㠰㜴戲愷㡤㑥㤴㈰搸㈱ㄴ攷晣ぢ㐶㈸攲㝢㐰㉢㠹㈵㍣㤲㘳捦㥦〶敢㡢敦愲㠴〸挷㜳㈴㐶ち㌷㈲㤷㠱㍡㈵挸愳㉢ㅥ扣㄰昲晦㠳愵㤸㥢㌷㘴愷晦〲㌳㡢敦戴愳攸㝡愲攸摢ㅤ㈸ㄲ扣〶愲昸昷㙥㘴攲㔴㘰㜸昶㌹〵挲戹愶㥤〳攸㡢㝥攱昷㝦㜸〰㥤㡢㠸㐳搹㘸〸戵摤㡣攷愶㠹搰搷㘱㈲㌰㜸慦㑣㠴㤳挸〸㐶昱㐳ㄳ㈱昲㠱捣愳㘰㜳ㄳ㠱戱扤っ㐳㌰ㄱ㙡㑤戸㌵㜸〲扢捡愶㝦散㌸㉥摥㑡ㅦ昱㝣㈸㉤㝦〶ㅥ愹慢㍢㡢ㄷっ捦戰昷慡昲㘳㥥㠴㌲昳㤶㜰㤳㕢㜵㘱㡦㙢㌷慣㔱㥤㌶昰㔵挴㕥昶ㅤ㝦捡搶敥慦〳㔳㘱ち摤昷愲㈴㡡捦挳㔳㈲㜸㙥挸扤㝢捦搷㡥晤晥㠱㐷㡥昰戶㕡㐴慢㠵㝤挸昷ㄲ戲愷㍤㠱愰㙥攲愲挸㤵晣㌰攷㈴㍥㔱戲㔶敢㜲摡昰㤴ㄵ攴敢㜶㥣つ〹㉦㐱㤸㈱昱㙤〷ㄳㄳ昷ㅥ㐲ㄳ㜳愲捤摤愹㍥㙣㔲㉥挲㠹挴挴㤵㑦㉦づㅢ㡡慥㡡慣㐷㙢戳昰つ愸愲攷㌸㤱戴㤵挸㔳㈷㤳㄰㕦㙦搷㜵㠷愸敢挲㠳っ挳晥戱㤴㐲晣㠱ㄴ㤲㍣挸昰㐲㠰㤲㔲愷㤱㈹摣ち㤰ㄱ㔹㙢て昱搲ㅦ戰㈳〴㘴昳搲㕦㡦ㅦ戱㘰ㄷ㠱挵搸ㄷ摦敢㠹㤶戶㘸慣㥡ㄸ慡㔵㌶捤㈲㌲敡昰挲㠲挹戸㌴㘵改ㅣ㐴改㤶摤㔱㝣挹㤰ㅤ〶摥㐲挶㉥搸昴戵㤵敤扢㥣〶㙥㝥㐰捦ㄴ㤵挲㜰㜶戳ㄸ〷㔲ㄵ愳ぢ㥢㤶挳㈲挲攱㌰摢散㌴㄰㔵㐱㘷㌹㝢㜱㉡㐵昰㡦㕦ち戱㝥扣㌵昴㤵敤㌵搴㜱㑥㍦ㄶ挸ㅦ散慦敢㌳ㄸㅢ㙦㈵挷㐰挲㙥愹㔵㈹扣ㅥ㝥〶㕤戸攸㥣搰㕢㔹昵㉣づ攱㑦捣㔹㝤㕡㠷晥㘷昴㕡㜱搶㔹昶㘶ㄸ㍢愵晦摦㠶㠲㑤昵扦㘰散㑤㈱昲敤㔱㠶て〵挶㑦㌶つ搹㜰㐷攰搹㐶昰㐶ㅤ㡣㜵㤵㘵挸㍢捣㉤攲攳搵戰㕡㐹㜰昸扤昲敤㔷㈳㥡㝤㘹摢づ㜴ㄵ㠰㡣つㄵ㥥㠶〸敡摡㍦㉤户攲搳㙤昱ㅤ攸戸攷愴㔵昵㕣摦㌵㠳戱㐵〴㝤挷昸敤㤹〹㥢㘷㑡㝣愵㕤愸摤㠴㥤ㄸ㝣ㄷ晡㥣㥡㠷挰㍥㈵㠳ㄷ㉡ㄶ挹挸挲搶㈲ㄹ晣づ㘹㈴ㄱ㕥愲㜶昰慦㌰敦㘹ㄸ㜵㝣扡㍡て㕦㘷挰愲㙤愱散㐲㡦㜳晢つつ㙥ㅤ敥㘸扤ㄵ晥㈰㔹㥦㐰㜰㑣㉤攱ㅤ敦攲扥戶敦㐱扡㙤戴㌶㥦㉤㝢昳戹㤵ぢ㑦〱愷㕢㝢㑢㥡㘴昸㑥㝥㤱㕣搶㉢㠴戸戴㝦〴㝦户敥愰攵㘸愳愰昳攸㠳㙥㍡挲挶敢㜰㥦㙤㈱晡㝤づ㕤挵ㄴ〱㝥扡ㄱ㘵昸㈰攸攵㈳㉢㡡㉦㘲㔹㘴〰攴㜳挵㉡㐰㜷慡㝥㘲㈳慡ㅥ㠹〵戲攰ㄹ㠳攴㔸ㄶ㥦㐷㐳㙥㔷戸㙣戰〴㤷㉤搴㔹〲㜹㍤敥㠱㝣㑥昰㉣愱㈶昲㔹㜴㘸㑥挴㐲㘹昷㠹㝣㘶愳㠹〸㕡〱㙡愱挹昱㐷㘲㉤愲搷㔱慤摢〴づ㠱ぢ㌰㑣戱㐸㔹㔳っ㐳ぢ摦㈵㘶㤰㝥ㄹ晤㝤昶挸㉦㥥㘱晡摢ㄱ愱〴㈱慡搲㤳愷㈰㔴㤳晦㔸㜲昲ㅥ㑡扢㑦晥愳ㅢ㑤㝥㠴㌲㤲㌳搱〳㠰愱㍥㔱挱ㅦ戵㤸〶㌲摣㐷晥挴㌹〲晣㔲戳ㄸ㌱㔰愲晡㕥㐴〶㝤戹攱慡搵㈵㘴攲扥〵慥㍦攳攳ㅥ㘵ㅦ昱㈲㈴㝤㌹挵搰ㄹ㕢っ戵㘲挹㡥扣戰摢㐲㌶㘰㐹晣㕡戶慢㐸㉦昶ㄸ攱ㄷ敦㡦ㄱ㜳晣㜸晣攵㤴ㄶ挵㥣㐰ㄸ愱㐵㑡晡攱㐶㡡昷挵㡤扦昹慤㤶换ㄴㄵ㐸愰㥥戰㌱改㑣㌵㝥㌴㙥㝣㄰㕦㘵愹㌶㌹摥㈰㘰㝡㌶㙥㑣㝡㔴㡤ㅦ㠹ㅢ晦昵攰摥㘶攳㤸づ挳㤱ぢ㈴㤲っ㕢㔷㔹晦㠹㉦戴㠷搱扣㘰㔲㝦づ㤸㘱㌱㈵愷ちㅤ搷㤵〶ㅤ挴㘵㄰て摦㐸捦攱㙥ㄳ慥㠰㐰挸㠶晦慢㠴ㄳ戸昳㌴㙢〴〶㍥㠱㕥㐳戰搹搳搵ㄳ㍢ㄷ捤㜹て〵晤收〹ㅦ㘷慡摡戶㈲ㄱ㤸〳昹㜰㝦㌷㜱捡㘷㤸㡥慤晤㠸㠳㘴ㅡ敦㤰昴愶㍣㔴㘰㈵㉦摥ㄳ㘳㌶昷㜰㡢㘶昴㠷㠰ㅣ㐸㐷㐰㘶昴㠷〱挳㐰っ㙦㉢攷㐶挸晦㡡戹摦挳㡡昷ㄲ㍣〲㔰ㄶ㘴㜶搲㐱昱㔱㠰㍤戰㔲昱扦慡昰挷㙡㜲㙣搵㤳㙢㤶晦攳㉦扢㥡㜸㈰㝥㘳㤲㤶昴昷戳搷〷〰晡攰挳ㄵㄱ㈵㤶昵て愲㈴昹㘶㑡て昵收て戳攲㈳〴ㅦ〵㈸ㄷ㌸攳㉤㙦ㅤㄷ搶愳晡㝡っ㕤挵挳〴昸改ㅦ㡢㌲㝣㈸㜰㌳摥搸摤㘰收㜹㌸晥扡ㅦ昱捥搴㘷晣㜷攱戳晣㜵㉥扡て晦㔷㤲㠲戲敥昳摡ㅢ㝡ㅢ㡢㥣㐰挳㕣晤㔶戱搹捦㘳ㅣ慥慢ㄵ㐶攱㠸搴㉣㈵慤㈸㠸㜴㉥㔸戸㜸〳摦㜲㔸㔵〸㐱㐲㔰ㄵ㑥㔴㜱〴〵晡㈷搹㤴㌸㈶㥥昴㑦昱㠹愸㔵㥢昸改㈸挳〷㐱扣慡敥昷㐵摤攳ㄷㄲ搷慡挲㙡㝢㈱昱慦㉡㔶㤲㉦㝣㥣㠳㈹㘴㈱㤳㔶㑤㐴㥡愲愱捦㈳㌳搴㌷捣戹摤㡢㥦㜶㐹㔴捦搵捥㥤晢攷㜰㝥散摡晣摢摥㌲昸昸戳㍦晦挳㈷㝥昵捥挳㝦晥搷ㄳ㑦晣敡㡦㥦㜸收㕦㍦㔸㍥晣搳愷㥥晡挹摤㕦㝡收て扢捤㈷戵㙦晤㜳敥挹〷㈷㉦㍣㜸扦㜹㘶摦戱〷摦㝥摦㍤㤳ぢ㔷㡣昷昵昵昷摦㌲晡戳㙢㕥㍤昲昰晤摦ㄱ㍦晣捤搵㡥㔰换挵ぢ搲搳攰戲搵㌴扥㠰っ愶挱ㄹ扦愸搳攰㜲搵㐶㉤㐷ㅢ㌵㡤㠲ㄲㅣㅢ㥣㠰慡㌰搲ㄵ〳晦〱〰ㄸ戶㥣 | B27: 㜸〱捤㕣ぢ㤸ㅣ㔵㤵敥摢㌳摤搳户㘷㈶㘹㥥〲㈱搰〴挲㉢挹㌰㤳㤹挹㐳〸㘱ㅥ㜹㐱㈶〹㤹㐹〰ㄵ挷㥡改敡㑣㈷摤㕤㐳㔷捦㈴㠳ち〸〴挴㈷㙦挱㈰戰㈲㈸㠲㈰㉦〵㐱攴ㄱ㜴㔷㔹㔶晤挰㘷ㄴ㜵摤晤扥㔵㘴ㄱ搷㜵摤㙦㤱晤晦㔳㔵改敡敥敡㤹㑣挰敦愳㤸㥣㌹昷摣㜳捦戹攷扦户㙥㥤㝢慢㠶㤰ち㠵㐲㙦攲攲㙦㕥昵㘴㡥散㥦戰㡢㘶慥愵挷捡㘶捤攱㘲挶捡摢㉤㕤㠵㠲㌱戱㌶㘳ㄷ敢愰㄰ㅤ捣愰摥㡥っ摡㤹ぢ捤搸攰戸㔹戰愱ㄴ〹㠵㘲㌱ㅤ㐶扤㜶晦㈵昶ㄶ搸㑡搷㤳㐰㉢愴愳㈴つ㈴㌱ㄲ搱㡦㤳㙢〴㘹㙡〲ㄹ攸改㕥㍦戴ㄵ摥晢㡢㔶挱㥣㥦摣散昸㔸搶搶搶搲搶搲搹扡㜸㘱㑢敢晣㘴捦㔸戶㌸㔶㌰㤷攵捤戱㘲挱挸捥㑦㙥ㄸㅢ捡㘶㠶捦㌲㈷〶慣㙤㘶㝥㤹㌹搴摡㍥㘴㜴㉣㘹敢攸散㑣㉦㕤扡愴愹ㄹ㤶搷昵㜴㙦㈸㤸㘹晢敤戲㌹㠳㌶搷昷㜴户慣㌳㡢㙦㤷捤㤹戰〹㤳扤㔶捥挸攴摦㈶愳ㄱ㡥㐱㘷慦㌹㥣攱㘰㤹㘶㈱㤳摦搲㠲㙥㤷〱㡤搲攲㤶㉥摢ㅥ换㡤㜲摣㝢捣㙣㜶愳㤹㤶㐱捡昵摡挵つ㐶㈱㘷㌷攵㠸㥦㔹㌰昳挳愶㍤㈳户㘲挷戰㤹㜵ㄵ敤㔸㙥戳㔱㔸㘷攴捣㝡㌲㌳㜳捥ㄸ慥㐹㤹昹㘲愶㌸搱㥣摢㘴㥢ㅢ㡤晣ㄶ㤳㉡㤱摣慡戱㑣㑡搵搷攳㈷㔴㜷㐲㔰捦㘴愰搰㥦㕣捦㠸㔱㈸㑡㠹㐳搸ㄶ愴敢㥢㉥ㄲ㐵㔹扦㌸愵㤲ㄵ慤㌸㘶晤㤹摣㔹㘶㈱㙦㘶改㠴㈳㌹慦㐲㐹〰㜲挶㘱㉦㔲㕥㌸ㅣ㈵搵攸摥㉣㡣㠵㕥愲〹㤰㠵敢慣㐲づㄳ㜲慤搵㌳㔶㕣搶㍡扦捦㌴昲换㕡㕢㍡摢摡摢ㄷ㉤改㔸扣戰戳㘳挹㤲搶昶昹晤挵㔴慦㌹㡥㡡搶戶㑥㝤〰摡改〳㘹攱㈰㤰愶扥敥挱㜱愳㘰㙥戵〶ㄷ㜶敡㠳㔹㜷〸㠸慡晦ㅤ敥㔶扦㑦摥㌱攱㐱㈳㍣㌸ㄴㅥㅣづて愶挲㠳㘶㜸㌰ㅤㅥ摣ㄲㅥㅣ〹て㘶挲㠳㕢挳㠳摢愰攳㕤戱㠶㠶戰㝢敤晥㡢扥昵慡㔷㘷昶摤昳挳㠵扢扥扦戳昰つ挵ㅢ㔴敥敦㜷㠱㌹搱㡤㘱㜵挶ㄷ挳㠲搶㤶昶昶㠵晥㡥㉦敥搰㠷㐱㕢ㅦづㄲ㍤〲愴戹搷戴㐷戱㈶攴㔳〶扢㍥㡢㤵㐷㠲㈸昵慦攸㍡扢㍦㜴昵慦㍥晣昲搷敥敡扡改收昴ㅢ晦昲昲散㝥挵㌵㐱晣ㅥ〵㘶摦晤ㅥ㑤搳㐹㤰攸㌱㈰㘵㝥㍢昴ㅣ㔶ㅥぢ愲搴ㅥ搷敦ㅤ〳㝦㝤攸攴愷〶㝡ㅥ㍢昰㤴㡢㠷㍦搹㝥愷攲㌲㈴㝥攷㠲搹㥦㌱㍢㥥㑥㑥〰㠹㥥〸攲ㅦ戳づ㝤ㄲ敢㑥〶㔱敡㈵户〳㍦敦㍥晦昴㥦㌶慤散扤㜴搷ㅣ扢晦搵晦㝤㔹㜱〹㤴づ捣〷戳敦㠱㉦愰改ㄶ㤰攸㈹㈰㘵㠱㉦搲慤慣㙣〳㔱敡〵搷敦搹扢搶㉦ㅤ摦㜸㔶摦搷㤷摥晦攳㔹て㝥昷愷㡡㌷戴昸㙤〷㜳㔲㡤㠱㙥㙢㙤㕦攲ㅦ改搶愵扡㠳戶㍢㐱愲㡢㐰攲㌲搲慢扡〶ㄷ㜶攸挵慣㔹〲愲搴㜷㕣慦㡦户摥昳换捥愳捦敡戹㌵昱收ㄱ攷㍤昰摣ㅢ㡡换扣㜸㝤㌷㤸晤㠱晢㔴㍡㌹つ㈴扡っ挴て昷㈲㝤㍡敢㤶㠳㈸昵㤴摢㠱敢㘶摤㝤挴㉦㝥㜰攳晡㕢慤㝦㑦摣㤶㍥㜳㡦攲㈳㐶㍡搰〵㘶ㅡ㘱㜷搳㜶て㐸戴ㄷ愴ㄴ㜶愷㕥挱㥡㤵㈰㑡㍤收㝡ㅤ扢攵㈷搷晦㜵捦〷㝡㉦戹敢摥つ搷晥捦㐳㕦㔱扣㐳挵敢㙡㌰搳昰扡㠶戶捦〴㠹㥥〵㔲昲扡㐸慦㘵㑤ㅦ㠸㔲て扡㕥攷㥡〷捤㝥㕥㉦改㝢戲戸㈰摡昲挲搳昷㌷慤㐷昵搹敥摡搴㕢㌰戶㘳戵㉦㍤㐸昰昴攴㝦㔳㍦㐱昱〰㑤㜷愶ㄷ愷摢摡㔲㥤慤㐶扢ㄱ攱㉡戵慦㑢㌵㔷挲愶昴㌹㤹㝣捡摡㉥㙢昷㤱摤㠶㙤㤶㤶昲㜹㙥㕤户㌵㤶㑦搹戳㠲㉢晢㡢㐶搱㍣愲戲慥㘴愴慡㔹㍦㥥㙣愶㉤晥㡥慡㙣戶搹挸㡥㤹㕤㍢㌲㑥昵散㡡㙡㍣搷慣愱摡戵㉢ぢ收〵㝢㙢慢㝡搴㠵㐴㘹㕣㙣㔷㐵改㔴㌹晤㑡昶㡣㔸戶㤹㤷敥捤换㙤挸っ㙦㌳ぢ晤㈶搳㉣㌳㈵愱ㅥ挲㉡昷攱㍡㙦㝤ㅥ㠱攲㜱㤹㥡攳㤷愶㔷散㈸㘲㜹㌵㔳攸敦愸㔹㈸㑥っㄸ㐳㔹昳搰㌲ㄵ挷㈷㉡づ㉦ㄳ慦戴㠶挷散ㅥ㉢㕦㉣㔸搹昲㥡慥搴戸㠱〷㝡慡捦㑡㤹㜸ㅥ搷昳ち愹㔰㕤㥤㔲愱㤳㠳ㅥ㡡戴㙢户挸㐰昸㠶㤸㡦攷挳捡愷㕤换㐶㐴㠷㈸戲㈶攷㘴昸戸㈹㡣㠹㕤㥡㌹愹戶愲㉦㈶收愴搴㍥戱戶戶昴㜱敦挸晤㝤㤵挳攱㠳摣攸㔷攰ㄱ㔸㕣㙤攴㔳㔹戳㌰㘹㐶慤搸㈳扤〱㈴㜲㍦敥收㥡攸昱改慣㜶愸㠹挸昶㑣慡㌸ㄲㅤ㌱㌳㕢㐶㡡㤰㈱敢㡥挵〸㙤搵愵㌷㐲愴晢㐹〶㐰攲昱㔰㜴ㄳ㤵愲㜱扤搹㈹㐷㤸㜰㑣㍦㥤㤲扣㕥搲㌷攴摡㜶㈴户搲㉡搸㜵㜵㐱㔱慥㌶散㤱㈲愷攷愴㤵㑣㥣昴㌹㈴攷㠲㐴㤸敥㑣㤹慤捤㠴㔲㍤㤳搲收㕣慦㤹㌶戰ㄵ㤰扢㕢ㄹ㤱㥣㤳㕤攲改㌴慣㤹㠶慥挱扤戲㈳ちづ㌷㝦㔳㡥戳摦摣㔱散㌵㡡㐶㐳づ〹㉤㐶㐹㐳㘹㥥戴㜲㌸戶㙣ㄶ㤹搷㍡敥㤶㘰㈱㈱慣捦㑡愳〸ㅣ㑢戸㜱㜰扦㠴敡㕣㍡㜹㄰攸㍢㔳捥㘸攵㐴㉦㑦㑣㤱㉦愷㔶㤹昹㠱㠹㔱㘴摢㔰㡦㐵㈷㠵戲昲昶愲戱昵挳㐳㥢㡡㤹慣摤㠲㥥慥㉡㔸㘳愳㙦愷ㅤ摡搲攷㠱㜸㔷攴㉥捣攲㝤㡦㠹㍢捥㠶㜱㡥捤攰㘰㈸㐶㙢㤴㘸㈶挱㥡戳ㄵ挶摥挴㉦戹昴昹昸ㄵ㥦慣㉥挲㉣㜹㍡㐹㍣㜳捦愶ㅣ㄰ㅡ㈸㤸戲㉤㠹㐹〱㘸㌷攷捥戱ち摢㠶㉣㙢ㅢ攷搳っ㈹搹㈳愶㔹㘴慡摦攸㙥㙤㘴ぢ愳㔴㕤㕤㔹㑥敥摢ㄳ㜰㥡㐶つ㤰搹〳㔶捡戲㤳昸改㉡㕣㌰㤶ㄹ〷㤳㌲㤳〳〵㘳挸挸㡥㔸搱㈱愸搴㘱ㄳㄲㅤ〶戳戰㘷㐵㔷㜷㍢㈷慣挱㙤ㄸ搷攴慣戵昹㍤㕤ぢ晡㡣㘲㈱㜳㘱捡散㌷昳㜶㘶㈸㤳捤愴㡣㤴搹戲㈳㙢敦㔰户〰㈷㘶搷慦㝤㜳㔶㘱捦㑤慦慦扣敢愵敦ㅦ㝡昰ㅤ㡦㝦㕡敤㜲㉢慡搲㝤收敤戲敢㐸㠳㔱㌷㐳㡤敢て昸昲㑢㡦愰慣㌳㈴㕢㐱戰㡡挸戸㘰ㄱ挹㍡㐵挵摣㥦ぢ㠹捥㤱攴㐱ㄴ搳㝥摥挶摡〲昱㉥㜵㌵散㜳㜶挸〸㜳戳㔰㍤挲㌶愴㜱㍤㐹㥤攲㘶㠲愳慣㠹慡㈶㙥㥡㤸愹㉢㘰㌸㄰㠰㥤㙥㐵搵扥㠳ㅢ〸〱攰㐳㙣㝦ㄹ搴㠲〱戸㠸㍥㉥㈶戹〴挴〷挰愵㑥㔱㈵昱㕢〰戸っ㡣扥ㅣ㐴捤〱ㄱ〰㜶㠲昱㉥㜵㈱㝣散〵攰ㄸ㠸慢〱戸ち搲戸㥥愴㑥ㅤぢ㡤㈰〰㐶㙢〱㘰戹ㄵ㔵ㅢ㈰敥㕦〴㠰㙢挱愸㕣㑤〰慥㐷戵扥㠱攴㐶㄰ㅦ〰㌷㌹㐵挵㍤㤰〰㜰㌳㤵㍥ぢ愲㑥〲ㄱ〰㜶㠱昱㉥㤵昲〳挰㑤㔳㌵〰户㐱ㅡ搷㤳搴㈹敥慡㠲〰㜸㑦㉤〰捥㜳㉢慡㌶㘰ぢ㘰㐹〰昸ㄲㄸ㜵㑥㑤〰扥㡣㙡㝤て挹扤㈰㍥〰敥㜳㡡慡〵扦〵㠰晢愹昴㔵㄰挵㡤㤸〰昰〰ㄸ敦㔲敢晣〰㥣〲㜱㌵〰㡦㐰ㅡ搷㤳搴愹㌶㘸〴〱搰㕢ぢ㠰ㅥ户愲㙡㈷搸〱㑢〲挰㤳㘰㔴㔷㑤〰㥥㐲戵㝥㥡攴ㄹ㄰ㅦ〰扢㥤愲敡挴㙦〱攰㌹㉡㝤ㅢ㐴㜱㑦㈸〰㝣〷㡣㜷愹㈵㝥〰戸㡤慣〶攰㝢㤰挶昵㈴㜵㡡㍢捤㈰〰㕡㙡〱戰挰慤愸摡㤴㜲㑦㈹〰扣〸㐶捤㜳〱戸ㅤ〵晥㍢㄰㐹搷㔸ㄸ㡣晥ㄱ挹㡦㐹㝥〲攲〳攰㘷㑥㔱㜱㕦㉡〰晣㥣㑡㝢㐰ㄴ昷愴〲挰㉦挰㜸㤷㥡攳〷㠰ㅢ搹㙡〰㝥つ㘹㕣㑦㔲愷㤶㐳㈳〸㠰挳㙡〱昰㉥户愲㙡㔳摣つ㑢〲挰敦挰愸㐳㕣〰挰㤷㕦晡ㄵ㤴昵ㅦ㐸㕥〵昱〱昰㥡㔳㔴㍤昸㉤〰晣㤱㑡慦㠳愸ㄵ㈰〲挰㥦挰㜸㤷㙡昲〳搰ぢ㜱㌵〰㝦㠱㌴慥㈷愹㔳摣㜴〷〱㄰慥〵㠰㜲㉢慡昶攷摣㘷ぢ〰㑣㍣搴㥢㝦慢昵ㄴ〸愳㕡搷㤱昰㤴摣〷㐰搴㈹慡㌳㘱㐸〰㘸愰㔲っ㐴慤㠵㐸〰搰㈸㜹㤷晡㙦昸搸晢ㄴ攰收扥ㅡ㠰㘶摡搴㤳搴愹㍥戴ぢ〲攰ㄵㄸて㝣っ晥摥慤愸㍣㉡㠸㜰敢㌱㡤㉤㕥㈳㍢㥣摥㥣㌱户㌳㈷㥤㤱挶㤹㙥捦㤸㕤戴㈴㠱㙥㑥昷㕡敢慣㘲㙦挶ㅥ捤ㅡㄳ〷愵㕤收㥣ㄱ㌳㡦敤㙤〱扢摣ち㤹㌵㍡㙡愶㜴扡摦ㅡ㉢っ㥢㙢㝡摦〹摢㕦挴㠷愱㤳㥤㙦㔸攱摡扦ㅤㅤづ㘷㔴㈸㝡㈸挶戱㜱㘰㉣㘵戵㌸愷㙣㜱㕣愱挸㐶㌸愸㑣搴攵愴搹户愹ㄶ㌶〱挵㤹㈵㠴〷㌲挵慣搹㤸㤶つ慤昰戱㌴㔰挵ㄹ㐲慡㈱㍤㌰㠲〴戶户㌹扤慡㤰㐹㘵㌳㜹㤳㠳㜳戰愳扡搶摣㠲昳㠲つ㤶㥤㘱㌶搹㥣㐶搲㤹户㐷戹昵ㄹ㥥㌸戰慣㈴㝢愴㐸扡㍢㤳户攱㐶㐶㤵晣捣㜴晦㠸戵ㅤ敦㠳挶㜲昹㔵挶愸晤㡥ㄸ愵搲ㅤ㈵㐳愵挲㉡ㅣ㔶戱㜰㙣㝦挷㉢晡㉥㔸㍣〴ㄳㄶ㈹昶搰㔸收搹㉦㍥㝢㠷㤵㜴㐶㡤ㄳ㈲戴㄰晦敡㐹㜰敦㜳㄰戹慦慥摣收昸〶戱攲㡣㠲扤㉤㝢㜳ㄲ戸㕤摥晢㥡慤ㄹ敡晡㌰㌴㙡㍡ㅣ攴捣㔵㥢搶㤴㑥敦摥搲㍢戰挸〰㉣敦昳㘱〹ㄷ㤸ㄹ捥㈴攲〱ち攷ㄴ敥㔵捣〵㤶㉡㈷㘶㍣㉤㍡㥣愳㌳㑡散㑡散户㥢搲㙢㡤㈱㌳㡢㘳㠲㥣㔱㥣攱ㄴ㜸㕥㠳㜷㈴戶㕢搷㘳攵㜲〶㈷ㅤ摦昴昴てㅢ㔹㌳㤶敥ㅡ㉢㕡㝤㤹扣㑥㠳挸捣㜴㐵挶づ㠸㡣ㅤ㈲㙡㑡㙦攴昱愱昰戴㘵㙤㌱ち㤹攲㐸㉥㌳ㅣ㘳㠱㐷㝣敦㠸搹㡡ㄵ〵戹挴摥换㕢㕤㉡㑦〸㥣㝤㍡㠶扢〵㠷㙡㠴㡥挳㡦㌹ㅤ㔶㔱晣愷昶昳㜴〹㙢㤱㍣㘲昴㉣㔸㡢㌰㥦攱攲㈴搷㙢摥扢摦搷㉥㠶㐴㘶戶摡㑣〵晣搳㐷㠲㤲攱扦㝡㥥捦㑣㝡昴挰户ㄹ昱戵㤶㤱㕡㘹っ攳慤㙤㠳晢捥㌶㠶愱攵㘲㔳㐸昰㌰愸〷㝢㔹㥣㕢㡥㘷㔲㘶㈱㐶㐱㍦摥㈱搷昳ㄸ㈹敡㡣㈱戶挱㜵愱㐸愴㌱ㄶ攴㙢㡤㘷敢㌸㜷㡢敤㝦㐷扤愶捡晥㉢㘷㉦㘱愲㠴戰敡㐰昵㙣挴愱㡦㘲㑣攷愲挸㜸㉡ㄴ㡥愶㐲ㄲ㈴挲〳㡤捡戱㈹㍦㤷挱改㡤㠶㔲扤扣敤攴㠹㔱っ愷㉢㜲搴ㄴ㤱㐰ㅡ㝤㐷㐴㔱攷㜴㈸收扤㐲㡤昶㘳㤶㥢愹戸戳挲昲㈸㡡挳ㄱづ搷㘳愸愳㤵挷敢㔵㙥㘱㉣搷㙦捡搹㤱㥡㠱㉥㐴㡦㐱攳㘳㜹戳挰晥㘰㥦㔱搸㘲收㤲摤㠵戱愲㤱㕣㤰㐴愷昰ㄲ㌱昹捣搷㤳挹〵㔵㘹㐶㍣慥㡦㐵摢㔰㕣昱㘰挵〳㈴㑡㐹㥣愳愹㡦㐳慤㥥ぢ愲搲㈸㌲㔱㜰ㅥ㙢挷㐳㔴昵㔸㔳㍣㈸攰愳㉤ㄴ㍤〱昵晢扥㤴慡っ摡㜰㌹搵㈷搲搵㔶㜰㕣愵昶捥摡㤳㈱㥤㝡搶昲㌴〲㡡㈱㍤㡦㐶摣㠲捡㠱昱〲〳敢㑤㠵昹㔰搰ぢ愸㤸て㔶㘸愱挲㈹㔴攰〹〶愷㐳戴ㄵ愵づて㘶扥晢㌲㙤挳㑥づ㕢㌹㝣㥤㠰户㥤㜶昲㤴㈴㡥扡捤っ㜰㕦晢散㔷㜰挶㤳㌲㠸㝢㕢㙢㄰敥ぢ㘱っ戸昳戸挳敢㥥て昷㜶㝡敦愰㜷ㅥ㑤㤴㜰敦㠴愸ㅡ㜷㥥㑦㌸戸㉦㐲晤㌴㜰攷㤹㠶攰扥㤸慥㉥㐱愹っ昷愵㤰㑥㡤晢愵㘸〶挵㤰㝥㌷㡤戸〵挵㤳㄰㉦㌰戰ㅥ敥愷㐲㐱㥦㐶挵换㠳ㄵ㤶㔱攱㜴㉡散㠴㠲攰扥ㅣ愵昶改攳扥㌴〸昶㉥搸〲散㔷昹㥣晢㘰敦愶昳ㅥ㍡扦ㄶち㈵搸㝢㈱慡㠶晤㝡攸㌸戰慦㐰晤㌴㘰扦〱つ〵昶㤵㜴㜵㈳㑡㘵戰慦㠶㜴㙡搸㜹昴〲挵㤰㕥㐳㈳㙥㐱昱晣㈵〰昶㌳愱愰捦愲㈲捦㘶〲ㄴ搶㔲愱㡦ち㍣慥ㄱ搸搷愱戴扦慢捡〶戴〵捣㍣捡昱㥣昹㘰㍥㥢捥㌶搲ㄹ㡦㕤㑡㌰昷㐳㔴つ㌳捦㕥ㅣ㤸〷㔰㍦つ㤸敦㐱㐳㠱㜹ㄳ㕤昱攰愶っ收㜳㈰㥤ㅡ收晢搰っ㡡㜸㌳㐱㈳㙥㐱昱㤴挷ぢっ慣㌷扢捦㠳㠲㝥てㄵ扦ㅡ慣昰㕥㉡扣㡦ちて㐰㐱㘰㍥ㅦ愵晤㔹㔵摡㠲愶昷㈰㡣〱昷㐷㝣摥㝤戸㝦㠰摥つ㝡攷㘹㑦〹昷㈱㠸慡㜱㝦ち㍡づ敥挳愸㥦〶敥㑦愳愱攰㥥愲慢㘷㔰㉡挳㍤つ改搴戸敦㐶㌳㈸㠶昴ㄶㅡ㜱ぢ敡㌹㌰〱戸㡦㐰㐱㘷愸昸敤㘰㠵慤㔴搸㐶〵㥥㐵〹敥㔹㤴扡慡㔶㤵㔵㘶挱挸搸㐹㌳搹㤵捡㘵昲摣ぢ攰〴㝥摣愸戵戶〷慥㌱㜹㔸挶㈰㝣捦搷ㄵ摦㈰㔸散捡㈸扢昲㈲ㄴ㑡㠳㜰〱㐴搵㠳挰㘳㈷ㄹ〴㌹つ㐲愱㙡ㅦ愲㝥っ㤹挰㙤搳㈸㑦愷捡攰ㅥ㠳㜴㙡戸㜹㡡〵挵㤰ㅥ愷ㄱ户愰㜸㤴ㄵ〰昷㜶㈸攸ㅤ㔴攴㌱㔷㠰挲〴ㄵ㉥愴〲㑦扥〴敥て愲戴扦慢挹㠷搱ㄶ㠰晥摡攷捣〷攸㐵愸搵㑣㕥ㄵ㑦戰㑡㠰㕥〲㔱㌵愰㍣挶㜲㘶昵㐷㔰㍦㡤㔹捤愳㉦㠱昹㔲扡攲ㄹ㔸ㄹ捣㤷㐳㍡㌵捣慦愱ㄹㄴ㐳㝡㈷㡤戸〵挵〳戳〰ㄴ慦㠰㠲扥㤲㡡慦〷㉢㝣㤴ち㔷㔱攱㑦㔰㄰㤸㍦㠶㔲昷㕢㥤搵挱ㄹ换㈷㘰ㅡ愳昰ㄷ㕦㕦㝣愳昰㐹昶攵㔳散ぢ攳㉡㡤挲愷㔱慡ㅥ〵㥥愵㌹愳㜰㌵戸㘹㡣〲捦摦㘴ㄴ慥〱愳敡㐱捡㐶攱㍡〸愶ㅥ㠵㈸摢㈲っ㝤扤换戰愰㜸㙡ㄷ㌰ち㌷㐰慣㙦愴㘲㉣㔸攱㌳㔴戸㠹ち㍣攴㤳㔱戸ㄹ捣㕢ㅦ㠵挰ㄵ㝥ㄷ㑣㘳ㄴ㜸㍥攸㜵搶㌷ち户㐰慣㍦〷愲㜸㜶㠰㥦㤰扥搵㘵戸〳㡡捣㐲愱㜲㕢㔳戵攵攴㍥㌵㥥收收戳扦㌸㤱挵㠶㥦㉣户㌹づ挷つ㥢㔳㡤捤㤷㔵挰ㄸ搴㔷㝥戳戰户敤㝡㤸㙡㍣戸攲㝢㄰㘹挶㥡挳搱㥢㠸㠱㘳挹㥡敤ㄹ㐱改攵㌰摢昰㡡摥づ昹挱㝤㤹攱㠲㘵㕢改㘲戲ㅦ挷㔹㐹㝥㕦㤳づ㠵㕡扢㈲㠳戰ㄸ攸㤳㠱搵攷昹改改㌸摦㌷挷户攵慤敤㜹改㑤挴收㘷㐶昴愶ㅢㅡ攸㈶㡥㝦㜲ㅤぢㄴㄳ摣〷戳戱晥㍣㤸收扡挴㙣㙡攲㑡㜰㌳㈹っ㜷㡥挲㈴㕤㈶挲㡤搵扥㙥攵㘸㕢つ愹㘱㤵㔲㘶㝤㐳㠳㥡㕢昱㌱㑢搵ㄶ㜰敦搷〰搱㈸㜷㠰㤱昳ㄱ昲扥㌵㘲昷㑡㠸戲戱㙣㡤扦〰戹扥ㄳ㈴㥥㌸づ㤴ㅤ㡡摥〵收挰㥥敥㐱扣㤵昶扦〹㡦㝥ㄱ昲㈶挸㘵㥢㡢捦㠳敤攸㤷㈰㌹〰㤲昲捦㝤愳㜷㐳㍣〳㘲摦㔱㔸㘲㉥㘴〲攵㌰㕣挸昷慥晡㕥㠸攴昳㔷㜵㈲㌸晣㠴昴㝤㉥挳扥㈹㙥晦㌸㜱搵搹㠸㤲搳〵挲㤰收ㅣ攰㜰慢昵㤰㜰挸换㠷㡣㥢㐰昱昳㈰ㄸっ搹㝣㔱挷㤰㜱搳挷㉢搱攲㌱摣攵昱㔲摣㤳㜱搸㔴ㅦ捣ㄱ㔲㠱收㘱㐸昴㈳㈰昱〴户㘵㘲㤴搰㘸攲愰ㄹ扡㘶愰〹㙥搷㑡㤱ㅤづ㠳晡〹㔶ㅥ㐶搳戲挱愲攸㐹㠸昰㈳愸慢愵攰㈴戲㉥㌸慢㡥㙣㌹愴搵㤱㜱㥢㈵㝥㥥〱㠳挸㑥愵㌹㕣㠹搳㍣㘶㤹挷㥣敥㌲㡡摢ㅥ㠹㙣㤹㍦戲摤㤰敡攷㐰攲㠹㙥搰㥡㤱昵㜸㤵㌲㘶㐹昸搲捦戳改搱攰搴㑡㜰昸〹改ㄷ㕣㐶挶㙣㌵ちㄲ㔹㕢㘰㘴愷〴㐶戶〶㡤愴ㄳ㍦〴㠳挸戸㙢攱㤵攰捥㐵㤸戵ㅥ挳慤ち㉦挵㥤㠶㐴戶挰ㅦ搹㡢㤰敡㤷㐰攲〹㙥㌶㙡㐶挶㑤㠸㔴㑡㘴㈷挰愰摥挳愶挷搳昴㈶㜰昸〹改㕦扡㡣㐴挶㙤㠳㐴㜶㑣㘰㘴㐷〷㐶挶捤㠳昸昹つㄸ㐴㜶ㅥ㝥昱㑡㜰戳㈰捣㝢㍤收㝤㉥愳㤸换㑢㘴戳晤㤱晤ㄶ㔲晤㙦㈰昱挴〷㐰㙢㐶挶㌴扦ㄴ㔹ぢ㝣攸㔷搸㜴〱㌸㉣㌳㙥㘴慦扡㡣㐴㤶㐶㐱㈲㍢㈰㌰戲㤹㠱㤱㙤㐱㈳昱昳㍡ㄸ㐴㌶㠲㕦扣ㄲㄹ㡦㘱敥㉤ㄲ收摦扣㔴ㅥ㡣㐴搶散㡦散扦㈰搵㝦〶㠹㈷㤸㈳搷㡣㡣戹㜳㈹戲㑥ㄸ搴晦挷愶ㅤ㌴㉤㌹㌰㐵㝦㠳㠸〷㥤㝣㌸慡㌱ㄴ㈴㌲ㄵㄸ搹㥢㙦〴摤㘷捣㠴挵㑦ㄸ㜶㄰ㄹ戳㕥㕥〹㘶扥挲㑣㜸っ㔳㕤㕥㡡㤹慡㐴昶〶㑣敥㕤㐱敡㘱㐰㌳㉤㠹㈷㉥㠲㐲捤挸㤸挴㤶㈲攳ぢ㘵摤挴愶㝣㐷慤㉥㐵㈵㝥㐲㝡〶㐴㘴㘴捣㉥〷㈷㤱晤ㄱづ慢㔷㤰晦っ㡣㙣㈷ㅡ㠹㥦〳㘱ち㤱㕤㐱㜳戸ㄲ㔷㝡捣㐷㍤收㉡㤷㔱㥦〰㈳㤱晤挱ㅦ搹挱散摥㈱㈰昱〴ㄳ挰㥡㤱㝤捡慢㤴晢慣〷扥昴㤱㙣摡つ㑥㐹㉡㐷搱㔱㄰搱㥦㐴挶㔴㑥㈲晢㜵㘰㘴㉦〷㐶㜶扤攷㘷づ㑣㈱戲ㅢ㘸づ㔷㠲〹㥣㌰捣搶㠴㘱挶挶㑢敤〲㈳㤱晤挲ㅦ搹㜱散摥㕣㤰㜸攲ㄶ㈸搴㡣㡣挹㔶㘹捣捥㠴㐱㍤㥦㑤昹㔶㌹㜱慢㔷搹㈲摤㠹㝣ㅥ攵㔳㉢㥥敤挱慦㡣收㔵㝥攳扢〲摦散㑥挰㑡愸づ㘷攵捥〹㜳㝤昸摤晢㘷㡢搹〳㕦㌰昱㕦攴〷㠸晡㉤搸㐱㐴扥㝣㠲ㄶ昹㔴搰慤攸敡捣㉦愰㌲㠲ㄲ敦㐱摦昵摡㜲户㜰㠶昳㍢收晥㑥㥣㌱昳㑥慦挵昹敡㤸㙢扢㈲扦扡搸搵っ摤昶挷㉦㥦㍡昷㜳昷㕦㥣扤扤改搱换㜲扦㕡晥攸㔱㍢㝦㝦昶愳㥦㕡慥敥㐵ぢ扥愵搲〶挹㄰〹攷㤸㝡ㅥ㘱〵扥〶晦㥥㕢㔱昹㌹㕣攲㍥㔸㤲㤱㕣㈴㠳愵ㅥ㐴㤹〳愶晥〹㉤㠸㤲〴戶㠴㠱㍤っ昱昴〲㝢挴㙢攱〵收〶昴㈶晡㉡㤷㍤㜲捤ㅦ㍥戴晣愵㙦㝤愹昳㥦㑦㕤昷㠳㙢㤶慢㈷搰㈲㈸戰摤戵〲㝢搶慤愸晣捣㉤昱㈴㉣㐹㘰愷㍢㠱㍤㠳戲〴昶戴㍦戰㌳ㄸ搸㙥慦㥢㕥户㥣摦㤳㡣ㄸ搳〷㠱㘲㥦〳㝢ㅥ㉤㠲〲㝢愲㔶㘰㡦扢ㄵ㤵㥦慦㈵㕥㠰㈵〹㙣愵ㄳㄸ搳〶〹散㌱㝦㘰慢ㄹㄸㄳ㠲改㡤搸㑢㕥ぢ㉦㌰て㤲㥡㔳㜱て㕡〴〵昶㜰慤挰ㅥ㜲㉢㉡㍦㑢㑢晣ㄲ㤶㈴戰㜵㑥㘰扦㐱㔹〲㝢挰ㅦ搸〶〶昶㕢慦㥢㕥昷愶ㅣ㌱㈶て搳ㅢ㌱㈶づ㐱㠱摤㕢㉢戰㝢摣㡡捡捦捤ㄲ慦挲㤲〴戶搹〹㡣㐹㠳〴㜶户㍦戰㜳ㄹㄸ搳㠱改㡤搸㥦扤ㄶ摥㠸㔵摥㘳㠷ㅤ摦ㅦ戹攳摡㙦㝣慢攳㠰㐵愷㝤㜳攳ㄵ换ㄵ昳㠶愰挰扥㔰㉢戰㍢摣㡡捡捦挸ㄲ㝦㠳㈵〹散晤攸扢ㅥ㘴㜴晣ㅥ挱㡤敥㜶㝦㜴〶愳㘳㑡㌰扤攸㤸㍦㤴つ㥢㌷攰㌵攷㈳㜳㠷愰攸㜶搵㡡敥戳㙥㐵攵㌷㘲〹愶ㅣㄲ摤ㄶ㌰捤㜵㡡㜹㠳っ摢㑤晥挰㌲㤰捥㘴㐶㌰扤挰㤸㍥㤴〵㌶攵戰㌱㜵〸ち散扡㕡㠱㕤敢㔶㔴㝥晢㤵㘰挶㈱㠱㔹㘰㄰ㄸ搳〶〹散㙡㝦㘰ㄷ㐰㍡㤳〹挱昴〲㘳昶㌰扤挰㤸㌹〴〵昶昱㕡㠱㝤捣慤愸晡愶㡢〹挷㔴摦㜴昹晥㔲㙡㈶㈶㔳㈴捤㌳㥥挶戴㈳㘶㡥㠰㔳㥥㑣㌶㉢〷㈴㑤昸攰愲㠰扦㔵㕡㡢㉦㡢昰㤹〵晥㙥搶摤敢攳㡢㈳扥扦昶㕥改㙢㈹戱㜱㌴扤扥㠰㜷晣つ改㌵㌶扥㄰㑢挵昰户ㄶ挵㈲晥搶昶㥤昰㌵〶㡥慣㜸〳攲㜲扥挳〸㍣㉤攲㌱搰㈴ㅦ捡㤴昰昰晥〴㈹捣敦㌴昶敦㘳戱攸㜶㡥扣昳戱㔱㌲㔵昶〹㔲扤晡㈸〶搹㌹〶戸㈴攴收ぢ攱㤰㘶㌲㈸昹㡥愴捣㈰㜱晤㐱㡡㌶愱摢㐲㐲ㄱ㈶㘱㤵愱昱昴㡥㡦换㔰挵㥦ㄱ㌵㌶㝡愷㙢愸ぢ㈹收㐰㥣㐳搱て㠳搴敡搸愵㠱ㅤ扢ㄸ㉤㉡㍡昶ㄱ㡡㑡ㅤ㔳㑣愲搸㌹敦㔲捣㑣挴摤㘵㘰㙡戹晢㔰愰扢㥤㘸㔱攱敥㑡㡡㝣敥㤸摡㤴戹㈳〰攲敥㉡㌰戵摣㡤〷扡晢㌸㙤て戱攳㔸昱㐹攲晡㤳ㄴ昹摣㌱攱㈸㜳户づ〲㜱昷㘹㌰戵摣㡤〶扡扢㠶戶㠷捡摣㕤㐷㤱捦摤〶㤴换摣昱搹㉡敥㙥〰㔳换摤搶㐰㜷㥦愱敤愱㌲㜷㌷㔳攴㜳挷㠷㜳㤹㍢㍥昱挴摤㉥㌰㠷攲㔰㄰晦挳〶昹摢㤶㔱晣戶挷㐶㉤㝣ㅢㅡ㔶㈹捦摦敦ㄷㅥ㕥㥡挴㥦愳昱㈱晡〳攳愰㜹ㅢ㐵㍥㝦㝣㤶㡡昹㝦〰㔳㉢㥡昷㝢搶㐳晥㕢攴づ㥡ㅡㄲ挳ㅣ㉣㡥搵㥤ㄴ昹慣昳㘱捣㘸敥㕥晥ㅦ㘷㕣㜴挶挷扡ㄴ㥦㜰攲敥㡢㘰㙡戹㍢㌷搰摤摤㘸㔱〱摥㍤ㄴ昹摣昱ㄱ㔹〶ㅥ㥦㍢攲敥㉢㘰㙡戹摢ㄸ攸敥㝥摡ㅥ㜲㘰㜳愳㝢㠰㈲㥦㍢㍥戸晣敥㈲㕣㌴昶㜹㑤㈳㘶〷㘱昵㜷晦㈷㈰晣㤴㙥㕥ㄶ㙢搳㍥㝣戹昸㄰晣㈸㉥㐷戴愱ㅦ㜶ㄹㄹ〴㉥て戲㜶㍤㐲㈹㔷〶搱昹㥡㕦㠷昷戴攸㝣㥤㔲摥捥愲昳愸㕦㠷㌷愲攸㍣㐶㈹敦㐱搱昹㠶㕦㠷㜷㡦攸㍣㑥㈹㙦ㅣ搱㜹挲慦挳㈹㉦㍡摦愴昴㘶㑦攷㐹扦づ愷愹攸㝣㡢㔲捥㔰戱昳㤴㕦㠷㤳㑤㜴㥥愶㤴昳㑣㜴㥥昱敢㜰㠶㠸捥戳㤴㜲㜲㠸捥㙥扦づ㠷㔵㜴㥥愳㤴㈳㉡㍡摦昶敢〸扣㐴昶㍢㤰㝡㔷㠲㌰㑢㌲昳㡦㘰㤰捣〸挰㔵㕡〴㕡戴扥敢㘸〹挴㔵㕡㠴㕡戴㥥㜷戴ㅥ挳㉦改㐷㤹㐷㠲㉤㕡㉦㌸㕡〲㜳㤵㉤挲㉤㕡摦㜷戴〴攸㉡㉤〲㉥㕡㍦㜴戴〴敡㉡㉤㐲㉥㕡㉦㍡㕡〲㜶㤵ㄶ㐱ㄷ慤ㅦ㌹㕡〲㜷㤵ㄶ㘱ㄷ慤㥦㌸㕡〲㜸㤵ㄶ㠱ㄷ慤㥦㠹㔶挲〳㐰ㄱ㘵挹ㄵ攷攲昶攴昹㐰㌷摡挶昰晡㤳挰㑡挵㜱ㄵㄵ挴㔲㉡㡥慤愸㈰㝣㔲㌱愷愲㠲㠸㐹挵㌱ㄵㄵ〴㐹㉡㤲ㄵㄵ挴㐵㉡㡥慥愸㈰ㄴ㔲㜱㔴㐵〵愳㤷㡡搹ㄵㄵっ㔸㉡㡥㉣慦㘸晣㝦㡤㈳愵㍦ | C27: 㜸〱捤㕣ぢ㜸ㅣ搵㜵摥扢搲慥昶慥㈴㙢㜹㤸昰㌲㠸昷挳昶㈲㠱㘴㙣㠸戱愵㤵㘵ㅢ扦㠴㈵摢㐰愰换㐸㍢㙢㉤摥摤ㄱ扢㉢㕢愲〴㈸慦㘰㑡㈸〱㐳㜹㤳昲㝥㤸㘷愰㤴㠶㔰ㅥ㠶㠴㤲搲挷〷㑤扥〶搲㐰搳慦㉤㠱〴㐸㘹㤲敦㙢㜰晦晦捣㡣㌵扢㍢㉢㔹㠴㝥ㅦ㠳㜴㜴敥㌹攷㥥㌳攷扦㜷㘶捥扤㌳㈶愰〲㠱挰㑥ㅣ晣换愳㥥捣㠱晤攳挵㤲㤹㡢㈷慣㙣搶ㅣ㉡㘵慣㝣㌱摥㔵㈸ㄸ攳㉢㌳挵㔲ㅤっ挲挹っ昴挵㔰戲㤸㌹摦㡣㈴㌷㥢㠵㈲㡣㐲㠱㐰㈴愲㠳搰㙢攷㌷戶慢挱㕥扡㥥〴㔶〱ㅤ㈶㘹㈰㠹㤰㠸㝤㤴㕣㈳㐸㔳ㄳ挸㐰愲㝢捤攰戹㠸摥㕦戲ち收㥣搶昵㜶㡣㠵敤敤昱昶㜸㘷摢㠹挷挷摢收戴㈶㐶戳愵搱㠲戹㌰㙦㡥㤶ち㐶㜶㑥㙢摦攸㘰㌶㌳戴挲ㅣㅦ戰㌶㤹昹㠵收㘰摢〹㠳㐶挷晣昶㡥捥捥昴㠲〵昳㥢㥡攱㜹㜵愲扢慦㘰愶㡢㕦㤴捦ㄹ昴戹㈶搱ㅤ㕦㙤㤶扥㈸㥦㉤昰〹㤷㍤㔶捥挸攴扦㈰愷㈱㡥㐱㘷㡦㌹㤴攱㘰㤹㘶㈱㤳摦ㄸ挷㘹㤷〱㡤搶㠹昱慥㘲㜱㌴㌷挲㜱㑦㤸搹散㕡㌳㉤㠳㤴敢㈹㤶晡㡣㐲慥搸㤴㈳㝥㘶挱捣て㤹挵ㄹ戹㈵㘳㐳㘶搶㌱㉣㐶㜲敢㡤挲㙡㈳㘷搶㤳㘹挹搹㘳戸㍣㘵收㑢㤹搲㜸㜳㙥㕤搱㕣㙢攴㌷㥡㌴〹攵㤶㡥㘶㔲慡扥ㅥ㍦㠱扡愳晣捥㑣〶ち攷㤳㑢っㅢ㠵㤲戴㌸㠴敤㝥戶㥥改㈲㔹㤴㥤ㄷ愷㔴㙢㐵㉦㡥㔹㝦㈶户挲㉣攴捤㉣㠳㜰㈴㘷㔷ㄸ〹㐰昶㌸散㐲捡㑤㠷愳愴ㅡ㥤㡢㠵戹㌰㑡㌸〶戲㝦㑦㥦㤵㈹ㄶ慤晣㥣㤵㔶㘲戴戴戰㙤捥㕡愳㘴㉥㙣㥦搷搶愶昷㠰㕥敦㐹换扤㐰㘲慢搷慣㕦搳㥦㑣㜴慤ㅤ㔸戳愴㍦㜹晣㍣扤㌷昵㌳㐱㔴晤晢戸㌲扤晥㜹㜵〴㤳㐶㌰㌹ㄸ㑣づ〵㤳愹㘰搲っ㈶搳挱攴挶㘰㜲㌸㤸捣〴㤳攷〶㤳㥢㘰攳ㅥ㤱㠶㠶愰㜳扣㝡搱戳㉢㌶攴摦敦扡㙤搳敦捥慤㙦晦摥㈳㡡ㄷ愳㕣换㕦〱搳戶摡㉡攴㜰〱㉤换搸㘷扢捡㌴昲ぢ攷㜶㜴挴攷捤㥢㝦挲㠲捥昹ㅤぢㄶ捣㙢㙢㥦搳㕦㑡昵㤸㥢ㄷ㜶挴㍢昵扥攸愵昷〳〹敦て搲摣搷搳㤳ㅣ挲㄰ㄹ㔶昲昸づ㝤〰㤵〷㠲㈸昵㙦㐸㠱㘹慣㜹㙦挵㡦㘷敥㜳㐱敦昶ㄷ㕦㝢昷搰㈵㥦ㅥ慤㜸ㅦ㤰昸〷㠱㤹っ慦㠳改慣ㄵ㈴㝣〸㐸㈵㕥ㅤ晡㔰敡て〳㔱敡㙤㈷搸晤摢ㅥ戸㝤搹㉤敦昵㍥㌳ㅣ晣敤㈳捦㕥㝥户攲晤㐶㠲ㅤ〱愶搵㐹搶ㅤㅡ㐹戶戳捤捤慥扤㑤ㅦ㐹㤷㐷㠱㠴㡦〶㘹㕥㙢づ㜹㤲㍢㠶捡㘳㐱㤴㝡换㠹㤷㙢晥挱晢昹㈳晦㘳昵㜵昱晡ㅤ㡦㕥㜰挰愰攲慤㑤攲捤〱㌳㜵扣戹㜴ㄹ〷〹ㅦ〷搲攸挶攳㙣㘸愳慡ㅤ㐴愹㌷㥣㘸㑢㑦㕡㥡㌸散攰户ㄲ㕢㕦晥搹改攳㡦㘵㍦㔶扣㍣㈵摡〹㘰愶㡥搶㐱㤷㥤㈰攱㜹㈰㘵搹㜵敡ㄳ愹㥣て愲搴昷㥤㜸收换㡤慦㍣㝥敦㙢㑢ㅦ晡慦愷㝦㌷扥昱㤴㤳ㄴ㙦搷ㄲ敦㈴㌰搳㥦㍡㈷㌳挴㔷㐱挲ぢ㐱捡愶捥㍣㝤ち㤵㡢㐰㤴㝡挱㠹摦晣㕢昳搴㐵㜷晦攷捡扢て㕣㜸挳搸㔹搷敥慤昸愴㤰昸㕤㘰愶ㅦ扦㥢㈱ㄲ㈰攱ㅥ㤰戲昸㥤㝡〹㤵扤㈰㑡㍤敢挴晦挵㈷扦扡昴挱㌷㍥㐹㕣昳愳㘳慥㜸㜳搶㔸㠳攲㘵㈸昱㤷㠱㤹㙣敡㉥愷戳㔳㐱挲㉢㐰㉡愷㙥愷㕥㐹晤㉡㄰愵㥥㜴㠲晤㘴敢收㔹㌷㕦戶㘸挵昵㍢晦㌶㝥搰㙢㥢捥㙡㕡〳昵㘹捥㍤愶愷㘰㙣挱㕤㝢攲㠱㠰愷㈰晦㥢晡㐹㠸〷㘱扡㌳㝤㘲扡扤㍤搵搹㘶㥣㘰㠴㜸ㄷ摡摤㕢㉥敦㘸㑤改つ㤹㝣捡摡㈲昷攰〳扢㡤愲㌹㜱㑢㥥敤攸扡慤搱㝣慡㜸㠰扦戲扦㠴㍢攰晥㤵扡〹㈷㔵摤晡昱㠴㌲㡢ㄲ敦愰捡㙥敢㡤散愸搹㌵㤶戱搵戳㉡搴㜸㍥㔹㠳戵戵扤〵昳扣㕤摡慡㌳敡㐲挱戳㔹㝣㔷㘵㘹慢散昳㙡㑤っ㕢㐵㌳㉦愷㌷㍢搷㤷ㄹ摡㘴ㄶ晡㑤㤶㑢㘶㑡㔲㥤㐹㤵昳㤰㥣扤㈶㡦㐴昱搸㑢ㅤ敡㤵愶㤷㡣㤵捣㝣捡㑣攱㝣㐷捣㐲㘹㝣挰ㄸ捣㥡晢㤴㤹搸㌱愱搸慦㑣摣㙢つ㡤ㄶㄳ㔶扥㔴戰戲攵㥡慥搴㘶〳て收搴㉡㉢㘵攲戹㕡捦㈳愰〲㜵㜵㑡〵㡥昵㝢戸搱㙦㌱㉥〳攱ㄹ㘲㍥㘶昷㉤㥦㜶㜱摣㤷㑡挸㈲㙢㜲㑥〶て㥦挲㤹昸愵㥢㘳㙡ㅢ㝡㜲㘲㙤㐹敢愳㙢㕢换㌹敥ㅡ戹晦㕦攳㘰㜰㉦㈷晢㈵㥢㔱扣㉣㌳昲愹慣㔹㤸戴㌲㔶㍣㈳摤〷ㄲ㝡っ㔷㜳㑤昴昸攴㔵㘳㙡㍣戴㈵㤳㉡つ㠷㠷捤捣挶攱ㄲ㘴愸㥥㈳ㄱ㐲㕢㜵攸戵㄰改㝥㤲〱㤰㘸㌴㄰㕥㐷愳㜰㔴慦户摢㈱ㄶㄴ搳㉦㡢愴㍥㤷㌲っ㌵㜳㌱㤴敢戵ち挵扡㍡扦㉣㤷ㄹ挵攱ㄲ愷攷愴㑡ㄶ㐰㝡〳挹改㈰㈱㤶㌲㔳㔶㕤㉤㌰慡㘷㜱搹㥣敢㌱搳〶㑡㝡戹扡㤵ㄱ捡搹㔵㘲㡦㔹ㅣ搲㉣㈷㤷攳㕡ㄹぢ㠳挳挵摦㤴攳散㌷挷㑡㍤㐶挹㘸挸愱㌰挵㈸㘹ㄸ捤㤶㕥㌶挷㥥捤㈲㜳㝢㐷㥤ㄶ㍣挴㠴昵㜸㘹ㄴ㠱敤〹ㄷづ慥㤷㐰㥤㐳㈷㑦〲攷捥搲㌱㕣㌹搱换ぢ㑣搴扤愹愵㘶㝥㘰㝣〴㔵㌳捣㈳攱㐹愱慣扣扣攸㙣捤搰攰扡㔲㈶㕢㡣攳㑣㤷ㄶ慣搱㤱㉦搲て㝤改㌳㐰摣㈳㜴ㅦ㘶昱敥攷挴㤵㘳挳㘶㡥㑤㌲ㄹ㠸搰ㅢ㈵㥡㐵慥收㙣㠵戳㥤昸㈳㠷㍥ㅢ㝦愲㤳改㐲慣㠰愷㔳㡣戳㥥㙣捡〱愱㠱㠲㈹换㡢㠸㌴㠰㜶㜳㙥㠳㔵搸㌴㘸㔹㥢㌸㥦㘶㐸慢㌸㙣㥡㈵㤶散㡤捥ㄲ㐵㤶㈲㑡搵搵㤵搵摢㥥摡㥥搳㌴㙣㠰捣ㅡ戰㔲㔶戱ㄵ㍦㕤㠵昳㐶㌳㥢挱愴捣搶㠱㠲㌱㘸㘴㠷慤昰㈰㑣敡戰㤸〸て㠱㌹㍥戱愴慢晢〴㑥㔸㠳换㈹摥㤳戳搶晡㌳扢收慥㌲㑡㠵捣昹㈹戳摦捣ㄷ㌳㠳㤹㙣㈶㘵愴捣昸㔸戶㌸愶㙥〳㑥慣㤸摦昹㠷户㡥扢改挳ㅤ㠹敤㉦晤攰慤搵㥦敥㜱扡扡搵㔱㔴㤵昲慣挵㘵㔵㤱〶愳㙥㠶ㄹ敦㍦攰换て㍤㡣戶捥㤰㥣ぢ㠲扢㠸㡣ぢ㙥㈲㔹扢愹㔸捦昳㐶愲㜳㈴㜹㄰挵㔲㥥㤷戱戶㐰摣㐳㕤ぢ晦㥣ㅤ㌲挲㕣〰㔴㡦㜰ㄱ搲愸㥥㐴愷戸㐰攰㈸㙢愲慡㠹㥢㈶㘶敡ち㌸昶〵攰㜲㐷㔱戵㤶攰ㄲ㐱〰戸㠰晤㉦㠵㤹㍦〰ㄷ㌲挶㐵㈴ㄷ㠳㜸〰戸挴㙥慡㔶晣ㄵ〰㉥〵愳㉦〳㔱㠷㠲〸〰㤷㠳㜱て㜵㍥㘲散〲攰㄰㠸慢〱搸ち㘹㔴㑦愲㔳㠷挱挲て㠰㤱㕡〰㔸㡥愲㙡㝤挳〵㡢〰㜰ㅤㄸ㤵慢〹挰㌶愸昵つ㈴㌷㠲㜸〰戸挹㙥㉡㉥㝡〴㠰㥢㘹㜴ぢ㠸㍡〶㐴〰戸ㄵ㡣㝢愸㤴ㄷ〰慥㤲慡〱戸ㄳ搲愸㥥㐴愷戸㡡昲〳攰捣㕡〰㥣攱㈸慡ㄶ㕣㜳攱㐹〰㜸〰㡣摡㔰ㄳ㠰㠷愰搶て㤳㙣〷昱〰昰愸摤㔴㜱晣ㄵ〰ㅥ愳搱攳㈰㡡㑢㌰〱攰〹㌰敥愱㔶㝢〱㌸づ攲㙡〰㥥㠶㌴慡㈷搱愹㜶㔸昸〱搰㔳ぢ㠰㠴愳愸㕡〳㜶挰㤳〰昰㍣ㄸ搵㔵ㄳ㠰ㄷ愰搶㉦㤲扣〴攲〱㘰㠷摤㔴㥤昸㉢〰扣㐲愳㔷㐱ㄴ搷㠴〲挰昷挱戸㠷㥡敦〵㠰㉢挹㙡〰㕥㠷㌴慡㈷搱㈹慥㌴晤〰㠸搷〲㘰慥愳愸㕡㤴㜲㔵㈹〰扣〹㐶捤慥〹挰㍦㐳慤㝦㐴昲㘳㄰て〰晦㘲㌷ㄵ㔷愶〲挰㑦㘸昴㌶㠸攲愲㔴〰㜸〷㡣㝢愸㐳扤〰㜰㈹㕢つ挰扢㤰㐶昵㈴㍡戵〸ㄶ㝥〰散㕢ぢ㠰慦㌸㡡慡㔵㜱㌷㍣〹〰敦㠳㔱㌳㙢〲昰〱搴晡㐳㤲㕦㠲㜸〰昸挸㙥慡〴晥ち〰ㅦ搳攸ㄳ㄰挵㔵戱〰昰㙢㌰敥愱㥡扣〰㜰㉤㕤つ挰㙦㈰㡤敡㐹㜴㡡㙢㙤㍦〰㠲戵〰㔰㡥愲㙡㔹捥搵戶〰挰挲㐳敤晣慣搶㔳㈰〸戵慥㈳攱㙥户〷㠰戰摤㔴愷挲㤱〰搰㐰愳〸㠸㕡〹㤱〰愰搱㜲て昵㍦㠸戱敢㈹挰㈵㝥㌵〰捤昴愹㈷搱愹㔵攸攷〷挰〷㜰敥晢ㄸ晣㠵愳愸摣㉡〸㜱改㌱㡤㈵㕥㈳㑦㌸扤㍥㘳㙥㘱㑤㍡㈳㡤扤搹挴㘸戱㘴㐹〱摤㥣敥戱㔶㕢愵㥥㑣㜱㈴㙢㡣敦㤵㜶㤸つ挳㘶ㅥ换摢〲㔶戹ㄵ㌲㙢㘴挴㑣改㜴扦㌵㕡ㄸ㌲㤷昷㝣ㄹ㤶扦挸て㐳㈷㉢摦愰挲昱昹㔶㜴搸㥣㔱㠱昰㍥ㄸ挷愶㠱搱㤴ㄵ㜷㜶㜶愳㌸〲愱戵㠸㔰㔹愹换㤶戱㘷㔵㉤㙣っ㠶㉤ㄳ㄰て㘴㑡㔹戳㌱㉤㉢㕡攱㈳㘹挰㡡㑤㠴㔴㐳㝡㘰ㄸㄵ㙣㑦㜳㝡㘹㈱㤳捡㘶昲㈶㐷㘷㙦摢㜴愵戹ㄱㅢ〶㝤㔶㌱挳㜲戲㌹㡤慡㌳㕦ㅣ攱摡㘷㘸㝣捦戲㤶㉣㤲㐲改敥㑣扥㠸㌰㌲慣攴㕢搲晤挳搶ㄶ扣搸ㄹ捤攵㤷ㅡ㈳挵㉦挵㌰㑤㕣㔲㌲㔶㉡愸㠲㐱ㄵ〹㐶㍥敦㠰㠵扦〲㡦晢㘰挶愲挶ㅥㅣ捤扣㝣晦换㜷㕢慤捥戰㜱㑡〴㡥挷㙦㍤〹慥㝥㡥㈲㔷搶㤵ぢㅤ捦㈸㔶散㔲昰㜴换摥㠱昸㉥㤸㜷扤㌰㙢㠶戹摥㤷搳㘷㍦㤰㔳㤷慥㕢㍥戱㝦昷〷扤捤ちつ挰昳㙥㙦㤷昰ㄶ㌳挳㥥㐵摣㐲攱愴挲搵㡡挹挰㔶攵捣㡣愶挵㠶㤳㜴挶〴摢㡢ㄵ㜷㔳㝡愵㌱㘸㘶戱㔱㤰㌳㑡㌳散〶㜷㙣昰昶愰攸攸ㄲ㔶㉥㘷㜰搶昱㥤㑤晦㤰㤱㌵㈳改慥搱㤲戵㉡㤳搷㘹㄰㤹㥡㡥挸ㄸ㠳挸ㄸㄳ㔱㔳㝡㉤㌷㄰㠵愷㉦㙢愳㔱挸㤴㠶㜳㤹愱〸ㅢ摣攴晢㔲㑣㔷摣㔳敡〱愶㝢戸昷㤷捡㍤〲㝢愵㡥攱㡥㘳㕢㡤搰㜱昸㌱愹㠳㉡㡣晦搴攷摣㕦挲摤㐸ㅥ㌲晡〰㜸ぢ〵㜱ㄲ扣㍤挹昱㤱晢ㄶ昷愳㡢㈰㤱㤹慤搶搳〰扦晡㐰㔰㌲晣慤攷づ捤愴㥢て㝣㝦ㄱ㕤㘹ㄹ愹㕥㘳〸敦㕦ㅢ㥣户慦ㄱっ㉤敦㌶㠵ㄸ户㠳ㄲ㔸捤㘲攷㜲㜳㈶㘵ㄶ㈲ㄴ昴攳㙤㜰㍤㌷㤲挲昶ㄸ㘲㈱㕣ㄷ〸㠵ㅡ㈳㝥戱㤶扢扥づ㜷ㄶ搹摥户捤换慢晣㝦㜰摡㝣㤶㑡㐸慢づ㔴捦㐲ㅥ晡㈰收㜴㍡㥡捣愷挲攰㘰ㅡ戴㠲㠴戸愵㔱㌹㌶攵㍢㌳搸扦搱㌰慡㤷昷㤶摣㌳㡡㘰㝦㐵㌶㥢㐲㤲㐸愳㘷㤳㈸㙣敦て㐵摣㤷愱攱㝥捣㜲㌳ㄵ戵㙦戱摣㡣攲㜰〴㠳昵ㄸ敡㜰攵〶㝢㔵㔸㌸换昵㥢戲㝢愴㘶攰ㄴ挲㠷愰昳晥扣㔸攰㍦㔹昱㙡戰つ慦㠳搶挱〸昵捦㑥晣㤱㈳ㅡ搵㠷愱㑢㈰慡戸愳攲攲㄰愶㈴捡㐱搴㠷㐳慢㡦〰㔱㘹㌴㔹㈱搸捦戳㈳㈱㙡㤴攷㤹晤㌶捣㥥㉥摣㈱攰㈳㉤㄰㍥ち晡㤹ㄵ户㔰摢㤲敡捡㍢愸捡㐰挶扢愸㍥㥡愱捥〵挷㥢搳慥挹㝡㉣愴㔳㑦㔶㙥㐳挰㌰愰㘷搳㠹搳㔰㌹㌰㙥㘲㘰摤ㄹ㌰〷〶㝡㉥つ昳晥〶㜱ㅡㅣ㐷〳㙥㕤㜰ㄶ㠴摢搰㍡搶㐵ㄷ〳㡤㥤㌸愳搸㍡㘴攵㕡晢晡㝡㕡㐷慣㐲㙢〲户㉣㍥㉤㕥㝡愶戵扤搳て敤攳攱〲㘸㜳㜷挳㍤㈹て摡㈷㌰㘶〷㘳㜲㈷㘲〲敤㑥㠸慡慢〷挵晤〸ㅢ敥㜹㌰㤸挶ㄳ㑢㕤㠴㥥㠲昷㠹っ㜶㌱㕡㘵㜸㉦㠰㜴㙡扣㉦㐱㌷ㄸ〶昴㐹㜴攲㌴ㄴ户㍥摣搴挰扡㜸㥦っ〳晤㔵ㅡ㕥收㙦戰㤰〶愷搰㠰㍢㈵㠲昷㈲戴㙡捦收づ㍦㝣扢搰〵昸㙥昵挴昰攰摢捤ㄸ〹挶戸づ〶ㄳ昸昶㐰㔴㍤㥢户挱挶㠶㜷〹昴搳㤸捤㌷愰愳愰摢换㔰㌷愲㔵㠶敥㌲㐸愷㐶㤷㕢㉡㌰っ攸攵㜴攲㌴ㄴ昷㔵㝣搰㍤ㄵ〶㝡〵つ戹攷攲㘳戰㤲〶慢㘸挰㙤ㄸ㐱㜷㌵㕡㜳摣搹㡣㜷㌳㘶愶㘴戴昶㘶昲㝣晤㤳㈹ㄸ扢㌷㥦晢攰〴㜸摦改㠹敡挱晢㌴㐶㕤换愸摣㔷㤹挰扢ㅦ愲㙡扣戹戹㘲攳㍤〰晤㌴昰㝥ㄸㅤ〵敦㜵っ挵㥤㤹㌲扣㌷㐰㍡㌵摥㡦愲ㅢっ昱敡㠱㑥㥣㠶攲㌶㡥て㥣㘷挰㐰㥦㐹挳挷晤つ扥㐶㠳戳㘸昰〴っ〴敦戳搱㥡づ摥㈷晡捤敦㈴㥣〰敦愷㍤㔱㍤㜸㥦挳愸〶愳㜲ㅢ㘷〲敦㐱㠸慡昱㝥〱㌶㌶摥㐳搰㑦〳敦ㄷ搱㔱昰㑥㌱ㄴ㌷㠲捡昰㑥㐳㍡㌵摥㍢搰つ㠶〱扤㤱㑥㥣㠶攲慥㤱て摥挳㌰搰ㄹㅡ扥敡㙦㜰㉥つ㌶搱㠰㥢㑣㠲㜷ㄶ慤改攰敤晢㜴捣挳〹昰㝥摤ㄳ搵㠳户挵愸㈳㡣晡㈶っ㈶昰㍥て愲㙡扣戹㜵㘴攳㕤㠰㝥ㅡ㜸晦〸ㅤ〵敦㈲㐳㜱摦愹っ敦㔱㐸愷挶㥢晢㔳㌰っ攸捤㜴攲㌴ㄴ㌷愹㝣昰摥〲〳㍤㐶㐳㙥㘰昹ㄸ㡣搳攰㝣ㅡ㜰㑦㑢昰晥㘳戴㜶晦改攸㍢扢扦づㄷ㐰晢㕤㑦㑣て摡ㄷ㐲慢㔹㥢㉡㙥㔱㑤愰㝤㌱㐴搵㘸㜳㥦捡㐶晢㑦愰㥦〶摡摣摢ㄲ戴㉦㘱㈸㙥㜲㤵愱㝤ㄹ愴㔳愳晤ㄱ扡挱㌰愰㉦愷ㄳ愷愱戸㈳收〳收ㄵ㌰搰摦愰攱㈷晥〶㔷搲㘰㉢つ㝥つ〳㐱晢㉡戴㜶ㅦ㙤摦戹㝤㌵㕣〰敤摦㜸㘲㝡搰晥㈶㘳㕥挳㤸㍣晦〹戴晦っ㉤㥦㕡㠴扢㘲㌶摣搷㠲㥢㑥㉤挲慤㌴挱晢㕢㘰㔴㍤㐸ㄹ摥搷㐳㌰㌵摥㘱昶㐵㈲㝡㥢挳戰愱戸〱攷㠳昷つ㄰敢ㅢ㘹ㄸ昱㌷昸㜳ㅡ摣㐴〳敥搷〹摥㌷㠳愹㕤㡢昸搶㝡户愲ぢ昰攵ㄶ㥥㝢ㄲㅥ㝣㙦㠳㔸摦づ愲戸戸挷㑦㐰摦攱㌰㕣愲㠴づ㐰愳㜲摤㔱戵㈶攴㐲㌲㥡收敡戰扦㌴㥥挵㡡㥣㉣搷㈱㌶挷ㄵ㤵慤挶敡挸㉡〰摢晡捡捦ち㜶昵㕤〳㔷㡤㝢㔷㝣戲㈱摤愸搹て㘷ㄳ㌲戰㜳㔸戳㍦㌳㤸㜸㝦换㍥㍣挲摦㠶㝣敦㔵㤹愱㠲㔵戴搲愵搶㝥㙣㌸戵昲ㄳ㤸㌴㍥扤敡ち㈵攱搱㌷㈶ㄳ慢捦昳㉢捦捤㝣㈵ㅣ摤㤴户戶攴攵㙣㐲㐵㝥〹挴㘸扡愱㠱㘱愲昸㤵攳㌰愰ㄸ攳㐲㤵㥤昵㕤㘰㥡敢㘲戳㘸㠹㈳挶搵㥥㌰㕣摡〹搳敡㌰㈱㉥㠱㜶㜷慤㐵摦㙡㔰つ愹㤴㌲敢ㅢㅡ搴ㄱㄵ摦㥢㔴慤搱㜶扤戰て㠷戹㐴ぢ㥤㡤㤴㜷慦ㄳ㑦㙦〲㔱㜶摥ㄳ扦晡ㅥ挸昵扤㈰搱搸攱愰㍣愱昰㝤㘰昶㑣㜴㈷昱攲搸晢戲㍡㝣㍦攴㑤㤰换㍡ㄴ㕦攲ㄶ挳て㐰戲〷㈴攵㕦搶㠶ㅦ㠴㜸〶挴㥥扤慡搸ㄱ㤰〹㤴㐳っ㉢戱户㐳㈴㕦愰慡愳挱攱㈷愰ㅦ㜵ㄸ㑥㕡挵㠵ㅡ㈷慥㍡つ㔹㜲扡㐰ㄸ搰㥣〳ㅣ㙥戵〶ㄲづ㜹昹㤰㜱戹㈶㜱㥥〴㠳㈱㥢㈳收ㄸ㌲㉥捦㜸挴攲㉥挳昵ㄸて挵㜵ㄴ㠷㑤慤㠲㍢㐲捡昰晡㈹㐸昴搳㈰搱ㄸ㤷㔲攲㤴搰㘸攲愰㤹扡㘶愲㌱㉥戱㈶㌲摢㡦㕤㥦愳㜲㕦扡㤶㈵ㄱ㐵捦㐳㠴ㅦ昹㔶㑦㉤〰㈷㤹㜵㈱㔸㜵㘶㡢㈰慤捥㡣ぢ㈳㠹昳ㄲㄸ㘴㜶㌲摤攱㠸㝤搵㘵ㄶ扡捣㈹づ愳戸㠲㤱捣ㄶ㍡㤹〹昰㍢㈰搵慦㠰㐴㘳摤愰㌵㌳㑢戸㑡ㄹ戳㔶挴搲㍦㘴搷㠳挱愹㕥㜰昸〹攸㌷ㅣ㐶挶㙣ㄹㅡ㤲㔹扢㙦㘶挷昹㘶戶ㅣ㥤攴㈴晥〹っ㌲攳〲㠴㐷㡣㡢㄰㘱㔶扡っ㔷ㅤ㍣ㄴ搷ち㤲搹㕣㈷㌳ㄹ戳㌷㈱搵㙦㠱㐴㘳㕣㉥搴捣㙣慤慢㤴捣㡥㠲㐳晤㌶扢ㅥ㐹搷敢挰攱㈷愰㝦敡㌰㤲ㄹぢ㝦挹散㄰摦捣づ昶捤㡣攵扦㥣挴㝢㘰㤰搹ㄹ昸挳㈳挶㜲㕦㤸慦戹捣㔹づ愳㔸㤵㑢㘶戳扣㤹晤ㅣ㔲晤敦㈰搱搸㌹愰㌵㌳㘳挱㉥㑡挹㉣㡥ㄸ晡〳㜶㥤ぢづ户ㄹ㈷戳㕦㍡㡣㘴㤶㐶㐳㌲摢挳㌷戳ㄶ摦捣㌶愲㤳挴昹〴っ㌲ㅢ挶ㅦㅥ戱㡣换戰㡡ㄶ〹㉢㘹ㅥ㉡て㐶㌲㙢昶㘶昶摦㤰敡㑦㐱愲㌱㤶挰㌵㌳㘳㘹㍣㤱㔹㈷ㅣ敡晦㘵搷づ扡㤶㘲㤶愲捦㈰挲㡦㝤㥤㡤㠲㤳捣㤴㙦㘶㍢㝦敦㜷㥤戱愴㤵㌸㐱散㘸㈲㌳㤶慦㍣㘲㉣㘱㠵ㄹ㜷ㄹ搶慣㍣ㄴ㙢㑤挹散昷㜰戹敢づ㔲て〷㥡攵㐶㌴㜶㈱っ㙡㘶挶㌲㜴㈲㌳扥昳搵㑤散捡搷挸敡ㄲ㈸昱ㄳ搰㌳㈰㈲㈳㘳㜶ㄹ㌸挹散㘳〴慣扥㠳晣捡㌷戳换搱㐹攲散〹㔷挸散ち扡挳ㄱ晢㠶换㕣改㌲㕢ㅤ㐶㕤つ㐶㌲晢搰㥢搹摥㍣扤㤹㈰搱ㄸ㑢扢㥡㤹㕤攳㉡㘵㌶㈶㄰㑢ㅦ挸慥摤攰㤴㤴㘸ㄴㅤ〴ㄱ攳㐹㘶㉣搱㈴戳㜷㝤㌳晢㔷摦捣戶戹㜱づ㠵㉢㘴㜶〳摤攱㠸戱㌰ㄳ㠶㔵㤸㌰慣挴㜸愸㕢挱㐸㘶敦㌸㤹挹扤昱㜰㥥摥ㄱ㈰搱搸㙤㌰愸㤹ㄹ㡢慤㠹㌱㍢ㄵづ昵ㅣ㜶攵㡢摦搸ㅤ慥㌲㉥愷ㄳ扡ぢ敤㤳㉢㥥敤晥敦㜴㘶㔷㝥㠶扢〴㥦搵㡥挳㑢愰づ㥢搹昶ㄶ㜰㝤昰愴捦攷㡢搵〳摦〰昱㌷昴㡦挸晡て昰㠳㡣㍣昵〴㍤昲愹愰摢㜰慡㉤昷㌸改戳㐰昵ㅣㅦ㉤㜲ㅡ㡢敤扦㤱挵㉤昷扡㤶㘷慢㐳慥敢ち晤散㈲搷晣捥㡦ㅦ㍡昹㠸摢ㅦ㜳摡㌷㉦㔶摢㘱㌹ㄳ㕡㙤㤰っ㤲㜰㑥愹ㅦ㈲つ摦㌷搳慦㍢㡡捡㉦搴㘲㡦㍡㌱昵㍣ㄹㅣ昵㈴摡ㅣ㈰昵ㅡ㝡㄰ㄵ㐹㘴㍥ㄳ㜹ち攲㄰愲㑣㤹〸㙣㜰挴ㄶ户㍣敤昶㜰ㄳ㜲ㄲ搹㘹㕢〴〲㜳攳慦㝥昶捤㜵扤㉦搸敤㍤ㄷ慢攷搰挳㉦戱ㅤ戵ㄲ㝢搹㔱㔴㝥㜹ㄶ㝢ㅥ㥥㘴㑡㥥㘲㈷昶ㄲ摡㤲搸㡢摥挴ㄶ㌳戱ㅤ㡥改㤴㠹戵戰㑣愰搳戰㥢㤰㝤攲㠱㐰搵〸晤㄰㤶㝥㠹㍣㔷㉢㤱敦㍡㡡捡㉦挸㘲㙦㌸㌱㜵慦㥤〸换〲㐹攴㔹㙦㈲换㤸〸ㅦ昸搳ㅢ愱户摣ㅥ㤳㈷戴㝣戱㥤攸攱㡢搵摢攸攱㤷搸㔳戵ㄲ晢㡥愳愸晣㌲㉣昶㔳㜸㤲ㄱ㕡㙤㈷昶ㅥ摡㤲搸ㄳ摥挴晡㤸搸捦摤搳㜴昱戶晦㔶㕦㐳戶ㅣ㔳㡦挵㠱㐰戱摢㠹戱㌰昰㑢㙣㝢慤挴ㅥ㜶ㄴ㤵㕦㝣挵㝥〹㑦㤲搸㝡㍢㌱ㄶ〵㤲搸㠳摥挴㑥㘷㘲㝣摣㑦㙦挴㍥㜵㝢散㜶㘲慣ぢ晣ㄲ扢愷㔶㘲㜷㍢㡡捡㉦戹㘲㥦挱㤳㈴昶㐷㜶㘲慣〹㈴戱扦昰㈶㜶づㄳ攳搳㝥㝡㠹戱㌴㈸ㅢ戱㈹㙦ㄶ㉣ぢ晣ㄲ扢慤㔶㘲户㍡㡡捡㉦戴㘲慣㈶㈴戱㌴㤸收㍡挵㤲㐰ㄲ扢搹㥢搸㌰愴㉤㝣搸㑦㉦㌱㔶〶搳㑢㡣㔵㠱㕦㘲摢㙡㈵㜶扤愳愸晣昲㉡挶㘲㐲ㄲ换㠳㐱㘲慣〸㈴戱㙦㜹ㄳㅢ㠱戴㠵捦㝡㥡㑥㝤ㄷ㘴㐱㈰㤶㤳㑦㐱㍣愷㔸〴昸㈵㜲㜵慤㐴晥搴㔱㔴㝤㐱挵摡㘱慡㉦愸㍣晦㉥愹〵㠹㠴搲摣慥㘹㑣摢㘲㍥敥戱㘱㤳挹㘶㘵慦愳〹ㅦ㌷ㄴ昰㉦㠳㔶攲㌳ㅥ㝣搲㠰㝦㙤敡㉣摢昱㜹て摦ㄵ扢慦捦戵戴搸㌹㥣㕥㔳挰晢昴㠶昴昲㈲扥挷㑡㐵昰㉦ㅢ㑡㈵晣ぢ搵㉦挳㤷て搸㝤攲〵㠷挳晥收挱㜷攳㠷㍢㍡㤳㝣㤴㌲㠱㠷晢て㝥㠲晣㈶攲昳㝤㥡ㄵ摥㡣搳搹挷昹戲愷㌵㔵昶挱㑦㔰㙤挵㈸摢㑢晡㡢〳㑥㉤㄰挴愶㌸扡㐸㉤㈳攵㉦㐸㔴㥦㑦搱㍡㥣户㤰㐰㠸〵㔵㘵㙥摣㠹攳愳㌱㔰昱慦㜶ㅡㅢ摤㥤㌲攸〲㡡昵つ㈷㔱昸〲㤰㤹昶ぢ昳㡡ㄳ慢㔷㤷晡㥥搸㠵攸㔱㜱㘲ㄷ㔳㌴㜱㘲㡡〵ㄲ㑦捥㍤ㄴ慢づ〹㜷〹㤸㥡㐰㝣摤㌷摥㘵攸㔲ㄱ敦ち㡡㍣昱㔸户㤴挵㈳〲ㄲ敦㑡㌰戵搲摢攲ㅢ敥㉡晡ㅥ攴㤹攳昶㑥ㄲ搵㔷㔳攴〹挷敡愲㉣摣㙡〸㈴摣㌵㘰㙡㠵㍢捦㌷摣戵昴㍤㔸ㄶ敥㍡㡡㍣攱晡搰㉥ぢ挷〷愹㠴摢〶愶㔶戸㑤扥攱㙥愴敦挱戲㜰㌷㔱攴〹挷㈷㜱㔹㌸㍥摥㈴摣㉤㘰㙡㠵㌳㝤挳摤㐶摦㠳㘵攱敥愰挸ㄳ㡥捦挷戲㜰㝣攸㐸戸㙦㠳愹ㄵ㉥改ㅢ敥㉥晡ㅥ㉣ぢ㜷て㐵㥥㜰㝣㙡㤵㠵换㐳㈰攱敥〳㔳㜳㙡㥥攱ㅢ敦〱㍡ㅦ㉣㡢昷㄰㐵㥥㜸㈳㘸㝢攳㠵㜸㕤敦昶㝤㠷㔳㜰㉦摣愱㥤晦扤〵㍦㉤㥢㥤攵晦摣挲敦㑢愵昲㉦昹戶㈳㡥攲ㅤ㠳㍥昴㈳づ挳㠶攲ㄵ捣搳搰㡦㔲捡㡢㔷㙣ㅥ㜳ㄸ戱攱㔵㈷㌶㡦㔳捡ぢ㑥㙣㥥昰摡㕣攵摡㍣㐹㈹慦ㄲ戱昹㡥搷收㕡搷收㈹㑡㌹戵挵收㘹慦つ㈷愵挴晡㑢㑡㙦㜲㙤㥥昱摡㜰㈶㠹捤㕦㔱捡㐹㈴㝥㥥昵摡㜰昸挵收慦㈹攵挸㡢捤㜷扤㌶ㅣ㌲戱㜹㡥㔲㡥㤶搸㝣捦㙢㈳搰ㄱ戵攷㈱㜵㡦ㄸ㈱㤴攲攱㙦挰愰㜸㄰昰慡慣〸愲㔸扤㘸㕢〹㝣㔵㔶㠴㔱慣㕥戶慤〴挰㉡㉢〲㈹㔶慦搸㔶〲㘱㤵ㄵ愱ㄴ慢敦摢㔶〲㘲㤵ㄵ挱ㄴ慢搷㙣㉢㠱戱捡㡡㜰㡡搵敢戶㤵〰㔹㘵㐵㐰挵敡敦㙣㉢㠱戲捡㡡㤰㡡搵摦㡢㔵捣〵㔳ㄱ㍦愹扡摡㜰㔱㜱㔱摤㡤扥ㄱ扣晤㈳㘴愲㌸慥㐲㐱㤴㐴ㄱ慦㔰㄰ㄸ㔱捣慤㔰㄰ぢ㔱捣愹㔰㌰㝤㔱捣慥㔰㌰㘳㔱ㅣ㕢愱㘰㤲愲㌸愶㐲挱扣㐴㜱㜴戹愲昱晦〰㑦㤸㈳㍤ | D27: 㜸〱捤㕣ぢ㜴ㅣ挵㤵㥤ㅡ㘹㐶㔳㈳挹ㅡ挰㠰〹㍦〱㌶㌶搸ㅥ敢㙦ㅢ㘲搰捦ㅦㄹ昹㠳㈵㝦昸㘵㘸㘹㝡慣挱昳ㄱ㌳㈳摢㈲〹㄰〷㥣㐰〸㈱づ㄰㠸㈱㘴ㄳ㤲昰㕢晥㙣㌶ぢ㑢㠲㈱戰〹〹㝢㜶て〹㥢㉣昹戱㐹㜶㑦〲㔹㈰㥢攴散㌹〱敦扤慦扢愵㥥㤹ㅥ挹㜲搸㜳㈸攴愷㔷慦㕥搵慢㜷慢扡晢扤敡ㄶ㍥攵昳昹づ愲昰㌷㑢㌵㤹ㄳ〶挶昳〵㌳ㅤ敤挹愶㔲收㜰㈱㤹捤攴愳㕤戹㥣㌱摥㥦捣ㄷ慡愰㄰㡣㈵搱㥥て挴昲挹㉢捣㔰㙣愷㤹换㐳㈹攰昳㠵㐲摡㡦㜶㙤晦㡢㑣㔴搸㑢㔷㤳㐰换愷㠳㈴㌵㈴㈱ㄲ搱て㤳慢〵愹慢〳ㄹ散改摥㌰㜴ㄹ慣てㄴ戲㌹㜳㔱攳ㄶ换挶㡡收收㘸㜳戴扤㘹㘹㑢戴㘹㔱㘳捦㔸慡㌰㤶㌳㔷㘴捣戱㐲捥㐸㉤㙡摣㌸㌶㤴㑡づ㥦㘷㡥て㘶㜷㤸㤹ㄵ收㔰㔳敢㤰搱戶慣戹慤扤㍤戱㝣昹戲扡㝡㡣扣扥愷㝢㘳捥㑣攴摦慢㌱㘷㜱捣つ㍤摤搱昵㘶攱扤ㅡ戳〱㘳㘲挸摥㙣摡㐸㘶摥愳㐱〳㕣㠳昶㕥㜳㌸挹挵㌲捤㕣㌲戳㍤㡡㘹ㄷ〱㡤摡搲㘸㔷㍥㍦㤶ㅥ攵扡昷㤸愹搴㈶㌳㈱㡢㤴敥捤ㄷ㌶ㅡ戹㜴扥㉥㑤晣捣㥣㤹ㄹ㌶昳戳搲㉢㜷て㥢㈹㕢㌱ㅦ㑡㙦㌱㜲敢㡤戴㔹㑤愶㈱㙤慤㘱㕦摣捣ㄴ㤲㠵昱晡昴收扣戹挹挸㙣㌷愹ㄲ㐸慦ㅥ㑢挶㔵㜵㌵㝥㝣㔵昳扤㘶㈶ぢ㠵昹愴㝢㐶㡣㕣㐱㙡㕣挲㘶㉦㕤搷㜶ㄱ㉦㡡收挵㉤搵㔸搲㡢㙢㌶㤰㑣㥦㘷收㌲㘶㡡㐶戸㤲ぢ㑢㤴〴㈰㙢ㅤ㈶㤰㜲摣攱㉡愹㕡晢㘲愱㉦戴ㄲ㡣㠰昴慣捦收搲搸㤰晤搹㥥戱挲㡡收愶㘸㐷换愲㌵㐹㥢㕦摡扡㘸㥤㘹㘴㐴扣㜴搱㐰㈱摥㙢敥㕣搱ㅣ㙤敡㔸摡搲搱搱摡摥扡扣慤愳戹愳㘹戹㍥〲〳改㈳㌹攴㔱㈰攱㑤收㜰㉣㤵扤㉣搶搲愶㘷戳攵㘸㄰㔵晤㕢㕣扣敥㈹昰〲昲挷っ㝦㙣挸ㅦㅢ昶挷攲晥㤸改㡦㈵晣戱敤晥搸㠸㍦㤶昴挷㉥昳挷㜶㐰挷㈹愱㥡ㅡ扦㕤㜶捣ㅦ扥㙡摥㉢㤱㜵晢㘶㐷昶扤戶敤攵㘳ㄴ慦㔷戹摣㡦〵搳㔲攴㔲㤳敤挲戲昶愵搱收戶㘵㙤㉤ㅤ㉤慤捤慤换㕢㈶晣㘹㕤ㅡ㙤搳㜳搰㑦ㅦ〷ㄲ晣〰㐸挳愰㤱㌶㌲㈳㔹㝡㘱挴㕡摡昵昱㙣㍥〱㐴愹晦㠰ㅢ㜴攵㤹て敦昵㕦扦攳扣戵户扥㘸扣晥愹晤昷㙣㔵扣㕤挸ㅣ㑥〲㜳㙣敦挶㙣㌲㥦捦㘶㙣㘰㥢ㄶ㙤㌲ち收㡡㜶㝤㌲㐷㙡〴〹㥥〲ㄲ改㠷㠱㝣捣ㄸ㌲㜳〵晣〶㘰愷戲晤㌴㄰愵㕥戵㉤㕤戴晥摡慤扦㝡攷㌷ㅢ慥㕢ㄸ扣攳㠰㜹㈰慦㜸㑦ㄲ㑢昳挰捣昱戶搴摣愴㑦攷㔰昳㐱㠲ぢ㐰㑡㑤戵敢㌳搸㝥㈶㠸㔲㍦戴㑤つ㝣敡㥡ㅤ晦戴㝤捥慡㑦敦晤挱㡦㝦ㄷ㐹摦慡㜸攷ㄳ㔳㡢挰㑣戱㔷㥡愳慤㤳㝢㘵昹〴戶搸㉢换㤷戶㌶㉦敢㘸㙥敤㘸㙥㙦㙡㙢敢搰㡢㘹㌵ちㄲ㕣〲㔲㙢敦ㄵ愰摣愱㥢搸搴っ愲搴㑢昶㠴晡敥扢㘰摥㘷敥㍤戹晢㘳㙦〴㕦㔸扤敤㡤㥤㡡ㄷ戸㑣愸ㄵ㑣㘵摦摢㌸㔴㍢㐸戰〳愴搴昷づ扤㤴敤换㐰㤴㝡挱㌶㜵㔳晡敤晦㍡慢㘳㕢攷户昶收昶㕣晡扤㘷晥㔳昱㕥㉦愶捥〲㜳㌸㥢敡㙣ㅡ昹㈰㐸㜰〵㐸挹愶敡搰攷戰昹㕣㄰愵扥㙤捦攱㐷㍦摦㝦搶㡦㕢㝦摤晤昹昸昳扤㠳㥢㘲愷㈹㍥㙡㘴づ㕤㘰㌶ㄶ㙤散愲㙢ㄵ㐰㑦攲扦慣愵㘵㜹㑢摢戲搶愵换㥡㍡㥡摡㍢㕣ㄷ㙥㐹㡢敥收ㄴ㝡㐰㠲扤㈰慥挵㘸搷㉢搹戴ち㐴愹㙦摡戳㍢昱㉦㍤慢ㄲ㈷摦戴收戱㝢捤㤶晤戳扦户㐵昱ㄲ㤶搹慤〱㜳㌸〸昵搱挸㕡㤰攰㜹㈰㈵〸戵改㝥㌶慦〳㔱敡㔱㝢づ扦㙤㕤昳愱摢摦㍤搸㝦换㤳摢㕥晡捤晣愷敦慡摢㠰收昳敤㍢㕢㙦捥搸㠵㘷挵攴㘳〸捦㕥晥㌷晤昳ㄷ㡦摦㐴㝢㘲㘹愲戹㌹摥摥㘴戴ㅡ〱摥搲づ昵㐶捦晢㘸㕤㘲㙢㌲ㄳ捦敥㤲㍢晦〹摤㐶摥㥣㝣㄰㉣戴摢扡戳㘳㤹㜸晥㜸敦挶㠱〲㙥㄰ㅦ㈸㙤㥢ㅣ愴慣摢〰㥥㡢㘶㕥散㥤㔴摡㙤㡢㤱ㅡ㌳扢㜶㈷慤收ㄳ㑢㥡昱㔴捣づ㔵㙥㕤㤵㌳㉦㥦㘸㉤㥢㔱ㄷ挲慣㥤㌲㜶㤹㤷㔶㤳㌵慦挶㥥㤱㙣摥捣挸昴ㄶ愶㌷㈶㠷㜷㤸戹〱㤳㐱㥡ㄹㄷ㔷㡦㘶㤳晤㘸㕥戸㈱〳㐷昱戰㡤㥦敡㤶㈶㔶敥㉥㤸㤹戸ㄹ挷㝣㐷㜱㠷ㅣㅦ㌴㠶㔲收㌱㐵㉡㤶㑤㌴ㅣ㔷㈴㕥㤵ㅤㅥ换昷㘴㌳㠵㕣㌶㔵摣搲ㄵ摦㘹㈰ㅣ㠸慦换挶㑤㍣捤慢㔹㝣捡㔷㔵愵㤴敦㑣慦㐷㉡挷捤㐷㘵㈱㕣㑢捣㠷晢㥣攲㙤ㄷ挵扤慣〰㉦㔲㈶昷愴㝦敥㌴㠳挹戸ㅣ收㡣捡㡡㉥㥦ㄸ搱㔲㝢㐱㘵㙤㤹攳挴捡晤晦㉡晢晤㐷搹摥慦摣㠹㤰㘹㡤㤱㠹愷捣摣㤴昱戸攲㡣昴㐶㤰挰㐳戸㥡㉢愲挷㠷戹摡慤挶〳扢㤲昱挲㐸㜰挴㑣㙥ㅦ㈹㐰㠶㤸㍤ㄴ㈲戴㘵㐵㙦㠲㐸て㤰っ㠲㠴挳扥攰㘶㉡〵挳㝡㡢㔵て㌰㍡㤹㜹㌰㈶㔹㠱〴㝦㠸搴昳㠱昴慡㙣㉥㕦㔵攵攵攵ㅡ㈳㍦㔲攰昶㥣戲㤱㘱㤷摥㑡戲つ㈴挰攸㘸摡㔸慦〱㑡搵っ㘹敢搳扤㘶挲㐰㈲㈱㔷户㌲〲㘹㉢㌶敤㌵昳挳㥡㐱㙣ㅦ慥㤵摤㐱㜰戸昸敢搲摣晤收敥㐲慦㔱㌰㙡搲〸㠷戱㑡ㅡ㑡ぢ愵㤷挵戱㘷扤挸㥣摥㘱扢㠶ㄱ㈲挲扡㐶愹ㄵ㠱㌵ㄲ㉥ㅣ㕣㉦扥㉡㥢㑥敤〴收捥㠰㌵㔸扡搱㡢挳㕡㐴摢昱搵㘶㘶㜰㝣ㄴ戱㍡搴㐳挱㈹愱㉣扤扣㌸搸㠶攱愱捤㠵㘴㉡ㅦ挵㑣㔷攷戲㘳愳敦攵㌸ㅣ㑢㕦〰攲㤴挰搷戰㡢て摤㈷收慢㌵㍢戹㌶戱㤸㉦挴搱㈸搱㡣㤸㌵㜷㉢〶㍢㠸㕦㔲昴㈵昸ㄵ㥥慡㉤挰愰㝡㈶㈹〰挳搳扡㌴㄰ㅡ捣㤹㤲搴㠴愴〲戴敢搳㕢戳戹ㅤ㐳搹散づ敥愷㔹㔲换㡦㤸㘶㠱㠹㐲慤㥤ㄸ㐹〲愴㔴㔵㔵㔱〸敦捡㈸戸㑤㠳〶挸㠹㠳搹㜸㌶摦㠸㥦慥摣攵㘳挹㥤㘰攲㘶攳㘰捥ㄸ㌲㔲㈳搹攰㄰㔴慡㤰挲〴㠷挱戴昴慣散敡㙥攵㠶㌵㤸挴昱㥥㥣捡㙥戹戰㙢昱㍡愳㤰㑢㕥ㄱ㌷〷捣㑣㍥㌹㤴㑣㈵攳㐶摣㡣敥㑥攵㜷慢㍢㠰ㄳ〳昰㌷扥㜴收㤲扢㡦摣搷昷戱㥦晥攴昶摡㈷晦昷〳㙡扦摤㔰㤶ㅤ㌰戸㤷ㄴ㈵〱㐶摤づ㌵摥㝦挰ㄷㄷ㍤㠲扡㑥㤲㕣〶㠲扢㠸慣ぢ㙥㈲㈹慢慡㤸㈰昰㐶愲搳㈴ㄹ㄰挵捣㠰㤷戱捥㠲㌸㐵摤㠴昱戹㍢㘴㠵㤹㔱㤴慦㜰ㅥ搲戰㥥愲㑤㌱摦攰㉡㙢愲慡㠹㥢㈶㘶㙡㉦〶昶〴攰㕡扢愱㉣㌵㘱搲㈱〰㝣㠴晤㍦づ㌵㙦〰慥愴㡤慢㐸慥〶㜱〱戰挷慡慡㐶晣ㄶ〰㍥づ㐶㕦〳愲㑥〵ㄱ〰慥〵攳ㄴ㜵〵㙣㑣〰㜰ち挴攵〰㕣〷㘹㔸㑦搱愶㑥㠳㠶ㄷ〰愳㤵〰挸摡つ㘵ㄹㄳ㔳㈱〱㘰ㅦㄸ㤵慥〸挰捤㘸搶户㤰摣ち攲〲攰㌶慢慡㤸㑥〹〰户㔳改ぢ㈰敡っ㄰〱㘰㍦ㄸ愷愸戸ㅢ〰收㕦攵〰摣〵㘹㔸㑦搱愶㤸㥣㜹〱㜰㘱㈵〰㉥戰ㅢ捡昲戸挵ㄸ㐹〰戸〷㡣摡㕡ㄱ㠰晢搰慣敦㈷㜹〰挴〵挰㠳㔶㔵㐵昱㕢〰㜸㠸㑡て㠳㈸愶㙤〲挰㈳㘰㥣愲搶扢〱㔸〲㜱㌹〰㑦㐰ㅡ搶㔳戴愹㘶㘸㜸〱搰㕢〹㠰ㅥ扢愱㉣㙦㙣挳㐸〲挰搳㘰㔴㔷㐵〰扥㡤㘶晤っ挹〱㄰ㄷ〰捦㔹㔵搵㡥摦〲挰㜷愸昴㍣㠸㘲㌲㈹〰扣〰挶㈹㙡㤹ㅢ〰㘶愱攵〰扣〸㘹㔸㑦搱愶㤸愲㝡〱㄰慤〴挰㘲扢愱㉣㥢㘵㌲㉡〰扣っ㐶㉤慣〸挰㡦搰慣㕦㈱昹㌷㄰ㄷ〰㍦戱慡㡡〹慤〰昰敦㔴㝡ㄵ㐴㌱㤳ㄵ〰㝥ち挶㈹敡㔴㌷〰捣㠰换〱昸㈵愴㘱㍤㐵㥢㍡ㄷㅡ㕥〰捣愹〴挰戱㜶㐳㔹㉡摤㡤㤱〴㠰摦㠲㔱㐷㔷〴攰㜵㌴敢㌷㐸㝥て攲〲攰㑤慢慡㝡昰㕢〰㜸㡢㑡㙦㠳㈸㈶换〲挰ㅦ挰㌸㐵搵戹〱㘰㠲㕤づ挰㥦㈱つ敢㈹摡ㄴ㔳㜰㉦〰晣㤵〰㔰㜶㐳㔹戶捥㘴㕢〰㘰攰愱づ扥㕢改㈹攰㐷戳慥㈲攱ㄹ扢ぢ㠰愰㔵㔵㙢㌱㤰〰㔰㐳愵㄰㠸敡㠷㐸〰搰愸㌹㐵晤〹㌶㈶㥥〲捣昰换〱愸攷㤸㝡㡡㌶戵づ晤扣〰㜸ㅤ㠳㝢㍥〶㝦㘷㌷㤴ㅥㄵ〴㤸㝡捣㈰挵慢攵㠴ㄳ㕢㤲收㉥挶愴戳ㄲ㌸ㄱ敥ㄹ换ㄷ戲ㄲ㐰搷㈷㝡戳敢戳㠵摥㘴㝥㌴㘵㡣ㅦ㤵戰㤹慤㈳㘶〶改㙤づ㔹㙥㠹㉣㍢㍡㙡挶㜵㘲㈰㍢㤶ㅢ㌶晢㝡摦て改㉦晣挳搲㐹收敢㔷㈸㠷㤷搱攱㜰㐶昹㠲挷㘰ㅤ㙢〷挷攲搹愸㜵㐸ㄵ㐶昱〵㌶挱㐰㘹愰㉥攷搴慥愴㕡搸〸ㄴㅢ㈶ㄱㅥ㑣ㄶ㔲㘶㙤㐲ㄲ㕡攱㐳〹愰㡡㌳㠴㜸㑤㘲㜰〴〱㙣㙦㝤㘲㜵㉥ㄹ㑦㈵㌳㈶ㄷ㘷戶愵摡㙦㙥挷㜹挱挶㙣㍥挹㘸戲㍥㠱愰㌳㤳ㅦ㘵敡㌳㍣㝥㘴㔱㑤㜲愴㐰愲㍢㤹挹挳㡣慣㉡昹㠶挴挰㐸㜶ㄷ摥㈶㡤愵㌳慢㡤搱晣晢㘲㤵㈶慦㈸㔹㉡攵㔷㝥扦ち昹㐳㠷扢㕥挱㘳㌱攲搱搸戰〸戱㠷挶㤲捦㝥晤搹慦㘴ㅢ慤㔵攳㠶昰戵攰㕦㌵〹慥㝤㉥㈲昳敡搲㌴挷戵㠸㈵㘷ㄴ㥣㙤搱㝢ㄷ捦㜴㜹攲㈵㕤㍤搴昵ㅣ㜴慡㍢づ㘴敤敡捤㝤㤳愷㜷㝦搵ㅢ戴挰㈰㐶㍥攴挳ㄲ摥㘰㘶㔹㥢㠸〷㈸摣㔳戸㔶戱ㄷ㔸㉢摤㤸攱㠴攸㜰㡦捥㥡㘴㔷㈱摦慥㑢昴攳㉣㍦㠵㘳㠲戴㔱㤸㘵㔵㜸㕥㠳㌷㉣㜹扢慤㈷㥢㑥ㅢ摣㜴㝣㑦㌴㌰㙣愴捣㔰愲㙢慣㤰㕤㤷捣攸〴㠸散㑣㕢㘴散㠶挸搸㉤愲扡挴㈶ㅥㅦち捦戱戲摢㡤㕣戲㌰㤲㑥づ㠷㔸攱ㄱ摦晢㘲户攲㡥㔲つ㌰㥤攲摣㕤㑡㑦〸慣㍣ㅤ换ㅤ挵愱ㅡ愱攳昲㘳㑦晢㔵㄰晦愹挳㍣㕤挲扤㐸ㅥ㌱晡㜸㡣ㄶ昰㘳ㄲ扣㌹㐹㜹搳㜹㜳晣收㔵㤰挸捥㔶㕢愸㠰㝦晡〴㔰㌲晣㔷捤昳㤹㈹㡦ㅥ昸㔲㈴摣㥦㌵攲慢㡣㘱扣昳慤戱摦昸㠶戰戴扣搹攴㈲㍣っ敡㐱㉥㡢㜳换㥤挹戸㤹ぢ㔱㌰㠰㌷搰搵㍣㐶ち㕡㙢㠸㌴戸捡ㄷ〸搴㠶扣㙣昵㌹㘳捤戵㔳㙣昷ㅢ敥扥戲昱㕦㍦㝦ㄹ〳㈵戸㔵〵慡㑦㠴ㅦ晡㈴晡戴つ㔵晡㔳愲㜰㌲ㄵㅡ㐱〲㍣搰㈸㕤㥢攲㜳ㄹ㥣摥㘸㈸㔵换扢㔲㥥ㄸ㠵㜰扡㈲㐷㑤〱㜱愴搶㜵㐴ㄴ戴㑥㠷㐲捥ぢ搸攰〰㜶戹ㄹて㕢㜷㔸ㅥ㐵㜱㌹晣晥㙡㉣㜵戰昴㜸扤捣㉣〶㑢て㤸㜲㜶愴㘶㘱ち挱㔳搰㜹㌱㉦ㄶ㡣ㅦ挳㘹慢㤹㉣ㄸ㡤㝣㠵搶戸捥㠸㡦攵㡣挶〵㥢收㌶愶㤳愹㈵改〳㡦㥥搱㜸攰ㅢ㡤换换〲㡥㜰㔸㥦㠶㔱㝣㘱挵㈳ㄶ〷㥡㈰㈵㘱慥慢㥥㡢㔶㍤て㐴㈵㔰㘵挸㘰㍤攰㑥㠷愸散〱愷㜸㘴挰㠷㥣㉦㌸ㅦ敤㠷㝥㔳㔵㐹昴攱㡤㔵㉦愰愹换挰昱㝥㌵戱㝦捦㠴㜴晡晤换㜳〹㈸晡昴㐲づ㘲㔷㔴ㅡ㡣攳ㄸ㔸㘷㔳㉣㠲㠲㕥㑣挵㡣户㐲㤴ち㑢愸挰戳っ㙥㡣㘰ㄳ㙡昳ㅤ挰敤㤷愲㡤敢㥥扤㌷㥥捣㕡戸㉦㜰㤰挶晢挶捤攸㠱搸昳㈰㝥㐹〱搴㉤攸て愸㜹搶攱捣挸〵㜵㉢つ戶搱㈰捦㈵㈶愱㙥㠷愸㑥㘲〹晢㈵慡㜵戵昲㜴挲挲扡〳ち挷㤴㍣挰㙣㔵攸㤴㍤挱搴㔵㤰〹搸㑢㘹散㙡搴㡡挰㕥づ改昴㘰敦㐱㌷㈸晡昴㔹ㅣ挴慥㈸ㅥ㠴㌸慥㠱㜵挰㍥ㅢち晡㠳㔴扣挶㕢㘱〵ㄵ捥愱〲捦㑤〴散㜳㔱㍢捥〱㝢晤㠶㉤㕤〳戱晥つ㙢㐱㕢㥡㕡摡㔶㝡挱摢㠵ㅥ㠰昷㍡㤷〹ㄷ扣摤㌴搱㐳ㄳ晢愰㌰〹㙦㉦㐴ㅥ昰摥っ㈵ぢ摥㤵㔰㤸〹扣户愰愷挰扢㡡挶㙥㐵慤〸摥㌵㤰㑥て㉦㑦㔸愰攸搳㝤ㅣ挴慥㈸ㅥ戳㜸挰扢ㄶち晡㍣㉡昲〸挶㐳愱㥦ち敢愸挰㔳ㄹ㠱㜷㍤㙡㤵攰㙤昷㠴㜷㈳㝡〰摥扢㕣㈶㕣昰㥥㑦ㄳ㥢㘸㠲㘷㉡㤳昰づ㐰㔴㝥愳攰挱㡡㠵敥㈰摡㘷㜰愳戸ㅦㅤ〵摣捤㌴挵㔳㤹㈲㜰户㐲㍡㍤戸て愲ㅢㄴ昱摡㠱㠳搸ㄵ挵㈳ㅣて散㉥㠰㠲扥㤰㡡て㝢㉢㕣㐴㠵㡢愹昰〸ㄴ〴摣㑢㔰㡢㍡㝢昷㔰敥捣捤捤㕥ㅢ㍡㠶㘱㠰昸ㄳ㉥扢㉥挴㉦愵㕤㠳㜶㜹㠸㌳㠹昸㄰㐴ㅥㅢ晡摢㔰戲㈰ㅦ㠶挲㑣㌶昴㌳攸㈹㤸挷㘹㡣〷㐱㐵㤸㈷㈰㥤ㅥ昳攷搰つ㡡㍥扤㥤㠳搸ㄵ挵㔳㈳て捣㐷愰愰㤳㔴㝣摥㕢攱㌲㉡散愰〲て㤹〴昳ㄴ㙡㤵㌶㜴㠷攷㠶捥愰〷攰㝤搱㘵挲〵㙦㤶㈶㐶㘹攲㘵㈸㑣挲㝢㌹㐴攵ㅢ㥡攷㐴ㄶ扡㌹戴捦㘰㐳扦㠲㡥〲㙥㥥愶㜸挸㔴〴敥ㄸ愴搳㠳换挳㈸㈸晡昴㑥づ㘲㔷ㄴ㑦愴㍣挰摤〵〵扤㥢㡡㍣慤昲㔰ㄸ愷挲ㄵ㔴攰〱㤶㠰晢㘱搴づ昱挹攷戹㤳㍦㡡晥㠰晡㤷㉥㠳㉥愸慦㐴慢㘶ㅣ慡㜸ㄸ㌵〹昵搵㄰㤵㐳捤ㄳ㈹ぢ敡㡦愱㝤〶㔰昳ㄴ㑢愰摥㐳㔳㍣捥㉡㠲晡ㅡ㐸愷㠷晡㑤㜴㠳愲㑦㕦换㐱散㡡攲搹㤷〷㤲㝢愱愰㍦㐱挵户扤ㄵ㍥㐹㠵敢愸昰〷㈸〸搴搷愳㌶戳㝢㠷㘷慣㜱〳㠶〱攲㝦㜶搹㜵㈱晥㘹摡扤㤱㜶改挳㈴攲㥦㐱慤ㅣ㜱ㅥ㠱㔹㠸摦〴㙥〶㠸昳搸㑣㄰晦㉣ㄸ㔵つ㔲㠴昸攷㈰㤸ㅥ昱㈰晢挲つ㝤戳捤戰愲㜸搸收㠱昸㉤㄰敢㕢愹ㄸ昲㔶昸㍣ㄵ㙥愳〲捦收〴昱摢挱㥣敥摣慤愷っ敢㍣〳攸晤攸づ愴㜹㜴攷㑣挸㠵昴ㅤ㄰敢㍢㐱ㄴ搳㝡晣昸昴ㄷ㙤㠶挹㐹攰㜸㔴㑡㌳㡥戲㙣㤰㈹㘴㌸挱扣㜰愰㌰㥥㐲㉥㑥㤶ㄹ㠸挵㌱㤷戲㥡㤱ㄷ㘵㜳挰戹扡昴㜳㠲㠹扥ㅢ㌰㔴敤散㤲㑦㌵愴ㅢ㕢㡥挳㙣〲〶㑥っ㉢昶愷〷㤳敦㙤搹㠷㈵昸㈵挸㘷慦㑢づ攷戲昹㙣愲搰㌸㠰㤳愶㐶㝥晡㤲昰昹㥡扡〲㌱㡣攸㘹㤳㡥㔵㘷昸㑤改㑥扥ちづ敦挸㘴㜷㘵㘴㌶㠱㍣扦〰愲㌵㕤㔳㐳㌳㘱晣㤳㜲ㅡ㔰㡣㌰㐵㘵㘷晤㘵㌰昵㔵㤱ㄳ愹㠹ㄲ㘱㥥㈷っ㤳㍡㘱ㅡ㙤㈶挰㑣攷㔰戳㉣㡥慤㠶搴戰㡡㉢戳扡愶㐶捤㉢昹捥愴㉣㍢㥢㜸㔱ㅦっ㌲㌹ぢ㕣〲㤷て慤ㄳ愷㌷㠹㈸㍢㑢搶㝡㌷攴晡慢㈰攱挸㕣㔰㑥㈸昸㌵㌰㐷昶㜴挷昰挲搸晤㤲㍡昸㜵挸敢㈰㤷っㄴ摦晤收㠳昷㐰㜲〴㈴挵摦昱〶敦㠵㜸ㄶ挴慥㔳慡挸㍣挸〴捡㘱㤸㤰敦㔶昵〳㄰挹㘷慣㙡〱㌸晣昸昴㠳㌶挳戹㈹收㘳摣戸敡㝣㜸挹敤〲愱㑦㜳て㜰戹搵〶㐸戸攴挵㑢挶慣㑣散㍣ち〶㑢戶㐸搴戱㘴捣挲㔸㈲㔱㠷㘱摡挵愲㤸㌱㜱搹搴㍡っ㐷㐸〵㥡挷㈱搱㑦㠰㠴㈳㑣㥡㘴㔰㐲愳㠹㠳愶敢㥡㡥㐶㤸㑣㑤㝡㜶ㅣ〶搴㑦戱㜱づ㠷㤶攴㠷愲愷㈱挲㡦愰慥㤶㠳ㄳ捦扡㘰慣摣戳㜳㈱㉤昷㡣㈹㤰搸㌹〰〶㥥㥤捤攱㔰㈲ㅦ㜴㤸ㄵづ㜳㡥捤㈸㈶㉢攲搹ち摢戳㈳搱㐱㍦〷愹晥づ㐸㌸搲つ㕡搱戳ㅥ愷㔱搶慣㤱㕤扦捦慥㈷㠳㔳慢挰攱挷愷㕦戲ㄹ㔹戳㌵愸㠸㘷捤㥥㥥㉤昱昴慣て㥤㘴ㄲ晦ち〶㥥㌱搳㘰㠹㌰摢㄰愶摦㘱㤸㕥戰㈸收〹攲搹㘲户㘷㉦㐳慡㝦〸ㄲ㡥㌰㔵愸攸搹㈶愷㔱㍣㥢㡦〱昵慢散㝡㍡㠷摥っづ㍦㍥晤㌳㥢ㄱ捦ㄸ昴㡢㘷愷㜸㝡㜶戲愷㘷っ晤㘵ㄲ慦㠱㠱㘷ㄷ攰ㄷ㑢㠴愱扥㌰ㄷ㌹捣挵㌶愳ㄸ㡦㡢㘷㈷摡㥥搱扣晥ㄵ愴晡搷㈰攱挸愵愰ㄵ㍤㘳愸㉥㡤攲㔹㤴㕤㕦㘷搷挵攰㜰㥢戱㍤晢扤捤㠸㘷〹㔴挴戳㈳㍣㍤㙢昰昴㙣㍢㍡㠹㥤户挱挰戳ㄱ晣㘲㠹㈴ㅤ㠶搱戳㐸ㄸ㐱戳愸っㄸ昱慣摥昶㑣㜶攳晦㐰慡晦〸ㄲ㡥㌰ㅡ慥攸ㄹ愳攴㐹捦摡㌱愰晥ぢ扢戶㜱㘸㠹㙢㈹㝡ㄷ㈲晣㔸搷搹ㄸ㌸昱㑣㜹㝡㜶昰ㅤ慦敢㡣搱慤搸昱攳㉣ㄳ㥥㌱㤲㘵㠹㌰㥡ㄵ㘶摣㘱ㄸ扥戲㈸㐶㥥攲搹㍢ㄸ㜲攲づ㔲㡤〱㌴㐳㡦㜰攴㑡㈸㔴昴㡣㐱改愴㘷㝣搷慢敢搸㤵慦㡦搵ㅥ㌴攲挷愷㘷㐱㐴㐶搶散ㅡ㜰攲搹㕢㌰㔸㝥〷昹㙦㑦捦慥㐵㈷戱㜳㈴㠶㠲㘷㝢㌹ㅣ㑡攴ㄳづ昳㐹㠷戹捥㘶搴つ㘰挴戳㌷摣㥥捤收昴㡥〶〹㐷ㄸ攴㔵昴散㐶愷㔱㜶㘳て㙣改ㄳ搸戵ㅢ㥣㤲㜰㡤愲㤳㈰愲㍤昱㡣攱㥡㜸昶㑢㑦捦㝥敥改搹捤㡥㥤㔳㌱ㄴ㍣扢㠵挳愱㐴ㄸ愴〹挳㠸㑣ㄸ㐶㘵㉣㙡㍦ㄸ昱散愷㙥捦收㜲㝡昳㐰挲㤱㍢愰㔰搱㌳〶㕢㤳㙢戶ㄶ〳敡㐵散摡〷㉥昲㐵愷㌱㉡搳〹㝣ㄹ昵戳㑢㥥敤摥㙦㜳ㄶ㤶㝥㝥扢ㄲ㥦搳㡥㘳ㄴ㕦ㄵ㡥戱慤挳摦㙡晦㔹㠷㌷ㄶ愳〷扥晢攱扦挰扦挰敢扦㘲ㅣ㜸攴㡡㈷㌸㈲㥦ち扡〹㔳㙤戸ㅢ㡤〱搴ㄸ愰扡捡㥢攷摡㤵㑥敢㜷挸晥ㅤ改㙣昸慡搳攳ㄲ㜵捡扥慥挰㉦慥㕡ㄱ㝥攵㉢愳㉢收㜵晥㘹挱挵㥦㌹㌰㌶慦㤳戵昰搶㜹㥤㠹㤳捣搷慥㍤敡慤㜳搵〳攸㜱㌴挶搱〶挹㄰〹昷㤸晡㍥摣昲㝣㐳晤愲摤㔰晡愵㕡攴㐱㡣㈴㉢搹㈱㡢愵ㅥ㐵㥤ぢ愶扥㡢ㅥ㐴㐹ㅣ㕢㐶挷ㅥ㠷㜸㘶㡥㍤攱昴㜰ㅣ挳ㅣ愵摣昵搶㝤㘷捦扢昳愱慢㝥昰㝣敤㍢㥦慦扥戳戳㤵攵戱敥㑥昵ㄴ㝡㜸㌹昶㕣㈵挷㥥戵ㅢ㑡扦㐰㡢㍣㡤㤱挴戱㜳㉣挷づ愰㉥㡥㍤攳㜶慣㤳㡥㍤㘷慢㑥扢㘲つっㅢ㌸㘸戰㤲㐳㤶㝢戳㍢搵昷愱改攵挸㔳㤵ㅣ㜹搲㙥㈸晤㤲㉣昲㤲㙤㔳慦戲ㅣ㘱㤸㈰㡥㝣搳敤挸ㅡ㍡挲〰㐰愶㘷㑤挳愱攵㕢慦攱㠷㡥收搴㡥捣敤㔴慦㐲搳换㤱挷㉢㌹昲㤸摤㔰晡㐵㔸攴㘷戶㑤扤摥㜲攴㌵搴挵㤱㐷摣㡥㙣愴㈳扦㐲搳捣戶ㅡ㠳〳改攱㌸攴㕣㐳㘷攰ㄲ晡攳㍤愷㜷㕥㑥挱㥢昳㍡慦敥㑦晤改捥ㅢ㜱つ㌱㌰昰㜲散㠱㑡㡥摤㙦㌷㤴㝥改ㄵ昹㍤㐶㤲慤戶挵㜲㡣㐱㠱㌸㜶慦摢戱㙤㜴㡣㡦晢㐳㕢愱㍦㍡㥡㡥㐳捥㙡㍡搷㡥㔵挷ち㌱づ昰㜲攴敥㑡㡥㝣挵㙥㈸晤㘲㉢昲慥㙤㔳㝦挸㜲㠴㌱㠰㌸昲㌷㙥㐷㉥愵㈳㝣扡捦㙣㠵ㄸちㄴ慤㔰愹㐳㘵㌷〳㠶〱㕥㡥摤㔱挹戱晤㜶㐳改㤷㔸ㄱ㐶て戲㐲〹㌰昵㔵㡡㈱㠰㌸㜶扢摢戱ㄱ㐸ㅢ昸㜰㥦㤹㘳㡣〴㡡ㅣ㜳戶ㅥ㌶摥㠲㡢ㅢ㑥敦晣挵㙢㝢戶㙦昹㉡戶摥ㄳ㈳慦ㅦ㜱㍥戶ㅥ愳〰㉦挷㙥慥攴搸攷散㠶搲㉦慣㈲っㅥ挴戱っㄸ㌸挶〸㐰ㅣ晢慣摢戱㔱㐸ㅢ昸㙣㥦㤹㘳っ〴㡡ㅣ㥢㜶挵ㄸ〴㜸㌹㜶㐳㈵挷㍥㘵㌷㤴㝤㌹挵搸㘱扡㉦愷㕣㝦㡦搴㠰愹〵ㄲ㍣慥愹㑤㔸㘲㍥敥㜱㘰㤳㑣愵攴慣愳づ㥦㌵攴昰ㄷ㐱晤昸㝥〷ㅦ㌳攰㙦㕢敤戴ㅤ摦昵昰㉤戱昳攲㕣㑢㡤㥤㠳㠹つ㌹扣㐹慦㐹昴攵昱ㅤ㔶㍣㠴扦㘸㈸ㄴ昰昷戰敦㠷㙦ㅥ㜰晡挴ぢ㄰挵晡摡挱昳攰㠷㈷㍡㔳㝣㡥㌲㠹㠷昳㠷㍥㝥㝥つ㜱㜸㥦㘴〵㜷㜲攵慤㑦㝡ㅡ攳㐵ㅦ晡㔴慢敢戰挸㔶㐶㝦戵敦愰捣摡攷挷昱㌸㝡㐸攸㈲搱㉦㐸㔸㕦㐱搱㘶㘸〸昱〵ㄸ㑦㤵扡挶㠳㌸㍥〹㝤㈵㝦慣㔳㕢敢ㅣ㤴搱㠲㘲㌸挳㍤ㄴ晣〸㐸愵㠹㝤摣㜳㘲㔷愲㐷挹挴慥愶㘸㜲㘲㡡昱㄰㈷攷ㄴ挵㈰㐳捣敤〱㜳㡣晤㘶戸〴〸扦晡愸愷扤㙢搰愵挴摥㕥㡡㕣昶ㄸ愶ㄴ搹㈳〲㘲敦㤳㘰㉡摡摢攵㘹敦㝡づ㍥挴愹攳㜶㑦ㄲ搶㌷㔰攴戲挷㘸愲挸摥㝡〸挴摥㡤㘰㉡挱㜹戹愷戹㥢㌸昶㔰㤱戹㝤ㄴ戹捣㙤㐴扤挸ㅣㅦ愴㘲敥㘶㌰ㄵ摤摢攱㘹敦㔶づ㍥㔴㘴敦㌶㡡㕣昶昸㈸㉥戲挷攷㥤搸晢〲㤸㑡敥㤹㥥收敥攰搸㐳㐵收扥㐸㤱换ㅣㅦ㤸㐵收昸ㄴㄲ㜳㕦〲㔳挹㕣捣搳摣㤷㌹昶㔰㤱戹扢㈹㜲㤹攳㘳慣挸㕣〶〲㌱昷㌵㌰㤵捣㕤攰㘹敥ㅥ㡥㍤㔴㘴敥㍥㡡㕣收㐶㔱㜷㥢ぢ昰挲㍥攴晢づ户攰㔱戸㐳摢晦㌳つ㝥㔴戶㌰挵晦㤵㠶搷㌷㑡挵摦昰㍤〰㍢㡡户っ㡥愱晦搶㘶㔸㔱扣㠴㌹つ晤㈰愵扣㝡㐵攷㈱㥢ㄱㅤ㕥㜶愲昳㌰愵扣攲㐴攷ㄱ户捥昵㡥捥愳㤴昲㉡ㄱ㥤挷摣㍡㌷㌹㍡㡦㔳捡慤㉤㍡㑦戸㜵戸㈷挵搶摦㔱㝡㥢愳昳つ户づ㌷㤲攸晣㍤愵摣㐳㌲捥㌷摤㍡㕣㝤搱昹〷㑡戹昰愲昳愴㕢㠷㑢㈶㍡㑦㔱捡搵ㄲ㥤㝦㜴敢〸㜴㐴敤㘹㐸㥤ㄲ㈱㠴ㄲ㑣㝣ぢっ㠲〹〱慦㑣㡢㈰㡡搶㌳㤶㤶挰㔷愶㐵ㄸ㐵敢㔹㑢㑢〰㉣搳㈲㤰愲昵ㅤ㑢㑢㈰㉣搳㈲㤴愲昵㠲愵㈵㈰㤶㘹ㄱ㑣搱晡慥愵㈵㌰㤶㘹ㄱ㑥搱㝡搱搲ㄲ㈰换戴〸愸㘸晤挰搲ㄲ㈸换戴〸愹㘸晤戳㘸㐵ㅣ㌰ㄵ昱㤳㈸慣〹ㄷㄵ㤳攸㙥昴つ攱㍤㈰㈱㤳㠶㈵㈵つ㐴㐹ㅡ愲㈵つ〴㐶ㅡㄶ㤷㌴㄰ぢ㘹㔸㔴搲㐰昷愵㘱㘱㐹〳㍤㤶㠶㌳㑢ㅡ攸愴㌴㥣㔱搲㐰扦愴㘱㐱㜱㐳敤晦〱㤶攵㌳慥 | E27: 㜸〱捤㕡㕢㙣ㅣ㔷ㄹ摥搹摤㔹敦慣搷昶㈶㑥㉦㐹㙦㙥㘹㥡㔲愷㔶㥣㌴㈴㘹㠹㤲昵㍡㑥㥣㌸戱㘳㍢〹戴㠵昵㜸攷㑣㜶攲戹㌸㌳戳㡥㕤㔵㉤て㍣㔵㠲㠷昰搴㔲搴㥢㐴㘹ㄱ攲つ㜱㝢㈹㈰㠱㈰㍣㔱愹㔴攲〱ㄵ㈴㑡愹㔰ㄱ㉦㝤愸㔴扥敦捣慣扤扢㕥㍢愹ㅢ㈴㥦搴晦㥥晢㥣昳摦捥㜷晥搳㠴㤲㐸㈴㍥㐵攲㉦㔳㥡㤹㍢愷㤶㠲㔰㌸〳㈵捦戶㐵㈵戴㍣㌷ㄸ㈸晡扥扥㌴㘶〵㘱ちㅤ㌲㘵ぢ敤㠱㕡づ慣愷㐴戶扣㈰晣〰㥤搴㐴㈲㥢搵㤲㘸攷㈴晣㉢搴ぢㅡ㐷攵搳㈰搳愵愱昱搹㑢㤸㜵㉡昴㝣戱扢敦㝣㌴昶昰攰攰挰攰挰晥㍤〷昶づ散搹摤㔷慡搹㘱捤ㄷ㠷㕤㔱ぢ㝤摤摥摤㌷㔱㥢戵慤捡㈹戱㌴敤捤〹昷戰㤸摤戳㙦㔶㝦攴攰攰㈳晢昷㥢㠷づㅤ捣攳搳㠹㌳愵愱〹㕦㤸挱捤㥡㌳挳㌹挷㑢㐳〳㘷㐴㜸戳收散挰㥣㤸㜲搸㜳㜴换扤㐹㤳慡攴敤扥㘱㔱戱㈸〴㈱㝣换扤㌸㠰㘵㌷㌱ㅡ愵〳〳㈳攰㜸㐵て挲㤲戰敤㐹㘱㜲㌱㜹㠷㍣ㄳ扥㜰㉢㈲攸㜶㡥㉤㔶㠴ㅤ㌷〷㔹攷扣敥㥦搱ㅤ㤱㘶愶挷㠹攴㌶㙡〸㌷戴挲愵㉥攷㕣㈰㈶㜵昷愲㘰ㄷ搵㌹㕥戳㡣㜴㕡㐹愷ㄳ愹㕤敤ㄶ㈳㘵㌳㌰攲㔷㑡㔵摤て㘵㠹㔲ㅢ㙣搷户㐱㐳攴挲㥢㤶㐵㉤敡㙢ㄹ㐵㌱㑤㔹捥㈹攱扢挲收㐷㈸扣晥㤶㑥㤲㈷ㄱ敢㤷㤹㔳摦つ㜹愱㜴挶㝡㉦户㠲ち㉤㑢愲㠱㘴㜲㈰戹昳挵戱昱挹㜲戱㔴ㅣ搷㍡搹㤲〷㔱搲晦㠵昹㌴㡥㘴㔳戲慣㈷换戳挹㜲㈵㔹㌶㤲㘵㤱㉣㥢挹昲挵㘴戹㥡㉣㕢挹昲愵㘴㜹づ㝤敡㈹摢搱㤱㡣搳愹㤱㤷摦㥡昸㘸搷㠹敦扦㜲晡㠳扦晤改摤㘳昹㙥㜴㍡ㅢ慦㙡搸搷慦㐰戴㉢㕡〳㔳攱扦敢㥢ぢ慣挵摣㙦ㅥ㌰〷〷㡤晤㝢昴㝤扡捡㝤摤愸㤰戶愱㙦摥扣㘰戹㠶㜷㐵㑡㉤㙦㡥㔸㜶㈸㝣㔹攸㌱昱ㄳ㘹㥥㉣㜷㤹挷ㄶ㘱戲㤵㐸挰摢捣㤲昰㐳愸㝡戸戴㈲昵㍢㠷昴㐰慣ㄴ晢攳戹㠷扣㥡㙢〴㜷戴㙦㥣ち昵㔰散㘸㙤㕢㤹㘴搵戰㈹㤸㠱〸攴㤲敥㙥ㅤ㜶㕥户㙢愲戸㘸㐵捤㜷戵㌴挳㈰扣搹戵㕢㐷㝣㜱㜹戹㜵搵㡡㡡昰㤶ぢ㜲敥㔵扢㡣㥡愲㜵昵㤵慡㕥㈰㕣戹扣㝥㘷挲慡捣〹㝦㑡搰搷ち㐳㙥昵ㄶ㌶挵㔶搹㍦敥㘲愳戰㌳攳扥挶㕡㌲㕡戸㠶㌰戰摥㜹㜰㜹㘹㕡㥦戵挵慤㑤㕤愲㙦愲㘱㝢㔳昵㠸㔷愹〵㈵捦つ㝤捦㙥㙥㈹ㅡぢ㍡㍣㠱㜱摡㌳㐴㕡愶㐴㐴㤵㐴㉡愵㈸㠹〷摢㤹ㄴ攷づ㘸㜴つ㑡㐲搳㕥扦㜳㠳ㄲ戱㜳㕢㘳㕤㥥ㄹ㤹〶㈵㘳晦㉦慥扢㤲㐶㈵㘴敦㍤敢昶㙥愳愴ㅣ㜴㝢戳攱つ㑣㐲㍥㤰㠳㉤㘸㤵挹晢搷㥥㜲㐵㉦慦戳搲〶愹昰㘸㘵敦㜵㤸㈶愷㕤搶扤晦㙦攷㘴戲㌷摥晤戱〵昸晢ㄳ扡㙢搸挲㕦ㄷㄸ㈸㕣㤱搶㐳㔲㈰搹㐲戲㤵愴ㄷ㐴晤㄰㙥㜲㑤㡥搲愷㉢㡢捡㤲㝡挵㌲挲㙡愶㉡慣㡢搵㄰㜵〰ㄴ搹㉣搹㍤ㄳ晦㙤㐵捦ㅡ㔱㠵㜶ぢ挹慤㈴户㠱攴㜲㠹捣敤昸㠵愷搶戶昳㘷〷㐸敦㐹ㅤ挷㠱摥㘷㠸㍥㜰㝡挱ち㝥晤㥡㤷㑢愸㜴攸㥦晤搸㤱ㅦ㤵愷ㅣ㘰㐸愰㍡㌸㑣㠳㔴慡ㅤ㐷㑥攸㐱㌵愴㌱慥摢挸㉤㙢㜷㤰摣〹㤲扦ぢ攴捣〹㘱挳㤴㙦ㄶ㠲㔱㜹ㄲ㕤昷愴愴㠴㙥㜵愶㤶摣㑡搵昷㕣攰戹㘱㍤搴㡢ㄵ挰㠱㐰搱㌳捥㤸㔷慡㠵ㄹ攷㠴㠵㥦扣㌳㈹收㠵ㅥ㤶攰慡挳㉥㘷っ㔰㐲晡搲㔱㘳㔱㜵㈲ㄴ㌰㉣㠲㡡㐶戸㌰ち搷戴㤸㐱づ扥㌶敦搰搹㠸挵㤰㔳㜷㌸ㄳ㍡攰㐶愸愱㔳扦ㅣㄵ攵㌸戲㑢搶搵㐷攷攲ㄲ㘶㈸挸㙣挳㉣㥤戲㈲㥡㈹㐱㔶㈶攰㥤ㄲ愹㜴㑣㕢慤攸㕣㘸搹挱㐰捣摥㠱㘱て㜰㔲㐸㐴㑢戶㘷㌲㔰戲捣扡挲㙡㌵㜶攲㡤昱捡㙣㌴㉤㤶㜲摣昷㙡昳挴ㅣ㌷㙢ㅥ捥㤵搰敥〶㜹改㍦㙦㍥戶昳㝢㍦晥㌴晥㝤ㄶ㘶㈴㤳㐶㐸愲㔱攷㔹挴㡦㑣摡扤昸挹慤搷愶ㄲ戵戴昵戶㙢㐰㈳㥡㜵摥挱㙥愷㝤㈱戱㕥㔶ㄶ㤶收㐵㤷㜳挱昳攷㘶㍤㙦㡥挲敦㤶愵愰㉡㐴㐸〰搵ㄹ攳㐵收ㄵ㐵㐹愵㥡㌰㔲〳搲㈲昴捡散〴戹㙢摡㌳扣愰て晦ㄵ晤换㌵㙢〱ㄹ㔸敥戴慦捦敡㜶搵换㍣㠰㉥㈹㐲扢㕤挸散㉤ㅤ㉢づ敤愳㜶改扣㥦昰扣戲扤昳㡦ㄷㅦ㍥慤㠷扥昵㤴㈱愶㠴ㅢ㔸戳㤶㙤ㄹ扡㈱〶ㄶ敤㘰㔱昹㌳昸㐴戰㜶摦昱㙦扦慥晦摣ㅢ㝤敥㠳㘷㝥㜸挷㥢㠷摦㔳摥㠹ㅢ㕡攱㤷㑡㘷搶慡㑡ㄲ㐵㉥ㅦ㑣つ㐷ㅥ摤㔴挶㍣攷㕡㘱搰㘹ㄶ㙢愱㌷㘲㠵挳㐱㤸㌷㐱㤰㤵㐳㜶㐸ㅦ摥㌰愸摦㍣㙦㠹㉢搳㘰收㍤慢㥢〰戰㑢戵㈰昴愴㤵摣扤扡㝤搸㍢攳㠵挳㔶㌰㙦敢㑢昷户㘹㡥㕡㉥㔴㠵ぢ㔰攱〳㕢㕣慦㤳㌷㍦㉦㡣㌶㙢㥣昲㙡㝥㐵㡣づ㙦〶㔸愲㐴收㥥㠰㐶挱搸㤵㥤㙢ㅦ挳つ㝣愷づ㈷愱㠵捡〶㑦㌵㜹戴㘸晤㤸〵昷㕡〵愷㡤戶ㅢ㔹ㅣ㍡㉡㡦扡昵㔵愴〱攸搰㈱攷㑣㠸㌵慡敢㡡㤱昴㈸㔴搵㄰戹戸㜴摡㜲扢攳散㜸㉤㙣㙡搱ㄷ㝢攳㤶愲㙤㡦扢㄰㝤㐵昷㡤捤㈰ㄵ㙣っ㈹ㄲ㠹㤲挱扦㡤㌱㍡㥡㈶㤱昸愸ㅥ㤰昸攸㔹㜸戳㠷㔱㑤㕥ㄳ㔱戴昵㕣换收㠸㑣〳㑥愴昹㜶㤱摤换搵㔹㤶㑥ぢ摤㤵㔲㤸ち㡤㘱戱搰㉤㝢〸㈸㌸敥戵戶攸㙤㉥捡〳㑣㌳㡢戳㠱㘷搷㐲搱扤㥣㤳㠶慥㤹㤳〰ㄸ挴晣昹攵摣㐴㈵挴慤㘸㜹㍥攲昹捤㈳㈱㜰㈴ㅤ㑢㐹㤱㜲捡慣愳扣捤㥢愰つ㙤㔰慡㌸㥡㑤㤹晥㝤㐴㜹攱㜹愶㌷㡥㈴敡㤹ㅣ㔳㐲㈵づ戹㜱㔰㑦㑢敡慤摦㌵㈳て㈷㥤㔷扥㕥㐷㍣摤㘵㑡扦㠷㑢㌳㐳ㅡ㍤㌴ㅤㅢ昱愶搰慡攸戶扤搴㙤㡥扡ㄵ扢㘶㠸㌱㝤㔶搸㜵㥦敤昹捥㈶㤱㤷っ挵㐵戲㕡㠷㉦昱㑤㘷ㄴ昱戸晡ㄵ㘲挳㙥㉥愱つ㠰慤ㄲ㔳㘰㡥㥣戶〷㈵㡡㠶昸晤㌳摦愰〸㑦戶慥摣晦㘵愴〸慥㙤㔵ㄵ㝤ㅡ㤱攴昲㈵㑣㕡㕣㐳户㌱㙦捣挳〵搹㘸愸㍡㘱㐵㔵㥢挶慥愴㤸㌲㤹捣㐶て㤸慢摢摦㕦㉣㔵ㅦ㌸㝡攸㥢㌳㑥㌵晤挸搱㍦扣晦捥户捣愵扦ㅣ㠱ㄴ愴㜱昰戲搳㡡㐱ㅢ㠰㠸㍣晢愵ㄳ攴㜱搴㐳てㄶ〱㠷㘹㉢戴㐵愷㈹摢㘵㍥㑢㤳㈰㌷㍢捣改㉡昰摣㜰㤷㜹摣户っ摢㜲〵㐱〸〲㌶㡣捥㡤㠹㡢〸㉤㑣㜸㠱㐵㜰搵㘵〲㠳戹挱㍣㘱㝢㘵㘹㙢㔳㐹ち㑢㌵㠷㉣ㄷ〶ㄴ㝤㤳昹ㅥ㜳慡敡㕤㐱晣戸收戸挷昵昹㘰㔳〸㡡ㄱ改㈸㐵㔶㤵㔴㤲㐹㈵㥢捣㙥昴慣㤲㈸㥢㠰㈰戱ㄷ搳㈶㐹㘰㉥㌴ㄸ㕥㑢搷戱㔹㑡㉡づ敥搰㘶戹慥愶㌸㙣摢㕢攵㜲〰㥥㝥㔸攳挷昲晢㐰㑥ㅥ㍦㌷扡ㄲㄲ晣㕣㔱㜴㤵ㄷ改㜵㡥〳愹ㅡ换昱〷慡㘴㜷愴㉥慣愳昶㘸㔲敡㉣戵慡㘰捥㤴㝤愸㡤㌸㐱搹㥤搹ㄱ摣ち昳㌰㝥戸㕦摣愶攱㜷扢愳〲㈱㥤愳摢㐱摣㔶昲ㅣ㐷愷㝡㔱㌵愷攰扢㐵㔶攲㙢㜸ㄳ捤〴㤱㍡ㄸ㔷改㡢愸搲ㄷ㘵ㄵ㡥㘴挶ㄴ㘵㥥㜳㜹ㄷ㜵摦ち慢㡥㔵挹戲挰戸摦愶搰㑢愸㤰扣挱㠲愱㑣㔲㌹〱㔶㕢㙦敥搱㘵ㄳ攲ㅥ挰晤㠱慣愳昸愱扤㐹㜹㡥㉢ㅢっ搸㐰㝤愵挳搷昶㘳㌶㔵扥搷昰づ捤搴〰挲㔰㈳㌵㕢㘱㙣㠵捤摡㤷攲っぢ㘹㠶㌱搶扤㍦昳㡥㤷ㅢ昳㜴㘳〴愱㘱捦敦㠸㕦㝤戲㄰㉤摤㡡㕦㘰捣愴㠴㑢ㅣ㠲㤹ぢ挰挲㝥㤶ㄵ㔳㠸㐶愴ㄹ㙤挹㐴㌲㈴㙦ㄲ慡摡㤹㙤昷慤搱晡㕣昷挷㜷换挶搷慢搱㔵昳㝦㜸昶攰ㄱ㉣ち摢攲昳㠹㜶㠰攴㈰㠸挲㘸っ昷搳搲攱㄰㍢㍣ち愲昲㔲摥㙡㈵㙢挶ㄷ㌸戹敡㌰敥㤱㜵戸ㅤ㐰㡥っ愲㈱㠸㥦㠰㈵㤹捥㉣攳て摡㘳㈰㝦扣㜶敤㌰㝥ㄲ捡扤㈰昵敦搳搴㜳㌹㌲㑦晢㌲〹㝢愸扣㠵摣搸慤㠷〳ぢつ㔷㔱摡㘸戰挵㍣㕢搳㙤㍣攰㡣〳て㠵慣摡っ㐶㤰㡥㔰㘹敢愳㐴昳扢づ㉥㜴㜲ぢ㑦㝣㡤攱㤱㔶ㅥ㌴昷㡤昷ㄶ戰攷挶㔰㙢㑥晤ㄵ攲〲㌷昶ㄵ㕡㐱挷〲㘳㕤攵㌲㘲㐰㈸㔱昰㌹㡤㉡㠶〳㐱攱㙤㔱㥡捤搱㌸挳㠲挲㝢㡤慣㉤㈲㔳㑦㉡㌱搸㍡㠷㐷ぢ攰攳昸摥ㄵ㔵愷㔳敢户昹㑣摢捥㐶㥡捦㤰㈱っ㔵㠸昱㔶慤㐱攱昱㈲㙢㠷攳㡣搴㘳扡㠸敢㝡㈵扡㌲㕣㘵攱㥦愶挲㈵ㅢ㘷〲戳㡣て㐵㌹ㅡ㐱搴㡣㐵㝢㍥㐰㙥扡㌵㉡扣㍣㤶ㄱ㤵捥㙤㉤㔱㜸㌹㡣㉤㜴㝦敡㉦㈰愲㌵挷㜳〷㉢㔲攱ㄸ愶捣〸挸戶搳㔶挵昷〲捦っ晢愶㠰㙤晡昸㉥㘳〲攵ㄶ搵㥦㘱挶戶摦攴挶搲㉥摦㍡愵愰㜳㜳慥㜷挵㤵慢㔱〳㍥㑦㐹㝥㜵㜴昰㌳挴扥㌲㝤〱㕣㉣搰㔵㜲戰㜶〲愴㉢㔵愰慦㘱㉡搰摦㌰ㄵ攸㕣㤸ち㜴㌰㑣㍤㜴〹㥣㠵慡㜴㔳㔳㠱㡥㠴搲捣㡣㠲攴㑢㐳㘵改㕢㈷昱㠴㤳㌹㠹㥡㉤愸㘹㝥攸捤㥣㐲㜵㌷慡ㅢ㘰㑢㠱㥥㠸戳挸搷㔱敤㌴㜳㝣㔴㔴愸昰㤲ㄱ攳挸戰〳晦ち㐷㐱㈴〷㈶㤰〱〷㡡昸㘱㔲愴ち㈲愳㉤搷愰㔰ㄸ〶㤱摤㈷㤱改㑡愹攴摢㘳㙢挷㜹ㅡ搶搵て敢㘸㝡ㄴ㍢㠶㐷慥㈵㥥㙡㈹㥣㈳慡摣㙡㍡昹攸挶收愲敦愱㐷㤶㝦㍦㠲㥡㝣㡥㜹挸愳ㄵ搵攴㡣昷攰㑦㥢〶㔱挸㑤〶㘹戵㥤㈴て㤰散〲㔱㝥㠰㑦戶㡤㕦扥ㅥ㌷戴挶㉦ぢㄴ㠲㘴攴攳㥣攴〹㤲㈷㐱㜲ち攵㐰慥㉡慦㘱㈸户挲搰㑡㌶㤹㔲挹昱㠷搶㘶㑦〴挱㔶摥㔶ㄹ㘱㔱㑤㕡㜷愷ㄹ㍤㙤㤲㐹㌲㤲㘵㑢搳挸〳㡤昹㜸摤ㅣ挳〵〳ㄸっ㙦昴戱㜲攱攲挱㔳戱㝥摥㙢戲挴挱ㄹ㜳摣〷〰攸㌰㐷〳㕣㘳㡣㉣㥥ぢ㐲扣㌶扢㥢攱㤴㠲戳㑡㔳㤹愰㑥っ㍥㈶摢晡〹㍡㠰㔶㝣搰㜰㔷㕢攱㐷晤扥㥥㈴㠸摢搸ㄹ㤵昹㍡㍥戶つ㙡㡤晦戳㐳㐶换攷敢敦㕣㐹攵ㄵ㠸㤵捥㉣昷慦扤摢㍦攵㥡㠱ㄶㄳ摡っ㝥愴㑥㈹㜲㈳㠸㘵㙡戳慣㘲㠴㔳㤲㠴㑡㈵㙣摤ㄹ摤昶〸㐷戴扣搰㜵㜶㜲扢㙦ㅣ昹攷搱㘷㡥㍥㔷㔴愸㘷㔲慦㕥㡣昵㡡摥㈶㥢捣㈸搴㍤搹昰摤戸㠱づ㈴ぢ㤴㑢㝤㤴つ㉦挴つ昴㈰摡㐵㄰㜵〶攴㠶ㄹ㐹㠳摡攰㌹㔸挵㔰㠵㑣攰ㅣ㥡〵挲㡤昲慦㠷敢戸挰挲愲㔲㤹㌱㘶㘶㍥敥㐹昷敤㐸㝦攵㘸晥昹扦晥晥扤慢㙦㍦㜹昸ㅦ㥦扣昸攲摢㝦扦㝡敤㤳㕦捥ㅥ晥敤慢慦晥收攴㑢搷摥摢㙡扥㥣晣挹挷㘳㉦㍦㍤㌸昷昴㘵昳摣㐳挷㥦晥敡愵戳㠳ㄳ㕢晡㔳愹㡥㡥㕤扤扦扢晤挱挲㌷㉥晦㔴㜹敢摤摢㕣㐵㝥ㅢㅦ搰㉥㠱㌰昱㝦户㈸㜰つ搲㙥攷㤰搱㙣㤰慥㘴㠱㍤㔸搹㤵㔶㔸㉤㤹昶㥤㤸㘹㐳愸挸㈲㌲捤慥戲攱㙡摣挰㜸㠰收㠱㈸㈴㌳㉣捤戳㈴〹㑢㜵挷㡢㝣愲昳㝦敤〷㥤㑡
A28: Decisioneering:7.0.0.0 | B28: Decisioneering:7.0.0.0 | C28: Decisioneering:7.0.0.0 | D28: Decisioneering:7.0.0.0 | E28: Decisioneering:7.0.0.0
A29: CB_Block_7.0.0.0:1 | B29: CB_Block_0 | C29: CB_Block_0 | D29: CB_Block_0 | E29: CB_Block_0
A30: 㜸〱捤㔸㕤㙣ㅣ㔷ㄵ㥥㍢扢戳摥㔹慦㤳㈵㜵㥢㍡㜱搳㙤ㄵ㐸挱改搶㥢挴㑤㔲戰㤲晤昱捦㔲晦㈵扢㜱㔴㤰㔸捤敥摣昱㑥㍣㍦敥捣慣敤㑤㔱㕦㐰㍣㔴挰㙢㈵㠴㐴㡢㔰ぢ〵晡挲〳ㄲ㑦㔴〸㠴㄰昴㠵〷㠴挴ぢ㐵㐲㙡攱愱㐸挰㙢㌹摦㥤㕤㝢晦㥣㈶㙥㤰㌲昶㥥戹昷㥣㝢捦㍤昷摣昳㜷㐷㘲㤲㈴㝤㐴て摥㜸愲㘸㑣㤶㕢㝥挰敤㑣挱戵㉣㕥て㑣搷昱㌳㌹捦搳㕡㑢愶ㅦ㐴㘸㐰慣㙡ㄲ摤㔷慡扥㜹㥢挷慢摢摣昳㘹㤰㈲㐹昱戸㉡ㄳ扤昳㑢㜵ㅡ㉡㘶愹㔱〲㐹ㅡ㈵㔵ち昹搵摡㉤㘲㕤づ㕣㡦㥦㑤慦㠷っ㘶戳搹㑣㌶㌳㌳㝤昱㕣㘶晡㙣扡搰戴㠲愶挷㘷ㅤ摥っ㍣捤㍡㥢㕥㙢搶㉣戳晥㍣㙦㔵摣㑤敥捣昲摡昴昹㥡㜶攱㔲昶挲捣㡣㜱昹昲愵㘴㡣㌸慦ㄵ昲㡢摣摡㈲㝥昷㡢敢〸㜱㕤㈹攴搷㍣㙥摣㉦㥥ち戴㤱㉤昲扡〹戵㜱敥㤹捥㐶愶㤰愷晦㉥慤㔰敦㘲㘶戵㕣收㡥㙦〶收戶ㄹ戴愰㌹搵㕥慤搷搶㌵慢挹㘳戶㄰㈹㙥慦㙢摥㡡㘶昳㌱晢㠶捦慦㙢捥〶㐷㑦戱ㄷ㥡愶ㅥ愵攳㡣㝣㜶搸㐲㙤㈵㘵㔶ぢ昹㐲㐳昳㠲㤰㈵㉤昰捣戰搱㘲愵㑣㤷㈸㘲㡥挰㐲㍤㙣戴㙤㌰㔸㔳㐸ㄹ㠷愸㉡㠱㔸㠲挰挹〵敦㔷慦ㅢ㘶摤㑤敢㍣㉤戸搴㑣换搴㌵敡㥤㘳搱晦㤰昹㜵㌳ㄸ愵ㄹ㜲㔵㤳慢㌵戹㕡㤷慢扡㕣攵㜲搵㤰慢ㅢ㜲戵㈱㔷㑤戹㝡㑢慥㙥搲㤸捥ㄳㅦㄹ㤱摢捦攴户㉥扣㔷晡㑥㝡昱慤愵ㅦ㝣昱㝢扦㝤㘱㤲挱攲㠴改㈵愹愱㡥ㄱ㠸ㅤ㈱㜰〷㠱戲㡣晤㡢〴㠲㔰愵搵敡挴戳晦昸敦攲㜷扦昰㤷㥦㑢敦㝦攵㜷挹ㄴ㑤㕤㈱㡤㘵㔶㜸㜰㥦捣㑢㠱愶敥晥㠴戰つ挵づて戸挸晤扡㡡搳㉦㌹㍡摦㡤㔱㡢慣㈲㘹ㄷ㕣㈷攰扢㐱㔱ぢ戴ㄱ㝢㑤昳戸ㄳ愸㌴㘸㑡捣ち㕢㤸㌹㈶㜰㥤搹㠹㜶㡦㌸愴㐴戳㡢换愸㐰㠴㥣ㄸ㠵㠷㐸㌴㠴昱搸戰㌸戱愸昹㡤㐰慢㔹晣㜴㥦㈱㐱㙦㘴扢㌷〲搳昲㌳挴㜲挱㜳㥢㕢搰攸晤攲〳昷㔷㘱㙥戱㘳〴㐴㔴挳㥢ㄶ戸慡㍥㐴慦㠴㈰慡㈰搲攱㝥〴捡㍥㉤㜹㥣㍡搷摡㘶㕣昴戴ㅤ㜲挹晤㈳愶㜸㠴扦㡦㡦㐹ㄴ㤲㡣ㄹ攳愲㤱捤敡㌳搳摡㜹㑤㠱て摣慢㑢㡤搳㥣愴㝤搳㜴㜴㜷㐷昸搸㌱㥢㥣㐶戸㕣愵戵挵〵㉡㘹㔴㌴㙦㠳㤳摦㝡愵攲戸㔱㜰㍤㡦㕢㕡挰㜵㠱㐰㥣㍥摥㡢昴攷㍤搷〶㝥㌲慦昹㝣摦㝦愷㡣㜰愱扣摢㜴㜴晦攴㜰㘲㌹㈰搶㈷晡㘹晢㑣〶愶㤵㈹愶㜱㕦㐸㝡慡㝦㥡戰搳摣慥ㄹ㤲ㅦ敢㈳㔳㔴㜳㙢〷㔳攷㍤晥攲ㅥ㜵㐰愲ㅣ㈵慢㙤づ晡挰㉥㐳㔲㈸㔷扡搰㜰㝤敥〸昱愶散㌵戳扥挹扤㌲㐷慡攳扡搸敡挳㈰㜱㜲㥤㍡昷愷㔶愱㝡ち慢晡㤳摤㔸㘳㙥㌷攰攴㜸㍡挹㑢改㈶㘸㔵㘰昴㡦昴っ〹搷㈴挲㐴て㝡摥慤㌷㝤㌸㤸攷㕡扤㤴㥣扥慤搱㥡晡戲慢昳㘸㔴㡥㐸㔱㈹㡡㐷愲㌰ㅥ㈱慦㥢敥昳㈹㤱㌳挰摢敦づ捥㕤㤶㠳攸㝣晥慥㈶昵㥡ㄷ收つ昳敥扤㉡㠰㍤摡敢㉢㤹敢愴㍤搲㤲挵攱㐸㜲扦昳㜷〹扡㙦㌵㔸㘴㘸攸ぢ㜷搴愵㌳搸㉤㐶㍦㜵昰㔶〴摢㍤换昸晦づ㤶攵㠷摡扢㥦摢愶昰扡愸㌹扡挵扤㍢敢ぢㄲ愹㡦〲㑣㄰㐸㈴㈴攵敦ㄴ㠴づ搴㈲ㄲㄷ摢㘵㉤㘵挷搴㠳㐶慣挱捤㡤㐶㐰㌸慡戰攲㜱愸昸㙡晢昷㝤㉡戱扥㡡㌲㑢㍤〹㌰㐹㈰㐱摣㐵㤸㡢㈵搴㔳愲㉦㌱㈴づ㤱㤴㤱晥〶㘳攰ㄳㄸ愶摥㠱㤶晣㌴㡤愰㄰㕥㜴㙤捤㜴昶㈳攳㈷慡搸ㄸㄲ㌲㈲愴晡ㄹ㠰㌳〰㑦ㄱ㐸㐸散㑦愴ㅣ㈸攸㌵敡㡡㕦㝢㥢戲晡㌹挲愸㔳〴扡户昹㌴昵㘳ㄹ㠰昴〲愷㘲㌱㈱㐵ㄱ昲㠷ㅤ挹㕥㠲挲㠹㈴㤶㕣㑤㥦搷敡㔴㠶㡥戴㡢搰㜸挱戵户㈸㙤㝡㈹㡣㉣㤰㈷㤲㠷㙦㥢㍡昷攲㐰㤴愹攲㡤㔲つ敡挷㐴ㅣ昳㈹ㅦ㐶㈴㐵ㄹ㡤て㕢慢搴攱㜵扡㙤㉦摤ㄵ㜵㘹㠰晦㍦慦㕤扡㠲愳㑣㈴㐴捤昲っ㌵搵㘹〲ち散收㥥㝤晦㈸㑤㝡挴㉥㌷摣㥤㐵㌲ㅥ敥㠷㌵㥥㕦昰捣攰昸㈰㥡昲扢㘶㑦〸晣㠲挷㈹摣㝢ㄵ㡡㝡㘲㡦㤸㜱㘲㈸㐵㑣㍡㈱㕣慦㉢攸㑣ㄹ敢㈶摦㐱慡㝡㝣㤰㐴㐵㙡愱改〷慥㈸㐷㑥つ搲㡢敥㡡ㅢㄴ㑤㝦换搲㕡愷㠷㤰㐳捡捤〶㜷㈸㔲㝢ㄴ戰㍦㙥㤰扢戵挵昵㈱㌲㤶摤愶㔷攷愵攲㠳㄰敢改愴挲㠷㠹㌰捦攲㉣㈶㌳㝡づㄷ㘶ㄸ㈲㡣昴搲昸摢ぢ㝦扤晤昵㉢㈸㡢㔸㈲愱㘶改㡤戰〳攲㘱㔲〲晣㜴慣愷㄰㜹ㄸ㌷㡥㘵扡愵㤹㕢ㄶ捦㙢ㅥㄹ户敢昹慡摤㘹㠶挶搷㜵㙢〸㍤收㐱㔰㌸攵搵㌰愳㘶づ捥㈸㕤㠲ぢ㍢㠴㐱㈳㘶戰昱扥搴㈷昶㡤㤸㝣挸昳㔲摥愵㐰㜷㡦㠲攰㥡㍥戲㡤㡡扦㕡㤵攲㄰ぢて㔳晥㐰慣㠶捡㠷㠴ㄲ㜵㜰㌳ㄴ戳ㄲ㥢㡥扢攳〸挹ㄵㅦ搵ㅤㄸ慡㈳㈳搸〶㙡㘸昱捣㔰摤㐱愶〳慢㐱㜲戹慢愴㡥㡡晥愸戱攷攵ㄵ㌳戰昸愸ㄱ㉡㄰敤戸㐱㝥㑢〵㤷㍥㘲㔴ㅡㅥ攷挵㌱㘳挱㌳㜵换㜴㌸ㄴ㑣愵㉣慥愳㑢㝣㠳㡡慢㌵ㄷ㔷㕦搷ㄹ㌳㉡㥥收昸㠸捡㑥扤㜵慣愷㈷㙣㑡㌱昲愶攳搳㌲㈲戲愰㝤搴㐰攰愳晤㌵㙤㘷㐱摢昲ㅦ〴愳㈳㙤㜶㥥搰捤㘵㈶换㉣㉥挷て㘹㌷㔲散〲㤴㉤散戴㜳愱㝥㉥㑤搵㤷㉣㈲㠰㝣づ慢㠵挷㠷戲攰敥㑢㉤挸㤹ㄴ㥦ㄷ摡㌵㜰㘴㔸㜲摢慢〵㘱㝤敡っ〱㠶㙡㐳ㄸ搲戳敤〶㍡散〹〲挸挶㝤改敤㈲愱搴㑢ㄸ㠰散㡦ㄴ搷ㅦ戸㠴昵愹㤷㠹㐲㈶挸捥搰ㅢ挱㡢晤㠶㙣ㅣ㉥㐳㙤㠹戱㕦㔳ぢ㔶㍦捣㙡㔱㑣㑣つ昳昰戰㡣搹晢攰㔲搲愹㡣㙢㝦㘱㐹攲ぢ㑢㠵㉣ㄳ户散戸攸㤰㕤㡥搹㌷㕤㙦戳收扡㥢㐰ㅦㄱ㍤扦挱㜹㠰㑦ㅥ愳㜶昸摤〶㙤㡡摡㤱㐸捦攷㡣㜶戴〰ㄱ㐵㔴㔸㤹捤㔲㉢㌲敦搵㐵㡦扤㐳昲攳㡢挳㤳ぢ摦㝥㔳晢㠵㕢㝡攵㠳㤷㝦㝣昲慤搹昷搸㉦摢㠴攷攷㕦㝢㘷敤挳㌳㡢㙦扣扥晣挱摦晥昸攷㌹㠶㉡〸㍥㈹挵㜲〴㈶晡㙣㘰㍤户戴㝡扤㥡㉢攴㔶㠷㔹〳㐳昵〴㡢㔰昳〴ㄸ㙡㈷㜱㘸㠵㜶〳㥤ㄴ㡡て搴㈲戱㈲㠱㑦ㄵ昲搵㜰㡢ㅤ㑤挵收〸㝤㠴搰㕤㔵㝡ち戵ち收愸昳〰㐸ㄸっ㔹㐷㌰㕦愴㐶攷㘱挲㔸愸愷㜶㘳㔳㌰ㅡ㠴㈹戵㐴㘰㉣㤲㠲㠱〸㜶㄰㐱挵㠲㈹㤸㡢㐰㉤〱㠵昲㤱挱㍣〶㔷挸て挳愶戰㐳戱〲改㠵㔶㘰㤰ㄳ㌶ㄲ㕢㈳昰㔸挵搵㕤㍦㑤晦㌹敦挵愶戹㑤つ晡㐰㐵㤱愷愶㔹つ㔷挵㤰搸㌵〲攷ち㜳戹晣㜹挴ㅤつ挱〹㜷㌵换㕤晦㔲敥改㘵㉤昰捣摢㍡敦㌹㡣捣慥攵敦戲户摢攷愸㝥敤搶㠷扦晦昷捦㤶㕦㤵㕥㝡㘱晣㥢摦㜸㤷晤戴㑤攸晦㜲㤵敡㘸㐶㠱㌲㍥㍦捣㠶〷㙥㐹㔳晤㔷搲㌹扡㘲戶愰慥〸ㄵ慣㡡㠸㤴㔱昹戹挳昱敡㘴㍦㌸扢昲ㄳ㤲晡ㄳ昰挱㜱昵㈶慦挷〹愳摥㈰挰㜰戰㌸ㄲ愱敦㔰改㌷愹㝢ㄸ愵晦昰㈰愵扦搹㈶昴㝦攰㘳㌰ぢ攸㥢扤㐱㈳戰㐹㈱搷㤷〹愳㐰戸晥挴㡡扢挰㍣昴摢㜷㑢ㅢㅤ㐵ㅡ晤搱㤵昷慦扥㝣昵㤵ㅣ挳㝣㑣敦㈰㐶晦〷挱㉦ㅥ㈳ | B30: 㜸〱敤㕣㕢㙣ㅣ㔷ㄹ摥㌳摥㕤敦慣敤搸㡤搳㑢㑡㘹㕤㑡㘹愹㠳ㅢ愷つ愱㐰〸扥㌴㤷攲挴㙥散愴㕣戵ㄹ敦㥥㠹愷搹㤹㜱㘷㘶㥤戸㔴㙡〵攵㈶㈸㤵捡㐵ㄴ捡㐵攵㈲昱挲攵㠱㜲㝤㐱㈰㠱㔰㤱㜸㠰〷㈴ㅥち㐲昰〰㐲㤱攰㠱〷㈴昸扥㌳㌳扢㌳扢摥戱扢㙤挱㐵㍥改晥㍥㜳㙥㜳捥昹慦攷晦捦㌴㈷㜲戹摣扦㤱昸㤷㈹捦捣㜵㡢敢㝥㈰敤㠹ㄹ户㕥㤷搵挰㜲ㅤ㝦㘲捡昳㡣昵㌹换て晡搰愰㔸戱㔰敦ㄷ㉡扥昵愰㉣㔵搶愴攷愳㔱㈱㤷㉢㤵㜴つ昵ㅣ㠴扦㤱昸㐱㘷慦挱㍣挰搲捣昴晣昲晤ㄸ㜵㌱㜰㍤戹㙦散㙣搸昷昰攴攴挴攴挴挱晤㠷づ㑣散摦㌷㌶搳愸〷つ㑦ㅥ㜶㘴㈳昰㡣晡扥戱㠵挶㜲摤慡扥㑤慥㉦戹ㄷ愴㜳㔸㉥敦扦㘳搹戸昳つ㤳㜷ㅥ㍣㘸摥㜵搷ㅢ〶昱敡摣愹㤹改〵㑦㥡晥㡢㌴㘶㠱㔳扥㜳㔶㔶㉤慥㑤㑡捦㜲捥㑦捣㑣攳扦挴晣昱㜴㘸㘲㜱㐵捡㠰慦㤶㥥㜴慡搲搷搱㜱挰㥥昲晤㠶扤捡捤搳敤愳㔸㙡搵昰㠳㠲㍤㈳敢㜵摤㡥㐷㉤搹昳搸扢扡戱㍥㘸㉦㑡挷户〲㙢捤ち搶㡢昶ㄲ〶慡つ搹㘷㝣㜹摡㜰捥换㔳㠶㉤ぢ昶戱㠶㔵换㠷㈹搷㜷㑢㍣㐴㜲㘲㙡昹ㄳ㔳扥㍤戳㘲㜸㙡㐶㍥㌷㈶愳敤㔱慦㥡㙥㝢㔳昷㜱㌹㜵昵〶㡥㜹㜳昷㜶愸㌹㙢㜸捤㤶攳摤㕢㐶㡢㑦捦攰昶敥敤ㄳ㝢㤴敥昳摡敥㝤搴㔶愶㕢㡢㠱㠸扥搵㡥㘲㌱㝡㤱愰㥦愰㐴㐰〴敡㘵㠲〱㠲㐱〰㤱晦㍢戸㈴搹㤱㔵㕡挵搰㉡换㕡愵慡㔵㙡㕡㐵㙡ㄵ㔳慢㥣搷㉡㉢㕡挵搲㉡昷㙢㤵ぢ㘸ㄳ愷㔲㝦扦ㄶ愵捦晣㜶㉣㜸攷㔷てㅤ晢敥㕤㘳㔷晣攳㥡敦昸㠳扢搰攸摥㘸㔲戳㥥㜱ㄱ愴搶愲㘲㜰〴晦㙤捥ㄵ㘰ち昳愰㜹挸㥣㥣慣ㅤ摣㙦摣㘱ㄴ戸慣っ攴愷〸㘵〴㙤〷捤晢㉣愷收㕥㔴戸扢㙥摡昰㘵㙢攳挶愳扡㘹户攱搴晣㔷㙣㕣戹ㄸㄸ㠱扣戶扤慥㌵㐸㐷户㐵戰㤵昴搵晢慥㙦敦㜶搶愸㌷攴搴㈵㉢慣㝥㘵㕢戵扤攰戹换摤㙢㡦㝡昲㠱㘶㙤挷㡣愶㈰搴搶搴搸ㅤ慢っ慢挲㜹㡤捤慣戸扥㜴搴昴挶敤〵慢㝡㐱㝡㡢㤲㈲㔱搶搴㔲慦㘴㔵挴昵攳昳づㄶち㙥慤扤㉡㔹㙡摥㝤㈹〰㌳换ㅡ收扢㉡扤㘰㝤挹㔸慥换慢㔲㑤挲㜷愲㘲㙦慡昸愸㕢㙤昸㌳慥ㄳ㜸㙥㍤㕤㌳㔵㕢㌳㈰㘹㙡㈷摤㥡捣攷㜳㑡㈸㐰攰昶昵〹㤱扢慤㍢㉦㈸㐴㈴㔰㑣㐶扥㈶㑤㜶ㄳ愷戱㍡慣愲㉥㐹㤳摡慢㌷ㄹ㡣昳㔵㌲㈶㠳〳ㄳ㙢愲晥攰㑢㙦摤㘴搸㈶收㕥摡挶㥡㌶ㅡ慤晥敥㌵改〴挷つ愷㔶㤷㕥愶昶ㄳ㥣㤱㍥っ㔰戸っ㠱搰㜵昷愸敡挴㈵戱㕥戸㘸搵㠲㤵攲㡡戴捥慦〴㈸㠳㠶㉣㤵戸戵ㅤ㐹扦〲㐵晡㙥㠲㔱㠰㜲㌹㔷摣挳㐶挵㌲㔲慥㐰改㤴挱换㈹㐱捥㝥㈹㕥ㅥ㌴㡦㕡昵㐰㠶㐲㜹搸〴㐶㐲慤愶搰㌷㐴ㄲ昵㡣㙡愸㌰昶㤸㌳愰㔲挳㜲㠲昵ㄶ摦㜶㜰㐹㐸㐴㍢戲㘰摢挹〲㡡㠲戴㍣挸攰㌵㄰㑤㥢㌴挸㙥㥣㈰㈲戲㐱㠶㘶挷挸㘹㈲㘳晢っㄹ㠱昶㐹㈲㘴敢晤摤㘵〴㠹扤㤳㐸搹愹㉢㍦敥㐸戳㡤㙣昹㔰㥡㕤㠹㡤搳慦㈲戸㥡攰ㅡ㠲扤〰攲㑦㤰㜰㤴㜲挸愷㤳晥ち㍣敢搷ㄱ扣ㄲ〰昲㐹愷捣㠹㐴ㄵ㙤愸慤搸㤱㙣㌷〴㍢㔹ㄹ挵愱㈸愲㘵摣戴㌳㠷㙣㠵攸挸敡摣ㅥ扡㌶慦㜴散㙢扡搳㘶㜲㌹愴挸㡣愶挹戵㙥搲㌴戹ㄱ㙣摡愳摥扡〱㕤昵㌱㠲ㅢ〱捡晡慢〸愱㕣㘸昰㙥捤愲愷㐹昹戲㌰㡢㐲㘳愸㐷〵ㅦㄱ㌲㡦〰ㄹ㐲慥攳昸戲㘳㐳搳ㅣㅣ㌷㕦昶㌶昴扥敥晣ㅤ㈱扤㑤㙦敥攸ㅤ晡㡢㥥愷ㄵ㝤ㄳ搸㑢晣慥慢㡥戹ㄹ搵晡㙢〸㙥〱㘸搳㌱㍣㝤㍦㕦㑦㠱㌲㡢敤〴收㜶搳敢愲慣摣愵昵㔵愹㌴搰愰戹㘴㜸攷㘵〰て挶㠹㔹搸挲慥攷挹㍡づ戵㌵㔵挰昳换搵改㐲晦愸攷摡㉣摦戱㤱晤㤷㠵㘲挸攷戵扥㕣㥢㡤㥣㘱㙢㈶㝣㑥〹捡愱づ扥愳扢㤰㐸㜴㑡㤳ㄷ晢㘵㥦㉦㜷㈴㐹て㤲攴戵搸㔶晤㌶〰㐸〹昱㥢慥ㄲ㘵ㅦ㥢扤㑥㌵㑢㕢慣昴昰㘵㥣㑥摡㝣㠸ㅤ㜲㘴㈰㜴搸㑥挳㝦攰て搹㡢㤶摤ㄴㄶ〳昶㠲昴慡昰㉤㔸㜵㔹づ摤戲ㄴ㌵㍢戲攲㘵㈲㉢晡晡㍡捥搳ㄹ晥㌵㐵㈷㙤㔲㈲㤳摢㌳㉢㌳捥攲㉤愲愲ㅢ㤲㐲㈵挳㌵搴㤴㐰愴㍣戶摤ㄱ㌱㍤㠸㤸摢戱㜱晡㝥㠲㐹㠲〳〰㠵㕦㐲搲㙣㜵攳ㄹづ敢㕦愳㑢扢㔲挹㤵㠸〶攵㈲㝣戶慢戰㍡挸搷扣㥥攰㄰㐰㥢昹㐳〷㘴〶㈱㉡㤴㈷〸㔱㠵㌱捣戳㤶扣㐸ㅡ搸㘵㈲戰㌴搳昰〳搷㘶㘴㘹挸㥣㜵㑦戹挱慣攵慦㈲ㄲ㌵㙡㐶㤹晢㔶愴〳敡昲㘰晢戴㤵戹慢慢戲愶㥢㡢㙥〳愲敤挴散㜶㌸㤸㘳㍢㘰㑢慡戳戹㈶㤰㝡㍢ㅦ㘳〸㠱㥤㔶晥㔶㝡㘳户攴晤收愱㙦戸戵愳㑢㔶㔰㤷〳㘶挸㜴捣㤷㑣散㈲㈲〷戵㝥㜳㘹挵㤳㜲㜶挸㍣收㔹戵扡攵㐸㈲〳㌶㈶㠳㜵㜳昲㍣愲〴ぢ㉥㘳㠰慥㌳㘴㉥㜹㠶攳慦ㅡっ㈸慥敦㑥㍤愹戰㐸挱㥣戶ㅣㅦ慦㔱㔸㘴㝥搸㕣㕣㜱㉦㈲㘲摢戰㥤㘳挶慡扦㉤戰㐲愲て㤳㐲㡤搰㠴愶㠹㤲㔶敡ㄵ㍦㍣㤰攷㜲攴扤㍣㠱挲㔵慥㐰㥦㜹㠶昶愶㕤ㅦ挵㘸㘸愷㜳㑥㠳㠸ㅥ㌵ぢ晢㌲愵㌰㌹㔵扦㡢㝤摥〸㜰捦戱㌳㈷㕡㤱戹ㄷㄴ戳㉥搰换㥦㈱攳ㄵ㔹㌴〳㈱昴搱敤ち㐹㠵㘵愴ㅣ㜰㈰㌰捥愷㜶昲㉢㥢慡つ愹㙦㔷㉢㝢ㄴ㤱愴㐱㜳捥㔸㤶㜵挴愳㙤㈳搸ㄵ㍥搰㡣戵㡤扡ㅦ搵捤戸戶㙤㤰戴㐸㤶㡢㔵㠳ㄴ㍣搵〸摣㤳㤶愳㥢〰㡡晥愲㈲攳ㄲ㡡㡣㑢慡㘸搰㍣捤搰愰捡㜳㉣昷扣攱㔹挱㡡㙤㔵㑢㝣㘰昸㙥㕢搰㈴㤸㥣㤲㌷㑥戱捣ㄸ㙢戳收捦挰㘴昳㈷㠰敥〹挸㔱㙥ㅤ搱て捡搵㐴ㄱ晦㐴㡦㡥㈵〸ㄸ攵㈹搵摦㡣搱ち敡㜶〴㐴㡥㑡㤷攳㍢ㄸ㤷ㅦ㐶㐹㈸㠴㠸昵っㄲ㠱㔷㌰㈱攴改攲㉥㥡㘷ㅣ㉢〰昶㠸戱愳㔶㌰敢〳攵〰挸慡攳敤戵ち慢㠹㑥攳㑤慤㜰㐳㘷㔵㑡㑤㕣摦㔹㥦搴ㅢ慦摥愰㍡搴㈸〹㐵戲㔹㈳愵㔹㌶㤸攳㜶㔲㌵㐲㈹敥㔸摢㠸㉣户㘹㙢摦㈹㐵㕥㠰㘲㔲㌴㤳搳摦愲〸〵㠱摥㐸㐷搱㘷㥦㑤ㅥ㠹㠸つ㙤㠰㌲昵㔴㔸㌶ㄴ㠵〴㑦攰摡㐹㑤㤶愳㈷昰昷慥㈸㍢摦〸㔲㌵挶愵搱愸㘶慡㕥㥦㜷㘰㈵㔴つ慦戶㑤㔸ㅡ㙢ぢ㌵㡣攲捥㕥戵㝦戸扤〹㐶㡣搸㤰㘱㤱っ㍦㌰搸㄰捣㤵㠸愸搲㍡ㅢ攲㔶㌷㡢㑢㝣㍡㈹つ㐷㘱㘰㌱愸捤捡㌵㘵㠶戵㉣昹㔱搵愱㜹㕡㔴㜲㔴㌷愷㤶㝤愸昴㠰㜲㍣捡㈹〶搷捤搳㜴㑢攱ㄲ〳挴㙥㤴㕢愸〶〸敤㌶〷攰挹㘰晢㘰〷㍢ㄲ㠶㑥㘸㥤㔱㠲ㄶ㌳〸㌷扤〸昲㑥㡦ㄸ㠵㈰㌵㔵晡摢ㄱ昱搹㈷㤹扥㝥㈴ㄷ㘷㈲㈶㘲戸㉢挳㝡〰㜲㤳㤱㐹㜲搱㘸ㅣ㌰て㈵㥢ㄲ㕡㠳㜱ㄹ㑤㡣㈱㥡㝣㕥㠰㕢㍣㡣㘵つ㤳㙤敡戸攷ㄶ㔸搰愶昵昵㕤收〹愷㕡㙦搴愴㔲挵戱慣㔶ㅡ㜹㕢攰㑢㕤〱っ戹㈹㘳㕦愲㑤㌹㠱愳ㄴ㤷㑣㈴昵㙥㜷敢㐷搰㕤〹㌹㡣ㄱ慡㍥〶㈰㌳摣㜲㉡㈰搶㜱㑦㠱昶攱敥搶〵〶㜵㜹づ㈲慤愳㠸戲㙣づ昷昱㥡㔱㘴挵㙤㠹㘶㜳敥㥣㑢㥢㍤㔱㜴摣ち㡢戶〵㡥戰捥㔰攰ㄵ㡢㌰㐶㝡攴づづ㤲扢ㅣ㐵㜷㉦㍦慣ㅥ㜳㤷㠱ち㠵〱挱ㄸ㉦㑦㐱㌹散㉡ㄸ㠹〶户搶戲扡〵愳扦戴扣昵㈹〰挱㌰㌰つ㕡戴っつ㥣ㄹ攴㌷㌷㜰㙥㐰慢㡣〸㘹㌲㤸捡ㄸ攵㈸ㅣ昶㐰ㅡ戸㠹〷改㈵ㄷ㑡㈸搸愳㉥㠶挵㜷ㄳ挷㙤ㅣ㠱㕣敦慡戶挲〵㈳挰昵ㄷ㘷㙦㕢昱㔴慤㐶㜳ㄷ晥戹㙤㠱㔵㕣摤〸捤搱㍤㙤㤷戲搴㥡㘸摦摤搴㔶ㄱ㕤ㄶ㍣㌰㍢㜱摣〸慡㉢㡢挱㝡㜸㜱慢㔷㤲㈸晣〸晥㠸つ摦㑥㥢㌹敦昰㈲敡ㅡ昷扥㝣挱㜱㉦㍡㙡㕥〵㥦户晥㐰㈱戸㐲搹捦㐹㤶㜳晦挶㍦㤵戴㕣攱㠷ㄸ㜱㉢搳收〰㉤〷〹挷㔱㈹㤴〶㘳挸㘷搰〹㙣昷收慤〱搲挹㥥㌶㍡㔱㠲㘰㠷㔰㥣昳㉦ㅡ愱㠸ㅦ〰慤㈴㤶昰㐸㡥㍤晦ㅡ㔸㕦㝣ㅦ㈵㐴㌸㥥㈳㌱㔲戸ㄱ戹っ搴㈹㐱ㅥ㕤昱攰㠵㤰晦ㅦ㉣挵摣扣㈱㍢晤ㄷ㤸㔹㝣慦ㅤ㐵搷ㄳ㐵摦敤㐰㤱攰㌵㄰挵扦昷㈰ㄳ愷〲挳戳捦㉢㄰捥㌵敤ㅣ㐰㕦昲ぢ扦晦挳〳攸㕣㐴ㅣ捡㐶㐳愸敤㘶㍣㌷㑤㠴扥づㄳ㠱挱㝢㘵㈲㥣㐴㐶㌰㡡ㅦ㥡〸㤱て㘴ㅥ〵㥢㥢〸㡣敤㘵ㄸ㠲㠹㔰㙢挲慤挱ㄳ搸㔵㌶晤㘳挷㜱昱㔶晡㠸攷㐳㘹昹㌳昰㐸㕤摤㔹扣㘰㜸㠶扤㔷㤵ㅦ昳㈴㤴㤹户㠴㥢摣慡ぢ㝢㕣扢㘱㡤敡戴㠱慦㈲昶戲敦昸㔳戶㜶㝦ㅤ㤸ち㔳攸扥ㄷ㈵㔱㝣〱㥥ㄲ挱㜳㐳敥扤㝢扥㜱散昷て㍥㝡㠴户搵㈲㕡㉤摣㠶㝣㉦㈱㝢摡ㄳ〸敡㈶㉥㡡㕣挹て㜳㑥攲ㄳ㈵㙢戵㉥愷つ㑦㔹㐱扥㙥挷搹㤰昰ㄲ㠴ㄹㄲ摦㜶㌰㌱㜱敦㈱㌴㌱㈷摡摣㥤敡挳㈶攵㈲㥣㐸㑣㕣昹昴攲戰愱攸慡挸㝡戴㌶ぢ摦㠲㉡㝡㥥ㄳ㐹㕢㠹㍣㜵㌲〹昱捤㜶㕤㜷㤰扡㉥㍣挸㌰散ㅦ㑢㈹挴ㅦ㐸㈱挹㠳っ㉦〴㈸㈹㜵ㅡ㤹挲敤〰ㄹ㤱戵昶㄰㉦晤〱㍢㐲㐰㌶㉦晤昵昸ㄱぢ㜶ㄱ㔸㡣㝤昱扤㥥㘸㘹㡢挶慡㠹愱㕡㘵搳㉣㈲愳づ㉦㉣㤸㡣㑢㔳㤶捥〱㤴㙥搹ㅤ挵㤷っ搹㘱攰㉤㘴散㠲㑤㕦㕢搹扥摢㘹攰收〷昴㑣㔱㈹っ㘷㌷㡢㜱㈰㔵㌱扡戰㘹㌹㉣㈲ㅣづ戳捤㑥〳㔱ㄵ㜴㤶戳ㄷ愷㔲〴晦昸愵㄰敢挷㕢㐳㕦搹㕥㐳ㅤ攷昴㘳㠱晣挱晥扡㍥㠳戱昱㔶㜲っ㈴散㤶㕡㤵挲敢攱㘷搰㠵㡢捥〹扤㤵㔵捦攲㈰晥挴㥣搵愷㜵攸㝦㐶慦ㄵ㘷㥤㘵㙦㠶戱㔳晡晦敤㈸搸㔴晦ぢ挶摥ㄴ㈲摦ㄱ㘵昸㔰㘰晣㘴搳㤰つ㜷〴㥥㙤〴㙦搴挱㔸㔷㔹㠶扣挳摣㈲㍥㕥つ慢㤵〴㠷摦㉢摦㝥㌵愲搹㤷戶敤㐰㔷〱挸搸㔰攱㙢㄰㐱㕤晢愷攵㔶㝣扡㉤扥ぢㅤ昷㥣戴慡㥥敢扢㘶㌰戶㠸愰敦ㄸ扦㍤㌳㘱昳㑣㠹慦戴ぢ戵㥢戰ㄳ㠳敦㐱㥦㔳昳㄰搸愷㘴昰㘲挵㈲ㄹ㔹搸㕡㈴㠳摦㈱㡤㈴挲㑢搴づ晥ㄵ收扤つ愳㡥㑦㔷攷攱敢っ㔸戴㉤㤴㕤攸㜱㙥扦愱挱慤挳ㅤ慤户挱ㅦ㈴敢ㄳ〸㡥愹㈵扣敢㍤摣搷昶㍤㐸户㡤搶收戳㘵㙦㍥户㜲攱㘹攰㜴㙢㙦㐹㤳っ摦挹㉦㤲换㝡㠵㄰㤷昶㡦攰敦搶ㅤ戴ㅣ㙤ㄴ㜴ㅥ㝤搰㑤㐷搸㜸ㅤ敥戳㉤㐴扦捦愱慢㤸㈲挰㑦㌷愲っㅦ〴扤㝣㘴㐵昱〵㉣㡢っ㠰㝣慥㔸〵攸㑥搵㑦㙤㐴搵㈳戱㐰ㄶ㍣㘳㤰ㅣ换攲㜳㘸挸敤ち㤷つ㤶攰戲㠵㍡㑢㈰慦挷㍤㤰捦〹㥥㈵搴㐴㍥㠳づ捤㠹㔸㈸敤㍥㤱㑦㙦㌴ㄱ㐱㉢㐰㉤㌴㌹晥㐸慣㐵昴㍡慡㜵㥢挰㈱㜰〱㠶㈹ㄶ㈹㙢㡡㘱㘸攱晢挴っ搲慦愲扦捦ㅤ昹攵戳㑣㝦㍤㈲㤴㈰㐴㔵㝡昲ㄴ㠴㙡昲㡦㈷㈷敦愱戴晢攴ㅦ摢㘸昲㈳㤴㤱㥣㠹ㅥ〰っ昵㠹ち晥愸挵㌴㤰攱㍥昲㈷捥ㄱ攰㤷㥡挵㠸㠱ㄲ搵昷㈲㌲攸换つ㔷慤㉥㈱ㄳ昷㉤㜰晤ㄹㅦ昷㈸晢㠸ㄷ㈱改换㈹㠶捥搸㘲愸ㄵ㑢㜶攴㠵摤ㄶ戲〱㑢攲搷戲㕤㐵㝡戱挷〸扦昸㔰㡣㤸攳挷攳㉦愷戴㈸收〴挲〸㉤㔲搲て㌷㔲㝣㌰㙥晣敤㘷㕡㉥㔳㔴㈰㠱㝡挲挶愴㌳搵昸〳㜱攳〳昸㉡㑢戵挹昱〶〱搳㜳㜱㘳搲愳㙡晣㘸摣昸㉦〷昶㌶ㅢ挷㜴ㄸ㡥㕣㈰㤱㘴搸扡捡晡㑦㝣愱㍤㡣收〵㤳晡㜳挰っ㡢㈹㌹㔵攸戸慥㌴攸㈰㉥㠳㜸昸㐶㝡づ㜷㥢㜰〵〴㐲㌶晣㕦㈵㥣挰㥤愷㔹㈳㌰昰〹昴ㅡ㠲捤㥥慥㥥搸戹㘸捥㝢㈸攸㌷㑦昸㌸㔳搵戶ㄵ㠹挰ㅣ挸㠷晢扢㠹㔳㍥挳㜴㙣敤㐷ㅣ㈴搳㜸㠷愴㌷攵愱〲㉢㜹昱扥ㄸ戳戹㐷㕡㌴愳㍦っ攴㐰㍡〲㌲愳㍦〲ㄸ〶㘲㜸㕢㌹㌷㐲晥㔷捣晤㍥㔶扣㥦攰㔱㠰戲㈰戳㤳づ㡡ㅦ〰搸〳㉢ㄵ晦慢ち㝦慣㈶挷㔶㍤戹㘶昹㍦昹戲慢㠹〷攳㌷㈶㘹㐹晦㄰㝢㝤ㄸ愰て㍥㕣ㄱ㔱㘲㔹晦〸㑡㤲㙦愶昴㔰㙦晥㈸㉢㍥㐶昰ㄸ㐰戹挰ㄹ㙦㜹敢戸戰ㅥ搵搷挷搱㔵㍣㐲㠰㥦晥㜸㤴攱㐳㠱㥢昱愶敥〶㌳捦挳昱搷晤㠸㜷愶㍥攳扦ㅢ㥦攵慦㜳搱㝤昸扦㤲ㄴ㤴㜵㥦搷摥搸摢㔸攴〴ㅡ收敡户㡡捤㝥〱攳㜰㕤慤㌰ち㐷愴㘶㈹㘹㐵㐱愴㜳挱挲挵ㅢ昸㤶挳慡㐲〸ㄲ㠲慡㜰愲㡡㈳㈸搰㍦挱愶挴㌱昱愴㝦㤲㑦㐴慤摡挴㑦㐵ㄹ㍥〸攲㔵㜵扦㍦敡ㅥ扦㤰戸㔶ㄵ㔶摢ぢ㠹㝦㔵戱㤲㝣攱㤳ㅣ㑣㈱ぢ㤹戴㙡㈲搲ㄴつ㝤づ㤹愱扥㘱捥敤㍥晣戴㑢愲㝡慥㜶敥摣㍦㠷昳㘳搷收摦晥搶挱㈷㥦晢挵ㅦ㥥昸昵扢て晦昹㕦㑦㍤昵敢㍦㍥昱散扦㝥戴㝣昸㘷㑦㍦晤搳㝢扥昸散ㅦ㜶㥢㕦搲㥥昹攷摣㤷ㅥ㥡扣昰搰〳收㤹摢㡥㍤昴㡥晢敦㥤㕣戸㘲扣慦慦扦晦㤶搱㥦㕦㜳敢挸㈳て㝣㑦晣昸户㔷㍢㐲㉤ㄷ㉦㐸㑦㠳换㔶搳昸㍣㌲㤸〶㘷晣㤲㑥㠳换㔵ㅢ戵ㅣ㙤搴㌴ち㑡㜰㙣㜰〲慡挲㐸㔷っ晣〷慣捤戴㠳 | C30: 㜸〱敤㕣㕢㙣㈴㔷㤹敥㔳敥㙥㜷戵敤戱㌳㥥㐹㌲㈱㈴づ㈱〴攲挱ㄹ㑦㌲㠴戰㍢っ扥㘴㉥㠹㘷散㑣㝢㈶愰㉣敡㈹㜷㥦ㅡ㔷愶慢捡愹慡昶㡣戳㤱ㄲ㐱㐲㔸㉤㈱ㄲ㝢搱㘶㤳摤愰㠰㤰㤰㔶ぢ扣㜰㤷㄰〲〹㠴㠲戴て散〳ㄲて搹〸挱〳〸㐶摡ㄷ㔶㐲㘲扦敦㔴㔵㜷㔵户扢散㜴㤲挵㔹昹㑣晡昷愹㜳慢㜳捥㝦㍤晦㝦㉡㌹㤱换攵晥㠴挴扦㑣㜹㘶㙥慣㙣昸㠱戴愷收摣㐶㐳搶〲换㜵晣愹ㄹ捦㌳㌶ㄶ㉣㍦ㄸ㐰㠳㘲搵㐲扤㕦愸晡搶㘳戲㔴㕤㤷㥥㡦㐶㠵㕣慥㔴搲㌵搴㜳㄰晥挶攲〷㥤扤㠶昳〰换㜳戳㡢㉢㡦㘰搴㑡攰㝡昲攰挴昹戰敦搱改改愹改愹㈳㠷敥㌹㍣㜵攸攰挴㕣戳ㄱ㌴㍤㜹搴㤱捤挰㌳ㅡ〷㈷㤶㥡㉢つ慢昶㠰摣㔸㜶㉦㐹攷愸㕣㌹㜴搷㡡㜱昷〷愷敦㍥㜲挴扣昷摥てづ攳搵戹㌳㜳戳㑢㥥㌴晤㌷㘹捣〲愷㝣昷扣慣㔹㕣㥢㤴㥥攵㕣㥣㥡㥢挵㝦㠹昹攳改㥥愹捡慡㤴〱㕦㉤㍤改搴愴慦愳攳㤰㍤攳晢㑤㝢㡤㥢愷摢挷戱搴㥡攱〷〵㝢㑥㌶ㅡ扡ㅤ㡦㕡戲ㄷ戱㜷つ㘳㘳搸慥㐸挷户〲㙢摤ち㌶㡡昶㌲〶慡㡦搸攷㝣㜹搶㜰㉥捡㌳㠶㉤ぢ昶㠹愶㔵捦㠷㈹㌷㜰㝢㍣㐴㜲㘲㙡昹㔳㌳扥㍤户㙡㜸㙡㐶㍥㌷㈶愳敤㜱慦㤶㙥㝢㙢敦㜱㌹㜵昵〶㡥㜹㕢敦㜶愸㌹㙦㜸慤㤶㤳扤㕢㐶㡢㑦捦攰捥摥敤ㄳ㝢㤴敥昳扥摥㝤搴㔶愶㕢㡢愱㠸扥搵㡥㘲㌱㝡㤱㘰㤰愰㐴㐰〴敡㘵㠲㈱㠲㘱〰㤱晦㙦㜰㐹戲㈳慢戴慡愱㔵㔷戴㙡㑤慢搶戵慡搴慡愶㔶扤愸㔵㔷戵慡愵㔵ㅦ搱慡㤷搰㈶㑥愵挱㐱㉤㑡て扣戴攷㍢㤵〳晦㜳晦昷扥晣愲昹搸敦晦㙤晦昰ㅥ㌴㝡㌰㥡搴扣㘷㕣〶愹戵愹ㄸㅣ挱㝦㕢㜳〵㤸挲㍣㘲摥㘳㑥㑦搷㡦ㅣ㌲敥㌲ち㕣㔶〶昲㔳㠴㌲㠶戶挳收㐳㤶㔳㜷㉦㉢摣摤㌸㙢昸戲扤㜱㤳㔱摤慣摢㜴敡晥㍢㌶慦慣〴㐶㈰㙦攸慣㙢て搲搵慤〲戶㤲扥㝡摦㑤㥤摤捥ㅢ㡤愶㥣戹㘲㠵搵敦散愸戶㤷㍣㜷愵㜷敤㜱㑦㍥摡慡敤㥡搱っ㠴摡扡ㅡ扢㙢㤵㘱㔵㌸慦㠹戹㔵搷㤷㡥㥡摥愴扤㘴搵㉥㐹慦㈲㈹ㄲ㘵㕤㉤㜵㍦慢㈲慥㥦㕣㜴戰㔰㜰㙢晤㕤挹㔲昳扥㉢〱㤸㔹搶㌱摦㌵改〵ㅢ换挶㑡㐳㕥㥢㙡ㄲ扥ㄳㄵ〷㔲挵挷摤㕡搳㥦㜳㥤挰㜳ㅢ改㥡㤹晡扡〱㐹㔳㍦敤搶㘵㍥㥦㔳㐲〱〲㜷㘰㐰㠸摣ㅤ扤㜹㐱㈱㈲㠱㘲㌲昲昵㘹戲㥢㍡㡢搵㘱ㄵつ㐹㥡搴摥扤挵㘰㥣慦㤲㌱ㄹㅣ㤸㔸ㄳ昵〷㕦晡摥㉤㠶㙤㘱敥慤㙤慣㘹攳搱敡敦㕢㤷㑥㜰搲㜰敡つ改㘵㙡㍦挱ㄹ改愳〰㠵慢㄰〸㍤㜷㡦慡㑥㕣ㄱㅢ㠵换㔶㍤㔸㉤慥㑡敢攲㙡㠰㌲㘸挸㔲㠹㕢摢㤵昴㙢㔰愴敦㈵ㄸ〷㈸㤷㜳挵㝤㙣㔴㉣㈳攵ち㤴㑥ㄹ扣㥣ㄲ攴散㤷攲攵㘱昳戸搵〸㘴㈸㤴㐷㑤㘰㈴搴㙡ち㝤㈳㈴㔱捦愸㠵ち㘳㥦㌹〷㉡㌵㉣㈷搸㘸昳㙤ㄷ㤷㠴㐴戴㉢ぢ㜶㥣㉣愰㈸㐸换㠳っ㕥〳搱㜴㐸㠳散挶〹㈲㈲ㅢ㘴㘸㜶㡣㥣㈶㌲戶捦㤰ㄱ㘸㥦㈴㐲戶㍥搴㕢㐶㤰搸扢㠹㤴㥤㝡昲攳慥㌴摢捣㤶て愵搹㝥㙣㥣㝥㉤挱㜵〴搷ㄳㅣ〰㄰扦㠲㠴愳㤴㐳㍥㥤昴㜷攰㔹扦㤱攰㥤〰㤰㑦㍡㘵㑥㈴慡㘸㐳㙤挷㡥㘴扢ㄱ搸挹捡㈸づ㐵ㄱ㉤攳㤶㥤㌹㘲㉢㐴㐷㔶攷捥搰戵㜹愵㘳摦搳㥢㌶㤳换㈱㐵㘶㌴㑤慥㜵㡢愶挹㡤㘰搳㍥昵搶捤攸慡㑦㄰摣〲㔰搶摦㐵〸攵㐲㠳㜷㝢ㄶ㍤㑤捡户㠵㔹ㄴㅡ㐳㝤㉡昸㠸㤰㜹〴挸㄰㜲㕤挷㤷㕤ㅢ㥡收攰愴昹戶户愱て昶收敦〸改ㅤ㝡㜳㔷敦搰㕦昴㍡慤攸㕢挱㕥攲ㄷ㍤㜵捣㙤愸搶摦㐳㜰㍢㐰㠷㡥攱改晢昵㝡ち㤴㔹㙣㈷㌰户㤷㕥ㄷ㘵攵㉥㙦慣㐹愵㠱㠶捤㘵挳扢㈸〳㜸㌰㑥捤挳ㄶ㜶㍤㑦㌶㜰愸慤慢〲㥥㕦慥㑢ㄷ晡挷㍤搷㘶昹慥㡤散扦㉤ㄴ㐳㍥慦つ攴㍡㙣攴っ㕢㌳攱㜳㑡㔰づ㜵昰㕤扤㠵㐴愲㔳㥡扣搸㉦晢㝣戹㉢㐹晡㤰㈴敦挳戶敡㜷〰㐰㑡㠸晦散㈹㔱づ戲搹晢㔵戳戴挵㑡て㕦挶改愴挳㠷搸㈵㐷㠶㐲㠷敤㉣晣〷晥㠸㕤戱散㤶戰ㄸ戲㤷愴㔷㠳㙦挱㙡挸㜲攸㤶愵愸搹㤵ㄵ㙦ㄳ㔹㌱㌰搰㜵㥥捥昰慦㈹㍡改㤰ㄲ㤹摣㥥㔹㤹㜱ㄶ㙦ㄳㄵ摤㤰ㄴ㉡ㄹ慥愱㤶〴㈲攵戱敤慥㠸改㐳挴摣㠹㡤搳てㄱ㑣ㄳㅣ〶㈸晣ㄴ㤲㘶扢ㅢ捦㜰搸攰㍡㕤摡搵㙡慥㐴㌴㈸ㄷ攱㉢㍤㠵搵ㄱ扥收〳〴昷〰㜴㤸㍦㜴㐰㘶㄰愲㐲㜹㠲㄰㔵ㄸ挳㍣㙦挹换愴㠱㍤㈶〲㑢㜳㑤㍦㜰㙤㐶㤶㐶捣㜹昷㡣ㅢ捣㕢晥ㅡ㈲㔱攳㘶㤴㜹㘸㔵㍡愰㉥て戶㑦㐷㤹扢戶㈶敢扡㔹㜱㥢㄰㙤愷收㜷挲挱ㅣ摢〱㕢㔲㥤捤㌵㠱搴摦昹ㄸ㐳〸散戴昲户搲ㅢ扢㉤敦㌷て㝤愳敤ㅤ㕤戶㠲㠶ㅣ㌲㐳愶㘳扥㘴㘲ㄷㄱ㌹愸て㥡换慢㥥㤴昳㈳收〹捦慡㌷㉣㐷ㄲㄹ戰㌱ㄹ慣㕢㤰ㄷㄱ㈵㔸㜲ㄹ〳㜴㥤ㄱ㜳搹㌳ㅣ㝦捤㘰㐰㜱㘳㙦敡㐹㠵㐵ち收慣攵昸㜸㡤挲㈲昳愳㘶㘵搵扤㡣㠸㙤搳㜶㑥ㄸ㙢晥㡥挰ち㠹㍥㑣ち㌵㐲ㄳ㥡㈶㑡㕡愹㕦晣昰㐰㥥换㤱昷昲〴ち㔷戹〲㝤收ㄹ摡㥢㜶㝤ㄴ愳愱㥤捥㌹つ㈳㝡搴㉡ㅣ挸㤴挲攴㔴晤㕥昶昹㄰挰晤㈷捥㥤㙡㐷收摥㔰捣扡㐰㉦㝦㠶㡣㔷㘴搱ち㠴搰㐷户㈷㈴ㄵ㤶㤱㜲挰㠱挰㌸㥦㍡挹慦㙣慡㌶愴扥㍤敤散㜱㐴㤲㠶捤〵㘳㐵㌶㄰㡦戶㡤㘰㑦昸㐰㌳搶㌶ㅡ㝥㔴㌷攷摡戶㐱搲㈲㔹㔶㙡〶㈹㜸愶ㄹ戸愷㉤㐷㌷〱ㄴ晤㐵㐵挶ㄵㄴㄹ㔷㔴搱戰㜹㤶愱㐱㤵攷㔸敥㐵挳戳㠲㔵摢慡㤵昸挰昰摤㡥愰㐹㌰㌹㈵㙦㥣㘲㤹㌱搱㘱捤㥦㠳挹收㑦〱摤㔳㤰愳摣㍡愲ㅦ㤴慢㠹㈲晥㠹㍥ㅤ㑢㄰㌰捡㔳慡晦㈵㐶㉢愸摢ㄱ㄰㌹㉡㕤㡤敦㘰㕣㝤〲㈵愱㄰㈲搶㌳㐸〴㕥挱㠴㤰愷㡢扢㘸㥥㜳慣〰搸㈳挶㡥㕢挱扣て㤴〳㈰慢㡥户㌷㈸慣㈶㍡㑤戶戴挲捤摤㔵㈹㌵㜱㔳㜷㝤㔲㙦扣㝢㤳敡㔰愳㈴ㄴ挹㔶㡤㤴㘶搹㘴㡥㍢㐹搵〸愵戸㘳㙤㈳戲摣愶敤㝤愷ㄴ㜹〳㡡㐹搱㑣㑥晦戰㈲ㄴ〴㝡㈳ㅤ㐵㥦㝤㌶㜹㈴㈲㌶戴〱捡搴㔳㘱搹㐸ㄴㄲ㍣㠵㙢㈷㜵㔹㡥㥥挰摦㝢愲散㘲㌳㐸搵ㄸ㔷挶愳㥡㤹㐶㘳搱㠱㤵㔰㌳扣晡づ㘱㘹慣㉤搴㌰㡡㍢晢搵晥攱昶㈶ㄸ㌱㘲㐳㠶㐵㌲晣挰㘰㐳㌰㔷㈲愲㑡敢㙣㠴㕢摤㉡㉥昱改戴㌴ㅣ㠵㠱㑡㔰㥦㤷敢捡っ㙢㕢昲攳慡㐳敢戴愸攴愸㙥捥慣昸㔰改〱攵㜸㤴㔳っ慥㥢㘷改㤶挲㈵〶㠸摤㈸户㔴ぢ㄰摡㙤つ挰㤳挱捥挱づ㜶㈴っ㥤搰㍡愳〴㉤㘶㄰㙥㝡ㄱ攴㥤㍥㌱ち㐱㙡慡昴扢㘳攲㥦㥦㘷晡昲戱㕣㥣㠹㤸㠸攱慥っ敢〱挸㑤㐶㈶挹㐵攳㜱挰㍣㤴㙣㑡㘸つ挷㘵㌴㌱㐶㘸昲㜹〱㙥昱㌰㤶㌵㑡戶㘹攰㥥㕢㘰㐱㥢㌶㌶昶㤸愷㥣㕡愳㔹㤷㑡ㄵ挷戲㕡㘹攴ㅤ㠱㉦㜵〵㌰攴愶㡣㝤㠹㌶攵ㄴ㡥㔲㕣㌲㤱搴扦摤慤ㅦ㐳㜷㈵攴㌰㐶愸晡ㄸ㠰捣㜰换愹㠰㔸搷㍤〵摡㠷㝢摢ㄷㄸ搴攵㌹㠸戴慥㈲捡戲〵摣挷㙢㐵㤱ㄵ户㈵㥡㉤戸ぢ㉥㙤昶㐴搱㐹㉢㉣摡ㄱ㌸挲㍡㐳㠱㔷㉣挲ㄸ改㤳㍢㌸㐸敥㙡ㄴ摤扤晡㠴㝡捣㕤〵㉡ㄴ〶〴㘳扣㍣〵攵戰慢㘰㈴ㅡ摣㕡摢敡ㄶ㡣晥搲昲搶㘷〰〴挳挰㌴㘸搱㌲㌴㜰收㤰摦摡挰戹ㄹ慤㌲㈲愴挹㘰㉡㘳㤴攳㜰搸〳㘹攰㈶ㅥ愴㤷㕤㈸愱㘰㥦扡ㄸㄶ摦㑤㥣戴㜱〴㜲扤㙢㍢ち㤷㡣〰搷㕦㥣〳ㅤ挵㌳昵㍡捤㕤昸攷㜶〴㔶㜱㜵㈳㌴㐷昷㜵㕣捡㔲㙢愲㝤㜷㙢㐷㐵㜴㔹昰昰晣搴㐹㈳愸慤㔶㠲㡤昰攲㔶扦㈴㔱昸㉥晣ㄱ㥢扥㥤㌶㜳摥攱㐵搴㜵敥㝤昹㤲攳㕥㜶搴扣ち㍥㙦晤㠱㐲㜰㠵㜲㤰㤳㉣攷晥㠴㝦㉡㘹戹挲㜷㌰攲㜶愶捤〱摡づㄲ㡥愳㔲㈸つ㈶㤰捦愰ㄳ搸敥慤㕢〳愴㤳㝤ㅤ㜴愲〴挱㉥愱㌸ㄷ摦㌴㐲ㄱ摦〶㕡㐹㉣攱㤱ㅣ㝢晥㈵戰扥昸ㄶ㑡㠸㜰㍣㐷㘲愴㜰ぢ㜲ㄹ愸㔳㠲㍣扡攲挱ぢ㈱晦㝦戰ㄴ㜳昳愶散昴㝦挰捣攲㥢㥤㈸扡㠹㈸晡㐶ㄷ㡡〴慦㠱㈸晥扤ㅦ㤹㌸ㄵㄸ㥥㝤㕤㠱㜰慥㘹昷〰晡㤶㕦昸晤㌳ㅥ㐰ㄷ㈲攲㔰㌶ㅡ㐲㙤户攱戹㘵㈲っ㜴㤹〸っ摥㉢ㄳ攱㌴㌲㠲㔱晣搰㐴㠸㝣㈰㡢㈸搸摡㐴㘰㙣㉦挳㄰㑣㠴㕡ㄳ㙥つ㥥挰慥戵改ㅦ㍢㠹㡢户搲㐷㍣ㅦ㑡换㥦㠳㐷敡扡敥攲㈵挳㌳散〳慡晣㠴㈷愱捣扣㘵摣攴㔶㕤搸攳㠶㑤㙢㔴愷㑤㝣ㄵ戱㤷㝤搷㥦戲扤晢敢挰㔴㤸㐲昷扤㈸㠹攲ㅢ昰㤴〸㥥ㅢ㜲㝦扤敦摦㑦晣搷㘳㑦ㅤ攳㙤戵㠸㔶ぢ㜷㈰摦㑦挸㥥昶〴㠲扡㠹㡢㈲晢昹㘱捥㘹㝣愲㘴慤㌵攴慣攱㈹㉢挸搷敤㌸ㅢㄲ㕥㠲㌰㐳攲摢〹㈶㈶敥㍤㠴㈶收㔴㠷扢㔳㝤搸愴㕣㠴㔳㠹㠹㉢㥦㕥ㅣ㌶ㄴ㍤ㄵ㔹㥦搶㘶攱慢㔰㐵慦㜳㈲㘹㉢㤱愷㑥㈶㈱扥搲愹敢㡥㔰搷㠵〷ㄹ㠶晤㘳㈹㠵昸〳㈹㈴㜹㤰攱㠵〰㈵愵捥㈲㔳戸ㄳ㈰㈳戲搶ㄹ攲愵㍦㘰㔷〸挸搶愵扦㍥㍦㘲挱㉥〲㡢戱㉦扥摦ㄳ㉤㙤搱㔸㌵㌱㔴慢㙣㥡ち㌲敡昰挲㠲改戸㌴㘵改ㅣ㐶改戶摤㔱㝣挹㠸ㅤ〶摥㐲挶㉥搸昴戵㤵敤晢㥣㈶㙥㝥㐰捦ㄴ㤵挲㜰昶戲ㄸ〷㔲ㄵ愳ぢ㥢㤶挳㈲挲搱㌰摢敡㌴ㄴ㔵㐱㘷㌹〷㜰㉡㐵昰㡦㕦ち戱㝥戲㍤昴晥捥ㅡ敡㌸㘷㄰ぢ攴て昶搷㑤ㄹ㡣㡤户㤲㘳㈰㘱户搵慡ㄴ㕥て㍦㠷㉥㕣㜴㑥攸敤慣㝡ㄶ㐷昰㈷收慣〱慤㑢晦㌳㝡慤㌸敢㍣㝢㌳㡣㥤搲晦ㅦ㐵挱㤶晡㕦㌰昶愶㄰昹戱㈸挳㠷〲攳㈷㕢㠶㙣戸㈳昰㙣㈳㜸愳づ挶扡捡㌲攴ㅤ收㉡昸㜸㌵慣㔶ㄲㅣ㝥慦㝣攷搵㠸㔶㕦摡戶㐳㍤〵㈰㘳㐳㠵㉦㐱〴昵散㥦㤶㕢昱改戶昸㌰㍡敥㍢㙤搵㍣搷㜷捤㘰愲㠲愰敦〴扦㍤㌳㘱昳捣㠸㉦㜶ち戵㕢戱ㄳ挳ㅦ㐷㥦㌳㡢㄰搸㘷㘴昰㘶挵㈲ㄹ㔹搸㕥㈴㠳摦㈱㡤㈵挲㑢搴づ晥㌵收㠳㑤愳㠱㑦㔷ㄷ攱敢っ㔸戴㈳㤴㕤攸㜱敥扣愱挱慤挳ㅤ慤〷攰て㤲㡤㈹〴挷搴ㄲㅥ晥㌸昷戵㜳て搲㙤愳戵昹㙣搹㥦捦慤㕣㜸ㄹ㌸摤摥㕢搲㈴挳㜷昲㡢攴戲㕥㈵挴愵晤㘳昸扢㝤〷㉤㐷ㅢ〷㥤㐷ㅦ㜴搳ㄱ㌶搹㠰晢㙣ㅢ搱敦ぢ攸㉡㘶〸昰搳㡤㈸挳〷㐱㉦ㅦ㔹㔱晣㉢㤶㐵〶㐰㍥㔷慣〱昴愶敡ㄷ㌷愳敡戱㔸㈰ぢ㥥㌱㐸㡥㘵昱〲ㅡ㜲扢挲㘵㠳㈵戸㙣愱捥ㄲ挸敢㜱て攴㜳㠲㘷〹㌵㤱㝦㐲㠷搶㐴㉣㤴昶㥥挸㍦㙥㌶ㄱ㐱㉢㐰㉤㌴㌹晥㔸慣㐵昴〶慡㜵㥢挰㈱㜰〱㐶㈹ㄶ㈹㙢㡡㘱㘸攱㕢挴っ搲㝦㐴㝦㕦㍤昶搳㔷㤸㝥㝢㑣㈸㐱㠸慡昴攴㈹〸搵攴㥦㑢㑥摥㐳㘹敦挹㍦扢搹攴挷㈸㈳㌹ㄳ㍤〰ㄸㄹ㄰㔵晣㔱㡢㘹㈲挳㝤攴㑦㕣㈰挰㉦㌵㡢㌱〳㈵慡敦㘵㘴搰㤷ㅢ慥㕡㕤㐱㈶敥㕢攰晡㌳㍥敥㔱昶ㄱ㉦㐲搲㤷㔳っ㥤戱挵㔰㉢㤶散挸ぢ扢㈳㘴〳㤶挴慦㘵㝢㡡昴㘲㥦ㄱ㝥昱㑣㡣㤸㤳㈷攳㉦愷戴㈸收〴挲〸㉤㔲搲て㌷㔲㝣㉡㙥晣戵慦户㕤愶愸㐰〲昵㠴㡤㐹㘷慡昱搳㜱攳挳昸㉡㑢戵挹昱〶〱搳慢㜱㘳搲愳㙡晣㔴摣昸㌷㠷て戴ㅡ挷㜴ㄸ㡥㕣㈰㤱㘴搸扡捡晡㑦㝣愱㍤㡡收〵㤳晡㜳挸っ㡢㈹㌹㔵攸戸愱㌴攸㌰㉥㠳㜸昸㐶㝡〱㜷㥢㜰〵〴㐲㌶晣㕦㈵㥣挲㥤愷㜹㈳㌰昰〹昴㍡㠲捤㥥慥㥥搸戹㘸㉥㝡㈸ㄸ㌴㑦昹㌸㔳搵㜷ㄴ㠹挰ㅣ挸㠷晢扢㠵㔳㍥挳㜴㙣敦㐷ㅣ㈴搳㜸㠷愴㍦攵愱〲㉢㜹昱㠹ㄸ戳戹㈷摢㌴愳㍦〱攴㐰㍡〲㌲愳㍦〹ㄸ〶㘲㜸㕢㌹㌷㐶晥㔷捣晤〹㔶㝣㤲攰㈹㠰戲㈰戳㤳づ㡡㑦〳散㠳㤵㡡晦㔵㠵㍦㔱㤷ㄳ㙢㥥㕣户晣ㅦ㝣挱搵挴㘳昱ㅢ㤳戴愴㍦挳㕥㥦〶ㄸ㠰て㔷㐴㤴㔸搶晦〶㈵挹㌷㔳㝡愸㌷晦㉤㉢㍥㐳昰㉣㐰戹挰ㄹ㙦㝢敢戸戰㍥搵搷㘷搱㔵㍣㐹㠰㥦晥㕣㤴攱㐳㠱㥢昱ㄷ扤つ㘶㥥㠷攳慦晢ㄱ敦㑣㝤挶㝦ㅦ㍥换摦攰愲〷昰㝦㈵㈹㈸敢㍥慦㝤愸扦戱挸〹㌴捣搵㙦つ㥢晤〶挶攱扡摡㘱ㄴ㡥㐸捤㔲搲㡡㠲㐸攷㠲㠵㡢㌷昰㉤㐷㔵㠵㄰㈴〴㔵攱㐴ㄵ挷㔰愰晦ㅤ㥢ㄲ挷挴㤳晥昷㝣㈲㙡搵㈶晥㐳㤴攱㠳㈰㕥㔵昷㐷愲敥昱ぢ㠹㙢㔵㘱㜵扣㤰昸㔷ㄵ慢挹ㄷ㍥捦挱ㄴ戲㤰㐹慢㈶㈲㑤搱搰ぢ挸㡣っ㡣㜲㙥て攱愷㕤ㄱ戵ぢ昵ぢㄷ晥㌰㥡㥦戸㈱晦搱㡦っ㍦晦敡㑦㕥晢摣捦晥敡攸慦晦昸攲㡢㍦晢攵攷㕥昹攳㜷㔷㡥晥攸攵㤷㝦㜸晦㑢慦扣戶搷晣扣昶昵㍦㉣㝣晥昱改㑢㡦㍦㙡㥥扢攳挴攳ㅦ㝢攴挱改愵㙢㈶〷〶〶〷㙦ㅦ晦昱昵敦ㅤ㝢昲搱㙦㡡敦晦晣㍡㐷愸攵攲〵改㘹㜰搹㙡ㅡ晦㠲っ愶挱ㄹ扦愵搳攰㜲搵㐶慤㐴ㅢ㌵㡢㠲ㄲㅣㅢ㥣㠰慡㌰搲ㄵ㐳晦ぢ㐵㌳戵愲 | D30: 㜸〱敤㕣㕢㙣ㅣ搷㜹摥㌳摣㕤敥㉣㐹㤱ㄶ改㡢ㅣ挷㘶散㌸扥㔰愵㐵搹慡攳戴慡捡㡢㈵搱愱㐴㕡愴攴〴慥戱ㅡ敥㥥ㄱ挷摡㤹愱㘷㘶㈹搱㌵㘰㈳戵㥢ㄶ㙤㉥㜰㥢㈰㑥㥣㌴㜰㡢〰㝤㐹㕡〴昰㈵昱㑢㤲〲つち〷攸㠳昳㄰愰て慥㔱㌴〸ㄲ〴〲昲攲〷〳挹昷㥤㤹搹㥤搹攵づ改戵㥤搲〵㡦扣㍦捦㥣摢㥣㜳晥敢昹晦㌳捥㠹㕣㉥昷㕢㈴晥㘵捡㌳㜳挳昲愶ㅦ㐸㝢㜲搶慤搷㘵㌵戰㕣挷㥦㥣昶㍣㘳㜳挱昲㠳㍥㌴㈸㔶㉣搴晢㠵㡡㙦㍤㉥㑢㤵つ改昹㘸㔴挸攵㑡㈵㕤㐳㍤〷攱㙦㈴㝥搰搹㙢㌰て戰㌲㍢戳戸晡㈸㐶㕤づ㕣㑦ㅥㅣ㍦ㄷ昶㍤㍡㌵㌵㌹㌵㜹攴搰扤㠷㈷てㅤㅣ㥦㙤搴㠳㠶㈷㡦㍡戲ㄱ㜸㐶晤攰昸㔲㘳戵㙥㔵㍦㈹㌷㔷摣㡢搲㌹㉡㔷て摤扤㙡摣昳昱愹㝢㡥ㅣ㌱敦扢敦攳㠳㜸㜵敥昴散捣㤲㈷㑤晦㍤ㅡ戳挰㈹摦㌳㈷慢ㄶ搷㈶愵㘷㌹ㄷ㈶㘷㘷昰㕦㘲晥㜸扡㜷㜲㜹㑤捡㠰慦㤶㥥㜴慡搲搷搱㜱挰㥥昶晤㠶扤捥捤搳敤攳㔸㙡搵昰㠳㠲㍤㉢敢㜵摤㡥㐷㉤搹㡢搸扢扡戱㌹㘸㉦㑢挷户〲㙢挳ち㌶㡢昶ち〶慡つ搹㘷㝤㜹挶㜰㉥挸搳㠶㉤ぢ昶㠹㠶㔵换㠷㈹搷㜷㕢㍣㐴㜲㘲㙡昹㤳搳扥㍤扢㘶㜸㙡㐶㍥㌷㈶愳敤㜱慦㥡㙥㝢㑢昷㜱㌹㜵昵〶㡥㜹㙢昷㜶愸㌹㘷㜸捤㤶ㄳ摤㕢㐶㡢㑦捦攰慥敥敤ㄳ㝢㤴敥㜳㐷昷㍥㙡㉢搳慤挵㐰㐴摦㙡㐷戱ㄸ扤㐸搰㑦㔰㈲㈰〲昵㌲挱〰挱㈰㠰挸晦〶㕣㤲散挸㉡慤㘲㘸㤵㔵慤㔲搵㉡㌵慤㈲戵㡡愹㔵㉥㘸㤵㌵慤㘲㘹㤵㐷戵捡㐵戴㠹㔳愹扦㕦㡢搲㑢㕦ㅣ㜰㝦昱昲て㑦㍤昳摤㌳㍦ㅥ扢捤㤸ㅦ摣㠷㐶て㐶㤳㥡昳㡣㑢㈰戵ㄶㄵ㠳㈳昸㙦㝢慥〰㔳㤸㐷捣㝢捤愹愹摡㤱㐳挶摤㐶㠱换捡㐰㝥㡡㔰㐶搰㜶搰㝣挸㜲㙡敥㈵㠵扢ㅢ㘶っ㕦戶㌶㙥㈲慡㥢㜱ㅢ㑥捤晦搰搶㤵换㠱ㄱ挸敢摢敢㕡㠳㜴㜴㕢〶㕢㐹㕦扤敦挶昶㙥攷㡣㝡㐳㑥㕦戶挲敡て户㔵摢㑢㥥扢摡扤昶戸㈷ㅦ㙢搶㜶捣㘸ㅡ㐲㙤㐳㡤摤戱捡戰㉡㥣搷昸散㥡敢㑢㐷㑤㙦挲㕥戲慡ㄷ愵户㉣㈹ㄲ㘵㑤㉤昵㙡㔶㐵㕣㍦戱攸㘰愱攰搶摡捤挹㔲昳晥换〱㤸㔹搶㌰摦㜵改〵㥢㉢挶㙡㕤㕥㤳㙡ㄲ扥ㄳㄵ〷㔲挵挷摤㙡挳㥦㜵㥤挰㜳敢改㥡改摡㠶〱㐹㔳㍢攵搶㘴㍥㥦㔳㐲〱〲户慦㑦㠸摣㥤摤㜹㐱㈱㈲㠱㘲㌲昲㜵㘹戲㥢㍣㠳搵㘱ㄵ㜵㐹㥡搴㍥扡捤㘰㥣慦㤲㌱ㄹㅣ㤸㔸ㄳ昵〷㕦㝡晢㌶挳㌶㌱昷晥㌶搶戴搱㘸昵昷㙦㐸㈷㌸㘹㌸戵扡昴㌲戵㥦攰㡣昴㘱㠰挲ㄵ〸㠴慥扢㐷㔵㈷㉥㡢捤挲㈵慢ㄶ慣ㄵ搷愴㜵㘱㉤㐰ㄹ㌴㘴愹挴慤敤㐸晡㔵㈸搲昷ㄳ㡣〲㤴换戹攲ㄸㅢㄵ换㐸戹〲愵㔳〶㉦愷〴㌹晢愵㜸㜹搰㍣㙥搵〳ㄹち攵㘱ㄳㄸ〹戵㥡㐲摦㄰㐹搴㌳慡愱挲ㄸ㌳㘷㐱愵㠶攵〴㥢㉤扥敤攰㤲㤰㠸昶㘴挱慥㤳〵ㄴ〵㘹㜹㤰挱㙢㈰㥡㌶㘹㤰摤㌸㐱㐴㘴㠳っ捤㡥㤱搳㐴挶昶ㄹ㌲〲敤㤳㐴挸搶㠷扡换〸ㄲ㝢㈷㤱戲㔳㔷㝥摣㤳㘶㕢搹昲愱㌴扢ㅡㅢ愷㕦㐳㜰㉤挱㜵〴〷〰挴晦㐲挲㔱捡㈱㥦㑥晡㠷昰慣摦㐰昰㘱〰挸㈷㥤㌲㈷ㄲ㔵戴愱㜶㘲㐷戲摤㄰散㘴㘵ㄴ㠷愲㠸㤶㜱搳捥ㅣ戲ㄵ愲㈳慢㜳㜷攸摡扣搲戱ㅦ敢㑥㥢挹攵㤰㈲㌳㥡㈶搷扡㑤搳攴㐶戰㘹㡦㝡敢㈶㜴搵挷〹㍥〲㔰搶㙦㈶㠴㜲愱挱扢㌳㡢㥥㈶攵〷挲㉣ち㡤愱ㅥㄵ㝣㐴挸㍣〲㘴〸戹㡥攳换㥥つ㑤㜳㜰挲晣挰摢搰〷扢昳㜷㠴昴㌶扤戹愷㜷攸㉦㝡㠷㔶昴㉤㘰㉦昱㕦㕤㜵捣慤愸搶㍦㐶㜰ㅢ㐰㥢㡥攱改晢㥤㝡ち㤴㔹㙣㈷㌰户㥦㕥ㄷ㘵攵慥㙣慥㑢愵㠱〶捤ㄵ挳扢㈰〳㜸㌰收攷㘰ぢ扢㥥㈷敢㌸搴搶㔴〱捦㉦搷愶ぢ晤攳㥥㙢戳㝣捦㐶昶㍦㄰㡡㈱㥦搷晡㜲㙤㌶㜲㠶慤㤹昰㌹㈵㈸㠷㍡昸敥敥㐲㈲搱㈹㑤㕥散㤷㝤扥摣㤳㈴㍤㐸㤲㍢戰慤晡㥤〰㤰ㄲ攲愷㕤㈵捡㐱㌶晢〳搵㉣㙤戱搲挳㤷㜱㍡㘹昳㈱㜶挸㤱㠱搰㘱㍢〳晦㠱㍦㘴㉦㕢㜶㔳㔸っ搸㑢搲慢挲户㘰搵㘵㌹㜴换㔲搴散挹㡡て㠸慣攸敢敢㌸㑦㘷昸搷ㄴ㥤戴㐹㠹㑣㙥捦慣捣㌸㡢户㠸㡡㙥㐸ち㤵っ搷㔰㔳〲㤱昲搸㜶㑦挴昴㈰㘲敥挲挶改㠷〸愶〸づ〳ㄴ㝥〲㐹戳搳㡤㘷㌸慣㝦㠳㉥敤㑡㈵㔷㈲ㅡ㤴㡢昰戵慥挲敡〸㕦昳㠷〴昷〲戴㤹㍦㜴㐰㘶㄰愲㐲㜹㠲㄰㔵ㄸ挳㍣㘷挹㑢愴㠱㝤㈶〲㑢戳つ㍦㜰㙤㐶㤶㠶捣㌹昷戴ㅢ捣㔹晥㍡㈲㔱愳㘶㤴㜹㘸㑤㍡愰㉥て戶㑦㕢㤹扢扥㉥㙢扡戹散㌶㈰摡收攷㜶挳挱ㅣ摢〱㕢㔲㥤捤㌵㠱搴摢昹ㄸ㐳〸散戴昲户搲ㅢ扢㈳敦㌷て㝤挳慤ㅤ㕤戱㠲扡ㅣ㌰㐳愶㘳扥㘴㘲ㄷㄱ㌹愸昵㥢㉢㙢㥥㤴㜳㐳收〹捦慡搵㉤㐷ㄲㄹ戰㌱ㄹ慣㕢㤰ㄷ㄰㈵㔸㜲ㄹ〳㜴㥤㈱㜳挵㌳ㅣ㝦摤㘰㐰㜱㜳㝦敡㐹㠵㐵ち收㡣攵昸㜸㡤挲㈲昳挳收昲㥡㝢〹ㄱ摢㠶敤㥣㌰搶晤㕤㠱ㄵㄲ㝤㤸ㄴ㙡㠴㈶㌴㑤㤴戴㔲慦昸攱㠱㍣㤷㈳敦攵〹ㄴ慥㜲〵晡捣㌳戴㌷敤晡㈸㐶㐳㍢㥤㜳ㅡ㐴昴愸㔹搸㤷㈹㠵挹愹晡㝤散昳〹㠰〷㑥㥣㥤㙦㐵收摥㔵捣扡㐰㉦㝦㠶㡣㔷㘴搱っ㠴搰㐷户㉦㈴ㄵ㤶㤱㜲挰㠱挰㌸㥦摡挹慦㙣慡㌶愴扥㝤慤散㜱㐴㤲〶捤〵㘳㔵搶ㄱ㡦戶㡤㘰㕦昸㐰㌳搶㌶敡㝥㔴㌷敢摡戶㐱搲㈲㔹㉥㔷つ㔲昰㜴㈳㜰㑦㔹㡥㙥〲㈸晡㡢㡡㡣换㈸㌲㉥慢愲㐱昳っ㐳㠳㉡捦戱摣ぢ㠶㘷〵㙢戶㔵㉤昱㠱攱扢㕤㐱㤳㘰㜲㑡摥㌸挵㌲㘳扣捤㥡㍦ぢ㤳捤㥦〴扡㈷㈱㐷戹㜵㐴㍦㈸㔷ㄳ㐵晣ㄳ㍤㍡㤶㈰㘰㤴愷㔴晦㘳㡣㔶㔰户㈳㈰㜲㔴扡ㄲ摦挱戸昲㈴㑡㐲㈱㐴慣㘷㤰〸扣㠲〹㈱㑦ㄷ㜷搱㍣敢㔸〱戰㐷㡣ㅤ户㠲㌹ㅦ㈸〷㐰㔶ㅤ㙦慦㔷㔸㑤㜴㥡㘸㙡㠵㥢㍡慢㔲㙡攲挶捥晡愴摥昸攸ㄶ搵愱㐶㐹㈸㤲敤ㅡ㈹捤戲挵ㅣ㜷㤳慡ㄱ㑡㜱挷摡㐶㘴戹㑤㕢晢㑥㈹昲㉥ㄴ㤳愲㤹㥣晥㈷㡡㔰㄰攸㡤㜴ㄴ㝤昶搹攴㤱㠸搸搰〶㈸㔳㑦㠵㘵㐳㔱㐸㜰ㅥ搷㑥㙡戲ㅣ㍤㠱扦昷㐵搹挵㐶㤰慡㌱㉥㡦㐶㌵搳昵晡愲〳㉢愱㙡㜸戵㕤挲搲㔸㕢愸㘱ㄴ㜷昶慡晤挳敤㑤㌰㘲挴㠶っ㡢㘴昸㠱挱㠶㘰慥㐴㐴㤵搶搹㄰户扡㔹㕣攲搳㈹㘹㌸ち〳换㐱㙤㑥㙥㈸㌳慣㘵挹㡦慡づ捤搳愲㤲愳扡㌹扤敡㐳愵〷㤴攳㔱㑥㌱戸㙥㥥愱㕢ち㤷ㄸ㈰㜶愳摣㔲㌵㐰㘸户㌹〰㑦〶扢〷㍢搸㤱㌰㜴㐲敢㡣ㄲ戴㤸㐱戸改㐵㤰㜷㝡挴㈸〴愹愹搲慦㡦㠹慦㍥挷昴捦挷㜲㜱㈶㘲㈲㠶扢㌲慣〷㈰㌷ㄹ㤹㈴ㄷ㡤挶〱昳㔰戲㈹愱㌵ㄸ㤷搱挴ㄸ愲挹攷〵戸挵挳㔸搶㌰搹愶㡥㝢㙥㠱〵㙤㕡摦摣㘷捥㍢搵㝡愳㈶㤵㉡㡥㘵戵搲挸扢〲㕦敡ち㘰挸㑤ㄹ晢ㄲ㙤捡㍣㡥㔲㕣㌲㤱搴扢摤慤ㅦ㐳㜷㈵攴㌰㐶愸晡ㄸ㠰捣㜰换愹㠰㔸挷㍤〵摡㠷晢㕢ㄷㄸ搴攵㌹㠸戴㡥㈲捡戲〵摣挷㙢㐶㤱ㄵ户㈵㥡㉤戸ぢ㉥㙤昶㐴搱㐹㉢㉣摡ㄵ㌸挲㍡㐳㠱㔷㉣挲ㄸ改㤱㍢㌸㐸敥㑡ㄴ摤扤昲愴㝡捣㕤〱㉡ㄴ〶〴㘳扣㍣〵攵戰慢㘰㈴ㅡ摣㕡换敡ㄶ㡣晥搲昲搶愷〱〴挳挰㌴㘸搱㌲㌴㜰㘶㤱摦摥挰戹〹慤㌲㈲愴挹㘰㉡㘳㤴愳㜰搸〳㘹攰㈶ㅥ愴㔷㕣㈸愱㘰㑣㕤っ㡢敦㈶㑥搸㌸〲戹摥㌵㙤㠵㑢㐶㠰敢㉦捥㠱戶攲改㕡㡤收㉥晣㜳扢〲慢戸扡ㄱ㥡愳㘳㙤㤷戲搴㥡㘸摦摤搲㔶ㄱ㕤ㄶ㍣㍣㌷㜹搲〸慡㙢换挱㘶㜸㜱慢㔷㤲㈸扣ち㝦挴㤶㙦愷捤㥣㜷㜸ㄱ㜵㠳㝢㕦扥攸戸㤷ㅣ㌵慦㠲捦㕢㝦愰㄰㕣愱散攷㈴换戹摦攲㥦㑡㕡慥昰㝤㡣戸㤳㘹㜳㠰㤶㠳㠴攳愸ㄴ㑡㠳㜱攴㌳攸〴戶㝢昳搶〰改㘴慣㡤㑥㤴㈰搸㈳ㄴ攷挲㝢㐶㈸攲㝢㐰㉢㠹㈵㍣㤲㘳捦扦〵搶ㄷ慦愰㠴〸挷㜳㈴㐶ちㅦ㐱㉥〳㜵㑡㤰㐷㔷㍣㜸㈱攴晦て㤶㘲㙥摥㤲㥤㝥て捣㉣㕥㙥㐷搱㡤㐴搱㑢ㅤ㈸ㄲ扣〶愲昸昷〱㘴攲㔴㘰㜸昶ㅤ〵挲戹愶扤〳攸晢㝥攱昷晦昰〰扡㄰ㄱ㠷戲搱㄰㙡扢ㄵ捦㑤ㄳ愱慦挳㐴㘰昰㕥㤹〸愷㤰ㄱ㡣攲㠷㈶㐲攴〳㔹㐴挱昶㈶〲㘳㝢ㄹ㠶㘰㈲搴㥡㜰㙢昰〴㜶㡤㑤晦搸㐹㕣扣㤵㍥攲昹㔰㕡晥㉣㍣㔲搷㜶ㄶ㉦ㄹ㥥㘱ㅦ㔰攵㈷㍣〹㘵收慤攰㈶户敡挲ㅥ搷㙦㔹愳㍡㙤攱慢㠸扤散㝢晥㤴㥤摤㕦〷愶挲ㄴ扡敦㐵㐹ㄴ摦㠵愷㐴昰摣㤰晢昳戱㙦㥦昸敦挷㥦㍥挶摢㙡ㄱ慤ㄶ敥㐴扥㤷㤰㍤敤〹〴㜵ㄳㄷ㐵慥收㠷㌹愷昰㠹㤲戵㕥㤷㌳㠶愷慣㈰㕦户攳㙣㐸㜸〹挲っ㠹㙦㌷㤸㤸戸昷㄰㥡㤸㤳㙤敥㑥昵㘱㤳㜲ㄱ㑥㈶㈶慥㝣㝡㜱搸㔰㜴㔵㘴㍤㕡㥢㠵㝦㠱㉡㝡㠷ㄳ㐹㕢㠹㍣㜵㌲〹昱㥤㜶㕤㜷㠴扡㉥㍣挸㌰散ㅦ㑢㈹挴ㅦ㐸㈱挹㠳っ㉦〴㈸㈹㜵〶㤹挲㕤〰ㄹ㤱戵昶㄰㉦晤〱㝢㐲㐰㌶㉦晤昵昸ㄱぢ㜶ㄱ㔸㡣㝤昱扤㥥㘸㘹㡢挶慡㠹愱㕡㘵搳㉣㈳愳づ㉦㉣㤸㡡㑢㔳㤶捥㘱㤴敥搸ㅤ挵㤷っ搹㘱攰㉤㘴散㠲㑤㕦㕢搹扥摦㘹攰收〷昴㑣㔱㈹っ㘷㍦㡢㜱㈰㔵㌱扡戰㘹㌹㉣㈲ㅣづ戳捤㑥〳㔱ㄵ㜴㤶㜳〰愷㔲〴晦昸愵㄰敢㈷㕡㐳㕦摤㕥㐳ㅤ攷昴㘳㠱晣挱晥扡㌱㠳戱昱㔶㜲っ㈴散㡥㕡㤵挲敢攱㘷搱㠵㡢捥〹扤㤵㔵捦攲〸晥挴㥣搵愷㜵攸㝦㐶慦ㄵ㘷㥤㘳㙦㠶戱㔳晡晦㔳㈸搸㔶晦ぢ挶摥ㄴ㈲㍦ㅤ㘵昸㔰㘰晣㘴摢㤰つ㜷〴㥥㙤〴㙦搴挱㔸㔷㔹㠶扣挳摣㌲㍥㕥つ慢㤵〴㠷摦㉢摦㝥㌵愲搹㤷戶敤㐰㔷〱挸搸㔰攱㕢㄰㐱㕤晢愷攵㔶㝣扡㉤㍥㡣㡥㘳愷慣慡攷晡慥ㄹ㡣㉦㈳攸㍢捥㙦捦㑣搸㍣搳攲㥦摡㠵摡㉤搸㠹挱㐷搰攷昴㈲〴昶㘹ㄹ扣㔷戱㐸㐶ㄶ㜶ㄶ挹攰㜷㐸㈳㠹昰ㄲ戵㠳㝦㤵昹㘰挳愸攳搳搵㐵昸㍡〳ㄶ敤ち㘵ㄷ㝡㥣摢㙦㘸㜰敢㜰㐷敢㤳昰〷挹晡㈴㠲㘳㙡〹て㍦挲㝤㙤摦㠳㜴摢㘸㙤㍥㕢昶收㜳㉢ㄷ㕥〰㑥㜷昶㤶㌴挹昰㥤晣㈲戹慣㔷〸㜱㘹晦ㄸ晥敥摣㐱换搱㐶㐱攷搱〷摤㜴㠴㑤搴攱㍥摢㐱昴晢㍣扡㡡㘹〲晣㜴㈳捡昰㐱搰换㐷㔶ㄴ摦挰戲挸〰挸攷㡡㔵㠰敥㔴晤晣㔶㔴㍤ㄲぢ㘴挱㌳〶挹戱㉣扥㠶㠶摣慥㜰搹㘰〹㉥㕢愸戳〴昲㝡摣〳昹㥣攰㔹㐲㑤攴㉢攸搰㥣㠸㠵搲敥ㄳ昹昲㔶ㄳㄱ戴〲搴㐲㤳攳㡦挴㕡㐴慦愳㕡户〹ㅣ〲ㄷ㘰㤸㘲㤱戲愶ㄸ㠶ㄶ㕥㈱㘶㤰晥㌳晡晢挶戱㥦扣挶昴慢㘳㐲〹㐲㔴愵㈷㑦㐱愸㈶晦㠵攴攴㍤㤴㜶㥦晣攷戶㥡晣〸㘵㈴㘷愲〷〰㐳㝤愲㠲㍦㙡㌱つ㘴戸㡦晣㠹昳〴昸愵㘶㌱㘲愰㐴昵扤㠴っ晡㜲挳㔵慢换挸挴㝤ぢ㕣㝦挶挷㍤捡㍥攲㐵㐸晡㜲㡡愱㌳戶ㄸ㙡挵㤲ㅤ㜹㘱㜷㠵㙣挰㤲昸戵㙣㔷㤱㕥散㌱挲㉦㍥ㅢ㈳收攴挹昸换㈹㉤㡡㌹㠱㌰㐲㡢㤴昴挳㡤ㄴ㝦ㄹ㌷晥搷ㄷ㕢㉥㔳㔴㈰㠱㝡挲挶愴㌳搵昸㤹戸昱㘱㝣㤵愵摡攴㜸㠳㠰改㡤戸㌱改㔱㌵㝥㍡㙥晣换挳〷㥡㡤㘳㍡っ㐷㉥㤰㐸㌲㙣㕤㘵晤㈷扥搰ㅥ㐶昳㠲㐹晤㌹㘰㠶挵㤴㥣㉡㜴㕣㔷ㅡ㜴㄰㤷㐱㍣㝣㈳扤㠰扢㑤戸〲〲㈱ㅢ晥慦ㄲ收㜱攷㘹捥〸っ㝣〲扤㠱㘰戳愷慢㈷㜶㉥㥡㡢ㅥち晡捤㜹ㅦ㘷慡摡慥㈲ㄱ㤸〳昹㜰㝦户㜱捡㘷㤸㡥慤晤㠸㠳㘴ㅡ敦㤰昴愶㍣㔴㘰㈵㉦㍥ㄳ㘳㌶昷㔴㡢㘶昴㈷㠱ㅣ㐸㐷㐰㘶昴愷〰挳㐰っ㙦㉢攷㐶挸晦㡡戹㍦挳㡡扦㈰㜸ㅡ愰㉣挸散愴㠳攲㌳〰㘳戰㔲昱扦慡昰挷㙢㜲㝣摤㤳ㅢ㤶晦愳㝦㜴㌵昱㜸晣挶㈴㉤改㥦㘵慦扦〲攸㠳て㔷㐴㤴㔸搶晦ㅡ㈵挹㌷㔳㝡愸㌷晦つ㉢晥㤶攰㜳〰攵〲㘷扣攳慤攳挲㝡㔴㕦㥦㐷㔷昱ㄴ〱㝥晡ㄷ愲っㅦち摣㡣㍦敡㙥㌰昳㍣ㅣ㝦摤㡦㜸㘷敡㌳晥晢昱㔹晥㈶ㄷ摤㠷晦㉢㐹㐱㔹昷㜹敤ㄳ扤㡤㐵㑥愰㘱慥㝥敢搸散㜷㌱づ搷搵ち愳㜰㐴㙡㤶㤲㔶ㄴ㐴㍡ㄷ㉣㕣扣㠱㙦㌹慡㉡㠴㈰㈱愸ち㈷慡㌸㠶〲晤敦搸㤴㌸㈶㥥昴扦攷ㄳ㔱慢㌶昱㑢㔱㠶て㠲㜸㔵摤ㅦ㡤扡挷㉦㈴慥㔵㠵搵昶㐲攲㕦㔵慣㈵㕦昸ㅣ〷㔳挸㐲㈶慤㥡㠸㌴㐵㐳㕦㐳㘶愸㙦㤸㜳㝢〸㍦敤戲愸㥥慦㥤㍦晦搶㜰㝥晣晡晣愷晥㜴昰戹㌷晥攳捤㘷㕦晦戳愳㍦㝦晢昹攷㕦晦㥦㘷㕦㝢晢搵搵愳晦晥挲ぢ晦昶挰㍦扣昶收㝥昳㥢摡㡢㙦㉤㝣昳㠹愹㡢㑦㍣㘶㥥扤昳挴ㄳ㥦㝥昴挱愹愵慢㈶晡晡晡晢㙦ㅢ晤昱㜵户㡦㍣昵搸换攲〷㍦扢搶ㄱ㙡戹㜸㐱㝡ㅡ㕣戶㥡挶搷㤱挱㌴㌸攳昷㜵ㅡ㕣慥摡愸搵㘸愳㘶㔰㔰㠲㘳㠳ㄳ㔰ㄵ㐶扡㘲攰㜷㝤ㅢ戵㔴 | E30: 㜸〱敤㕣㕢㙣ㅣ㔷ㄹ摥㌳摥㕤敦慣敤搸㡤搳㑢㑡㘹つ愵㤴搶挱㡤搳㠶㔲㈰〴㕦㥡㑢㜱㘲㌷㜶㔲㄰愰捤㜸昷㑣㍣捤捥㡣㍢㌳敢挴愵㔲慢㔲㙥攲㔲愹㕣㐴㘹戹愸㈰㈴㕥戸㍣〰攵昲㠲〰㠱㔰㤰㄰㠲〷㄰て〵㈱㜸〰愱㐸扣昰㠰〴摦㜷㘶㘶㜷㘶搷㍢㜶户㉤戸挸㈷摤摦㘷捥㙤捥㌹晦昵晣晦㤹收㐴㉥㤷晢㌷ㄲ晦㌲攵㤹戹㙥㜱摤て愴㍤㌱攳搶敢戲ㅡ㔸慥攳㑦㑣㜹㥥戱㍥㘷昹㐱ㅦㅡㄴ㉢ㄶ敡晤㐲挵户ㅥ㤴愵捡㥡昴㝣㌴㉡攴㜲愵㤲慥愱㥥㠳昰㌷ㄲ㍦攸散㌵㤸〷㔸㥡㤹㥥㕦扥ㅦ愳㉥〶慥㈷昷㡤㥤〹晢ㅥ㥡㥣㥣㤸㥣㌸戸晦捥〳ㄳ晢昷㡤捤㌴敡㐱挳㤳㠷ㅣ搹〸㍣愳扥㙦㙣愱戱㕣户慡㙦㤷敢㑢敥㜹改ㅣ㤲换晢㙦㕦㌶敥㜸攳攴ㅤ〷て㥡㜷摤昵挶㐱扣㍡㜷㜲㘶㝡挱㤳愶晦㈲㡤㔹攰㤴敦㤸㤵㔵㡢㙢㤳搲戳㥣㜳ㄳ㌳搳昸㉦㌱㝦㍣摤㌹戱戸㈲㘵挰㔷㑢㑦㍡㔵改敢攸㌸㘰㑦昹㝥挳㕥攵收改昶ㄱ㉣戵㙡昸㐱挱㥥㤱昵扡㙥挷愳㤶散㜹散㕤摤㔸ㅦ戴ㄷ愵攳㕢㠱戵㘶〵敢㐵㝢〹〳搵㠶散搳扥㍣㘵㌸攷攴㐹挳㤶〵晢㘸挳慡攵挳㤴敢扢㌹ㅥ㈲㌹㌱戵晣㠹㈹摦㥥㔹㌱㍣㌵㈳㥦ㅢ㤳搱昶㠸㔷㑤户扤戱晢戸㥣扡㝡〳挷扣愹㝢㍢搴㥣㌱扣㘶换昱敥㉤愳挵愷㘷㜰㕢昷昶㠹㍤㑡昷戹愵㝢ㅦ戵㤵改搶㘲㈰愲㙦戵愳㔸㡣㕥㈴攸㈷㈸ㄱ㄰㠱㝡㤹㘰㠰㘰㄰㐰攴晦〱㉥㐹㜶㘴㤵㔶㌱戴捡戲㔶愹㙡㤵㥡㔶㤱㕡挵搴㉡攷戴捡㡡㔶戱戴捡晤㕡攵㍣摡挴愹搴摦慦㐵改愹慦㝢㡦〶㤷㝥㌷晢㙣昱㔷摦扡攵㡥敦晦㘴㜰ㄷㅡ摤ㅢ㑤㙡搶㌳㉥㠰搴㕡㔴っ㡥攰扦捤戹〲㑣㘱ㅥ㌴敦㌴㈷㈷㙢〷昷ㅢ户ㅢ〵㉥㉢〳昹㈹㐲ㄹ㐱摢㐱昳㍥换愹戹ㄷㄴ敥慥㥢㌶㝣搹摡戸昱愸㙥摡㙤㌸㌵晦ㄵㅢ㔷㉥〶㐶㈰慦㙤慦㙢つ搲搱㙤ㄱ㙣㈵㝤昵扥敢摢扢㥤㌱敡つ㌹㜵搱ち慢㕦搹㔶㙤㉦㜸敥㜲昷摡㈳㥥㝣愰㔹摢㌱愳㈹〸戵㌵㌵㜶挷㉡挳慡㜰㕥㘳㌳㉢慥㉦ㅤ㌵扤㜱㝢挱慡㥥㤷摥愲愴㐸㤴㌵戵搴㉢㔹ㄵ㜱晤昸扣㠳㠵㠲㕢㙢慦㑥㤶㥡㜷㕦っ挰捣戲㠶昹慥㑡㉦㔸㕦㌲㤶敢昲慡㔴㤳昰㥤愸搸㥢㉡㍥攲㔶ㅢ晥㡣敢〴㥥㕢㑦搷㑣搵搶っ㐸㥡摡〹户㈶昳昹㥣ㄲち㄰戸㝤㝤㐲攴㙥敤捥ぢちㄱ〹ㄴ㤳㤱慦㐹㤳摤挴㈹慣づ慢愸㑢搲愴昶㥡㑤〶攳㝣㤵㡣挹攰挰挴㥡愸㍦昸搲搷㙤㌲㙣ㄳ㜳㉦㙤㘳㑤ㅢ㡤㔶㝦昷㥡㜴㠲㘳㠶㔳慢㑢㉦㔳晢〹捥㐸ㅦ〶㈸㕣㠶㐰攸扡㝢㔴㜵攲愲㔸㉦㕣戰㙡挱㑡㜱㐵㕡攷㔶〲㤴㐱㐳㤶㑡摣摡㡥愴㕦㠱㈲㝤㌷挱㈸㐰戹㥣㉢敥㘱愳㘲ㄹ㈹㔷愰㜴捡攰攵㤴㈰㘷扦ㄴ㉦て㥡㐷慣㝡㈰㐳愱㍣㙣〲㈳愱㔶㔳攸ㅢ㈲㠹㝡㐶㌵㔴ㄸ㝢捣ㄹ㔰愹㘱㌹挱㝡㡢㙦㍢戸㈴㈴愲ㅤ㔹戰敤㘴〱㐵㐱㕡ㅥ㘴昰ㅡ㠸愶㑤ㅡ㘴㌷㑥㄰ㄱ搹㈰㐳戳㘳攴㌴㤱戱㝤㠶㡣㐰晢㈴ㄱ戲昵晥敥㌲㠲挴摥㐹愴散搴㤵ㅦ㜷愴搹㐶戶㝣㈸捤慥挴挶改㔷ㄱ㕣㑤㜰つ挱㕥〰昱㘷㐸㌸㑡㌹攴搳㐹㝦〵㥥昵敢〸㕥〹〰昹愴㔳收㐴愲㡡㌶搴㔶散㐸戶ㅢ㠲㥤慣㡣攲㔰ㄴ搱㌲㙥摡㤹㐳戶㐲㜴㘴㜵㙥て㕤㥢㔷㍡昶戵摤㘹㌳戹ㅣ㔲㘴㐶搳攴㕡㌷㘹㥡摣〸㌶敤㔱㙦摤㠰慥晡ㄸ挱慢〰捡晡慢〹愱㕣㘸昰㙥捤愲愷㐹昹戲㌰㡢㐲㘳愸㐷〵ㅦㄱ㌲㡦〰ㄹ㐲慥攳昸戲㘳㐳搳ㅣㅣ㌷㕦昶㌶昴扥敥晣ㅤ㈱扤㑤㙦敥攸ㅤ晡㡢㥥愷ㄵ㝤㈳搸㑢晣扥慢㡥戹〹搵晡㙢〹㙥〶㘸搳㌱㍣㝤㍦㕦㑦㠱㌲㡢敤〴收㜶搳敢愲慣摣愵昵㔵愹㌴搰愰戹㘴㜸攷㘴〰て挶昱㔹搸挲慥攷挹㍡づ戵㌵㔵挰昳换搵改㐲晦㠸攷摡㉣摦戱㤱晤㤷㠵㘲挸攷戵扥㕣㥢㡤㥣㘱㙢㈶㝣㑥〹捡愱づ扥扤扢㤰㐸㜴㑡㤳ㄷ晢㘵㥦㉦㜷㈴㐹て㤲攴ㄶ㙣慢㝥㉢〰愴㠴昸㑤㔷㠹戲㡦捤㕥慦㥡愵㉤㔶㝡昸㌲㑥㈷㙤㍥挴づ㌹㌲㄰㍡㙣愷攱㍦昰㠷散㐵换㙥ち㡢〱㝢㐱㝡㔵昸ㄶ慣扡㉣㠷㙥㔹㡡㥡ㅤ㔹昱㌲㤱ㄵ㝤㝤ㅤ攷改っ晦㥡愲㤳㌶㈹㤱挹敤㤹㤵ㄹ㘷昱ㄶ㔱搱つ㐹愱㤲攱ㅡ㙡㑡㈰㔲ㅥ摢敥㠸㤸ㅥ㐴捣㙤搸㌸㝤㍦挱㈴挱〱㠰挲㉦㈰㘹戶扡昱っ㠷昵慦搱愵㕤愹攴㑡㐴㠳㜲ㄱ㕥敡㉡慣づ昲㌵㙦㈰戸ㄳ愰捤晣愱〳㌲㠳㄰ㄵ捡ㄳ㠴愸挲ㄸ收ㄹ㑢㕥㈰つ散㌲ㄱ㔸㥡㘹昸㠱㙢㌳戲㌴㘴捥扡㈷摤㘰搶昲㔷ㄱ㠹ㅡ㌵愳捣㝤㉢搲〱㜵㜹戰㝤摡捡摣搵㔵㔹搳捤㐵户〱搱㜶㝣㜶㍢ㅣ捣戱ㅤ戰㈵搵搹㕣ㄳ㐸扤㥤㡦㌱㠴挰㑥㉢㝦㉢扤戱㕢昲㝥昳搰㌷摣摡搱㈵㉢愸换〱㌳㘴㍡收㑢㈶㜶ㄱ㤱㠳㕡扦戹戴攲㐹㌹㍢㘴ㅥ昵慣㕡摤㜲㈴㤱〱ㅢ㤳挱扡㌹㜹づ㔱㠲〵㤷㌱㐰搷ㄹ㌲㤷㍣挳昱㔷つ〶ㄴ搷㜷愷㥥㔴㔸愴㘰㑥㕢㡥㡦搷㈸㉣㌲㍦㙣㉥慥戸ㄷ㄰戱㙤搸捥㔱㘳搵摦ㄶ㔸㈱搱㠷㐹愱㐶㘸㐲搳㐴㐹㉢昵㡡ㅦㅥ挸㜳㌹昲㕥㥥㐰攱㉡㔷愰捦㍣㐳㝢搳慥㡦㘲㌴戴搳㌹愷㐱㐴㡦㥡㠵㝤㤹㔲㤸㥣慡摦挵㍥㙦〲戸攷攸改攳慤挸摣ぢ㡡㔹ㄷ攸攵捦㤰昱㡡㉣㥡㠱㄰晡攸㜶㠵愴挲㌲㔲づ㌸㄰ㄸ攷㔳㍢昹㤵㑤搵㠶搴户慢㤵㍤㠲㐸搲愰㌹㘷㉣换㍡攲搱戶ㄱ散ちㅦ㘸挶摡㐶摤㡦敡㘶㕣摢㌶㐸㕡㈴换挵慡㐱ち㥥㙡〴敥〹换搱㑤〰㐵㝦㔱㤱㜱ㄱ㐵挶㐵㔵㌴㘸㥥㘲㘸㔰攵㌹㤶㝢捥昰慣㘰挵戶慡㈵㍥㌰㝣户㉤㘸ㄲ㑣㑥挹ㅢ愷㔸㘶㡣戵㔹昳愷㘱戲昹ㄳ㐰昷〴攴㈸户㡥攸〷攵㙡愲㠸㝦愲㐷挷ㄲ〴㡣昲㤴敡㙦挱㘸〵㜵㍢〲㈲㐷愵换昱ㅤ㡣换て愳㈴ㄴ㐲挴㝡〶㠹挰㉢㤸㄰昲㜴㜱ㄷ捤搳㡥ㄵ〰㝢挴搸ㄱ㉢㤸昵㠱㜲〰㘴搵昱昶㕡㠵搵㐴愷昱愶㔶戸愱戳㉡愵㈶慥敦慣㑦敡㡤搷㙣㔰ㅤ㙡㤴㠴㈲搹慣㤱搲㉣ㅢ捣㜱㍢愹ㅡ愱ㄴ㜷慣㙤㐴㤶摢戴戵敦㤴㈲㉦㐰㌱㈹㥡挹改㙦㔵㠴㠲㐰㙦愴愳攸戳捦㈶㡦㐴挴㠶㌶㐰㤹㝡㉡㉣ㅢ㡡㐲㠲挷㜱敤愴㈶换搱ㄳ昸㝢㔷㤴㥤㙦〴愹ㅡ攳攲㘸㔴㌳㔵慦捦㍢戰ㄲ慡㠶㔷摢㈶㉣㡤戵㠵ㅡ㐶㜱㘷慦摡㍦摣摥〴㈳㐶㙣挸戰㐸㠶ㅦㄸ㙣〸收㑡㐴㔴㘹㥤つ㜱慢㥢挵㈵㍥㥤㤰㠶愳㌰戰ㄸ搴㘶攵㥡㌲挳㕡㤶晣愸敡搰㍣㉤㉡㌹慡㥢㔳换㍥㔴㝡㐰㌹ㅥ攵ㄴ㠳敢收㈹扡愵㜰㠹〱㘲㌷捡㉤㔴〳㠴㜶㥢〳昰㘴戰㝤戰㠳ㅤ〹㐳㈷戴捥㈸㐱㡢ㄹ㠴㥢㕥〴㜹愷㐷㡣㐲㤰㥡㉡晤晤戰昸散㤳㑣㕦㍤㥣㡢㌳ㄱㄳ㌱摣㤵㘱㍤〰戹挹挸㈴戹㘸㌴づ㤸㠷㤲㑤〹慤挱戸㡣㈶挶㄰㑤㍥㉦挰㉤ㅥ挶戲㠶挹㌶㜵摣㜳ぢ㉣㘸搳晡晡㉥昳戸㔳慤㌷㙡㔲愹攲㔸㔶㉢㡤扣㉤昰愵慥〰㠶摣㤴戱㉦搱愶ㅣ挷㔱㡡㑢㈶㤲㝡户扢昵挳攸慥㠴ㅣ挶〸㔵ㅦ〳㤰ㄹ㙥㌹ㄵ㄰敢戸愷㐰晢㜰㜷敢〲㠳扡㍣〷㤱搶㔱㐴㔹㌶㠷晢㜸捤㈸戲攲戶㐴戳㌹㜷捥愵捤㥥㈸㍡㘶㠵㐵摢〲㐷㔸㘷㈸昰㡡㐵ㄸ㈳㍤㜲〷〷挹㕤㡥愲扢㤷ㅦ㔶㡦戹换㐰㠵挲㠰㘰㡣㤷愷愰ㅣ㜶ㄵ㡣㐴㠳㕢㙢㔹摤㠲搱㕦㕡摥晡ㄴ㠰㘰ㄸ㤸〶㉤㕡㠶〶捥っ昲㥢ㅢ㌸㌷愰㔵㐶㠴㌴ㄹ㑣㘵㡣㜲ㄴづ㝢㈰つ摣挴㠳昴㤲ぢ㈵ㄴ散㔱ㄷ挳攲扢㠹攳㌶㡥㐰慥㜷㔵㕢攱㠲ㄱ攰晡㡢戳户慤㜸慡㔶愳戹ぢ晦摣戶挰㉡慥㙥㠴收攸㥥戶㑢㔹㙡㑤戴敦㙥㙣慢㠸㉥ぢㅥ㤸㥤㌸㘶〴搵㤵挵㘰㍤扣戸搵㉢㐹ㄴ㝥〰㝦挴㠶㙦愷捤㥣㜷㜸ㄱ㜵㡤㝢㕦㍥敦戸ㄷㅣ㌵慦㠲捦㕢㝦愰㄰㕣愱散攷㈴换戹㝦攳㥦㑡㕡慥昰㝤㡣戸㤵㘹㜳㠰㤶㠳㠴攳愸ㄴ㑡㠳㌱攴㌳攸〴戶㝢昳搶〰改㘴㑦ㅢ㥤㈸㐱戰㐳㈸捥戹ㄷ㡤㔰挴昷㠰㔶ㄲ㑢㜸㈴挷㥥㝦〵慣㉦扥㡢ㄲ㈲ㅣ捦㤱ㄸ㈹扣ち戹っ搴㈹㐱ㅥ㕤昱攰㠵㤰晦ㅦ㉣挵摣扣㈱㍢晤ㄷ㤸㔹㍣摢㡥愲敢㠹愲敦㜴愰㐸昰ㅡ㠸攲摦㝢㤰㠹㔳㠱攱搹攷ㄵ〸攷㥡㜶づ愰㉦昹㠵摦晦攱〱㜴㉥㈲づ㘵愳㈱搴㜶ㄳ㥥㥢㈶㐲㕦㠷㠹挰攰扤㌲ㄱ㑥㈰㈳ㄸ挵て㑤㠴挸〷㌲㡦㠲捤㑤〴挶昶㌲っ挱㐴愸㌵攱搶攰〹散㉡㥢晥戱㘳戸㜸㉢㝤挴昳愱戴晣ㄹ㜸愴慥敥㉣㕥㌰㍣挳摥慢捡㡦㝡ㄲ捡捣㕢挲㑤㙥搵㠵㍤慥摤戰㐶㜵摡挰㔷ㄱ㝢搹㜷晣㈹㕢扢扦づ㑣㠵㈹㜴摦㡢㤲㈸扥〰㑦㠹攰戹㈱昷摥㍤㕦㍢晡㠷〷ㅦ㍢捣摢㙡ㄱ慤ㄶ㙥㐵扥㤷㤰㍤敤〹〴㜵ㄳㄷ㐵慥攴㠷㌹㈷昰㠹㤲戵㕡㤷搳㠶愷慣㈰㕦户攳㙣㐸㜸〹挲っ㠹㙦㍢㤸㤸戸昷㄰㥡㤸ㄳ㙤敥㑥昵㘱㤳㜲ㄱ㑥㈴㈶慥㝣㝡㜱搸㔰㜴㔵㘴㍤㕡㥢㠵㙦㐰ㄵ㍤捦㠹愴慤㐴㥥㍡㤹㠴昸㝡扢慥㍢㐸㕤ㄷㅥ㘴ㄸ昶㡦愵ㄴ攲て愴㤰攴㐱㠶ㄷ〲㤴㤴㍡㠵㑣攱㌶㠰㡣挸㕡㝢㠸㤷晥㠰ㅤ㈱㈰㥢㤷晥㝡晣㠸〵扢〸㉣挶扥昸㕥㑦戴戴㐵㘳搵挴㔰慤戲㘹ㄶ㤱㔱㠷ㄷㄶ㑣挶愵㈹㑢攷〰㑡户散㡥攲㑢㠶散㌰昰ㄶ㌲㜶挱愶慦慤㙣摦敤㌴㜰昳〳㝡愶愸ㄴ㠶戳㥢挵㌸㤰慡ㄸ㕤搸戴ㅣㄶㄱづ㠷搹㘶愷㠱愸ち㍡换搹㡢㔳㈹㠲㝦晣㔲㠸昵攳慤愱慦㙣慦愱㡥㜳晡戱㐰晥㘰㝦㕤㥦挱搸㜸㉢㌹〶ㄲ㜶㑢慤㑡攱昵昰搳攸挲㐵攷㠴摥捡慡㘷㜱㄰㝦㘲捥敡搳㍡昴㍦愳搷㡡戳捥戰㌷挳搸㈹晤晦づㄴ㙣慡晦〵㘳㙦ち㤱敦㡣㌲㝣㈸㌰㝥戲㘹挸㠶㍢〲捦㌶㠲㌷敡㘰慣慢㉣㐳摥㘱㙥ㄱㅦ慦㠶搵㑡㠲挳敦㤵㙦扦ㅡ搱散㑢摢㜶愰慢〰㘴㙣愸昰ㄵ㠸愰慥晤搳㜲㉢㍥摤ㄶ摦㠵㡥㝢㑥㔸㔵捦昵㕤㌳ㄸ㕢㐴搰㜷㡣摦㥥㤹戰㜹愶挴㤷摢㠵摡㡤搸㠹挱昷愰捦挹㜹〸散㤳㌲㜸戱㘲㤱㡣㉣㙣㉤㤲挱敦㤰㐶ㄲ攱㈵㙡〷晦ち昳摥㠶㔱挷愷慢昳昰㜵〶㉣摡ㄶ捡㉥昴㌸户摦搰攰搶攱㡥搶摢攱て㤲昵〹〴挷搴ㄲ摥昵ㅥ敥㙢晢ㅥ愴摢㐶㙢昳搹戲㌷㥦㕢戹昰っ㜰扡戵户愴㐹㠶敦攴ㄷ挹㘵扤㐲㠸㑢晢㠷昱㜷敢づ㕡㡥㌶ち㍡㡦㍥攸愶㈳㙣扣づ昷搹ㄶ愲摦㘷搱㔵㑣ㄱ攰愷ㅢ㔱㠶て㠲㕥㍥戲愲昸㍣㤶㐵〶㐰㍥㔷慣〲㜴愷敡愷㌷愲敡㤱㔸㈰ぢ㥥㌱㐸㡥㘵昱ㄴㅡ㜲扢挲㘵㠳㈵戸㙣愱捥ㄲ挸敢㜱て攴㜳㠲㘷〹㌵㤱捦愰㐳㜳㈲ㄶ㑡扢㑦攴搳ㅢ㑤㐴搰ち㔰ぢ㑤㡥㍦ㄲ㙢ㄱ扤㡥㙡摤㈶㜰〸㕣㠰㘱㡡㐵捡㥡㘲ㄸ㕡昸㉥㌱㠳昴换攸敦㜳㠷㝦㜱㠹改㙦㠷㠵ㄲ㠴愸㑡㑦㥥㠲㔰㑤晥昱攴攴㍤㤴㜶㥦晣挷㌶㥡晣〸㘵㈴㘷愲〷〰㐳㝤愲㠲㍦㙡㌱つ㘴戸㡦晣㠹戳〴昸愵㘶㌱㘲愰㐴昵扤㠰っ晡㜲挳㔵慢㡢挸挴㝤ぢ㕣㝦挶挷㍤捡㍥攲㐵㐸晡㜲㡡愱㌳戶ㄸ㙡挵㤲ㅤ㜹㘱户㠵㙣挰㤲昸戵㙣㔷㤱㕥散㌱挲㉦㍥ㄸ㈳收搸戱昸换㈹㉤㡡㌹㠱㌰㐲㡢㤴昴挳㡤ㄴㅦ㠸ㅢ㝦昳摢㉤㤷㈹㉡㤰㐰㍤㘱㘳搲㤹㙡晣晥戸昱〱㝣㤵愵摡攴㜸㠳㠰改戹戸㌱改㔱㌵㝥㉣㙥晣搷〳㝢㥢㡤㘳㍡っ㐷㉥㤰㐸㌲㙣㕤㘵晤㈷扥搰ㅥ㐶昳㠲㐹晤㌹㘰㠶挵㤴㥣㉡㜴㕣㔷ㅡ㜴㄰㤷㐱㍣㝣㈳㍤㠷扢㑤戸〲〲㈱ㅢ晥慦ㄲ㡥攳捥搳慣ㄱㄸ昸〴㝡つ挱㘶㑦㔷㑦散㕣㌴攷㍤ㄴ昴㥢挷㝤㥣愹㙡摢㡡㐴㘰づ攴挳晤摤挴㈹㥦㘱㍡戶昶㈳づ㤲㘹扣㐳搲㥢昲㔰㠱㤵扣㜸㌴挶㙣敥㤱ㄶ捤攸て〳㌹㤰㡥㠰捣攸㡦〰㠶㠱ㄸ摥㔶捥㡤㤰晦ㄵ㜳㍦捡㡡昷ㄱ㍣〶㔰ㄶ㘴㜶搲㐱昱晤〰㝢㘰愵攲㝦㔵攱㡦搵攴搸慡㈷搷㉣晦㐷㕦㜲㌵昱㘰晣挶㈴㉤改ㅦ㘴慦て〱昴挱㠷㉢㈲㑡㉣敢ㅦ㐶㐹昲捤㤴ㅥ敡捤ㅦ㘱挵㐷〹㍥〶㔰㉥㜰挶㕢摥㍡㉥慣㐷昵昵㜱㜴ㄵ㡦㄰攰愷㍦ㅥ㘵昸㔰攰㘶扣戹扢挱捣昳㜰晣㜵㍦攲㥤愹捦昸敦挶㘷昹敢㕣㜴ㅦ晥慦㈴〵㘵摤攷戵㌷昵㌶ㄶ㌹㠱㠶戹晡慤㘲戳㕦挰㌸㕣㔷㉢㡣挲ㄱ愹㔹㑡㕡㔱㄰改㕣戰㜰昱〶扥攵㤰慡㄰㠲㠴愰㉡㥣愸攲㌰ち昴㑦戰㈹㜱㑣㍣改㥦攴ㄳ㔱慢㌶昱㔳㔱㠶て㠲㜸㔵摤敦㡦扡挷㉦㈴慥㔵㠵搵昶㐲攲㕦㔵慣㈴㕦昸㈴〷㔳挸㐲㈶慤㥡㠸㌴㐵㐳㑦㈱㌳搴㌷捣戹摤㠷㥦㜶㔱㔴捦搶捥㥥晤攷㜰㝥散摡晣㍢摥㌶昸攴㜳㍦晦攳ㄳ扦㝥昷愱扦晣敢改愷㝦晤愷㈷㉥晤敢〷换㠷㝥晡捣㌳㍦扥攷ぢ㤷晥戸摢晣愲昶敤㝦捥㝤昱愱挹昳て㍤㘰㥥扥昵攸㐳敦扣晦摥挹㠵㉢挶晢晡晡晢㙦ㅥ晤搹㌵慦ㅢ㜹攴㠱㘷挵て㝦㝢戵㈳搴㜲昱㠲昴㌴戸㙣㌵㡤捦㈱㠳㘹㜰挶㉦改㌴戸㕣戵㔱换搱㐶㑤愳愰〴挷〶㈷愰㉡㡣㜴挵挰㝦〰慥戵戶㙡
A31: Decisioneering:7.0.0.0 | B31: Decisioneering:7.0.0.0 | C31: Decisioneering:7.0.0.0 | D31: Decisioneering:7.0.0.0 | E31: Decisioneering:7.0.0.0
A32: CB_Block_7.3.0.0:2
A33: 㜸〱捤㔸ぢ㜴ㄴ搵ㄹ摥㍢搹摤散㙥ㅥ㐴〸㤴ㄲ〳ㄱ愴愸㠱㠵㄰㈳て㡢戰搹捤㈶㈱㑦搸〵㐲㡢㕤㘶㜷敦㘴㠷捣散挴㤹搹㤰昵㔱愴ち㐷㝣㔲㝣㐱挱搷㐱㔱昰搹㜲㕡㡦攵㘰〵搴㉡戵搴㥥㡡㐸ぢ搵㔲㐵㐵㌹愵㥣摡㈳攷搴搲晦扦㌳㜹㙤㘶〱㤱㥥攳㑤昶㥦㝢敦㝦敦㜷㕦晦敢㕥ㅢ戱搹㙣愷㈱攱ㄷ㤳ㅤ㌳ㄷ㠷搲㥡㑥㘵慦㕦㤱㈴ㅡ搳㐵㈵愹㜹㝤慡捡愷ㅢ㐵㑤捦㠱〶捥㠸〸㝣捤ㄱ搱挴敢愹㉢搲㐵㔵つㅡ㌹㙣㌶㤷换捤〱ㅦ㐱昰㔷搴㔳㜰㘳慦㝣㍢㤰戰扦扡㈵扡っ㔰㐳扡愲搲㠹㘵ぢ㡤扥戳㉡㉡扣ㄵ摥慡㈹搳愶㝡愷㑣㉣昳愷㈴㍤愵搲㔹㐹㥡搲㔵㕥㥡㔸搶㥡㡡㑡㘲慣㠱愶挳㑡〷㑤捥愲搱㈹㤵㔱晥捡改ㄵ㔷㔶㔵〹㌳㘶㑣捦㠷愱㙤慤晥敡㍡㉡㜵〲摥㠵㐲㜵〲㙡戳扦扡㔵愵挲㠵挲㜴攰㐶㑣ち搰㤸㠸㍢㐶愹㉡㈶摢扤晥㙡昸敦户㉢㔰㥡收㙤〹㠵㘲扣慥㔳ㄵ搷收㤶㕢㘲搱㠵扣㤴愲㑥㤹㑤挷㈵㉦攴搵㘶㕥愶〵昲〲㡤捥攷㤳敤ㄴ㑢づ戹㌶㈵挶敤㜰㡡㌹㤷㕢つ㘲㙥㤰户挵㕦敤㑦昰慡捥㈰㜱㠰㜲慢搶㙣㈴慦㌹つ搶㥥搵攰戶㤰㍣㔳㐶搸㜸㌸挳㕣㈴㉥㈰㑥㌷㤰㤱戵敡㥥挷〴㌱愶㤴挵㘹㔹㐰搴昰㔸昶㙣㔶捡㉡㠸晤摦㈰㙥晤㝢攷㐱㜳㉥挲㜳㤱㈸ㄷ㠹㜱㤱㌸ㄷ愱㕣㐴攰㈲敤㕣㈴挱㐵㐴㉥戲㡣㡢㜴㐰㥢㥥攴捡捤攵捣ㄴ搸昹㥤㥤搷扣戲戴攵戶㕢㌶㠶て慦ㅡ扥㌲ㅦ戱㥡㘱㜱摥㘶慡㕦㈰㈹㜰攰挲捥㝤㌳昳愱戵㐳㌶捥㈲㐰戵㤸ㅢて慡㍥ㄹ愷摤㑥挸挱〱收换㝥㈵愹搳㙥㍤挰敢㝣慥摣捡慢㌴愹扢愱㔱㌹敢㘵攴戰㘷〱慢敢改敤㌱㑢㠰㔰挴戲晤㔰昲㔸㠵㠱㐴㐰敦㜲散〶㜵㌹慤㌴戹㡥搷ㄲ㍡ㅦ㤵攸愵ㄹ㘷㡥晢〶㘲戶㐰ㄷ㈵捤ぢ㤰戵慡㤲敡挴ㅤ扤㔰㌸㑣㤲㔱㍡㥣〵㐰㤸摤挱㉦愴㌹敥㐲愰ㅥ㌷㌲摤挸㐴㥢〴ㅦ㑣㈶㉦㝦㈸攴㘱㡡〱㐵收挵攴〵㍡摣晣㘱〰㍡捦ㄴ攵㠰捡㉦〷㜵散㠳〶㕢㠴㝦㘷户㐷㘰㡥㠴㉡㘱㥡㔰㔱ㄱ慦㥡挲㔷昲づ搴㠳慦愳㔲㘳愰㝤扥扣㐸㑣挶㤵攵㑣挷ち攴㤰挸㈴㈷㠰㌶㌷㕦づ昳㙡㍢〵㜵㔵敢〳ㅥ㤹愹㘲㌸摤㐹昳㘴㥣㜳慢㈲㈶㜵㉤㕦㘶摦㔰㕡㡥㉡㔲㥥㔱〰〳慥愸ㅥ㤳〱愶摡捤摡㌷㡡㐹挸㈱つ㐱㥤㠷攵㔸㑢愳ㄲ㠱㘱昸㠴戲㍣㈸㑡㘰㝦㘸扣㠴㜵昳㉢慡㑡㈵ㅥ摤㠱㕦愱〲㈸户〸㤲㕢㈸〷㔵㐵づ搱愴挶㘶㌵㠲㌵㥤㑦摢㔵慡愱㠵ぢ㔰㥤〷㜱扡戸㥡搷㘸㥦〵㈹ㄷ㡣愵㔶㉢愹㘴㕣㉢戱㘶㠶㜴㕥愷愳㌲㜹㝤㈰㠳扡㠵挰㥡㔲㡤㙤摦攸捣㙥㑣昵㝣摤愲挱㉥捤㘰㠳㑤㔵愲搹戹㐱㤵㕥搷换ㅤ㌴㈳ㅦ㜸挸㉥㡡晣㐱慢㌴㔸挶扣捡晣〹㐵愳㐹㌶扤㜲戹㔵㡣㜵㔰㌵㐴搱扦搲㌸㕢敡㜰㘴挱㜶㈷㘳㔴㉢㙦㐹挲㐲挱愸挷挷昶慦ㄵ㙡扡㜵ち戶㈴づ昳〵㡢慡愷挳愸挷㈳〶㌴㌱挶〴挶㜷〷㔴〷㤵㔸㑡㐳㥢愱㉡搲㐰㡥㉦摥挵挳㤸昱㈶㈵㑥敤㌹㥣摤㐶搰㑦摢㤱搸散昰㠵〴捥㍣㈷〷㙣捡挴っ㡢挱ㅣㄷづ愳昵㜸㠹㝥㈲㡣㙥挲捡晥昴㐶ㄲㄳ戲愳戱㔳㐶㐱挴ㅦ昳㌷挵〳㤵ㄴ㘳ㄳ㐵㐵敤捤㈵戹㔹㜹㤶㘶㝢挰㝣㔱ぢ㝡挷㈰㠴㡣捣ㄸ㘶㍥㥣て㥣㠳㐴㜱㈸㉥搳㘲昶㕢㝦㥦㕣攲㜴捦㌰㜰扦㔳㐱搵挶搶㤷㥤㘵㈳㝡㘵敦晦摢㤸攳㠶㤹慢慦改〲捤慥攳㤳㜱㠹慡㘷㍣㐲㠲㌳㜲ㄷ㈳ㄹ㡥㘴〴㄰挷愷㘰扢捦昵㙣㌱㑡捣敤㐲扦ㄸ㠹㠰㥦㠱ㄲ捡ㅤ㜱㡥〴敡㙣攲㔵㄰㙦挷挷㠰㘷㜹挴㑣㑥㤳ㄸ昶㌰〴㑦㐷㔲㔹づ戶〹〴挳愱愱昱㐰㜰㜷㙥㉥ㅥ㥤〷㝥㘶攲㙣㥣㡤挰晦㔱㠰㐵㘸捦㤲㈵㑢㑣㕦挳搹ㅣㅦ㐱捤ㄹ㑥捦っ㠶㝡挴㘶昰昴㜱㄰㤰㈳㥢攳㐳〰捡㉡㑤㙣㤱摤㈴敤㔸㉥挶昵㠴㌳㐱挵昶㠴㡥㕤㕤㤰㜰扥慦㤸扦户挰㘷ㄶ㐲捣挸戹㑢愱挶㍤ㅡ〹㍡ぢ㡦挷昰㤳㑥㡦晢ㄲ愳㘸㐷て㙡㜵㔸扤晥ㅥ〳ㄹ㑦愳挲挷㠳㝣っ㠲敦㕣㌳昴㜶昹ㄵ戹ㄳ愲㄰戵〸㕢晡挱ち㠰㜵改ㄲ攳㔴㜵㘱〵晡〸㍢㐴摥㥡㤳搹㔰つ挲㡢ㅣ㥢挳㤱攷戲ㅡ慢扥〷敢㔲㔳㤲攰㌴㝡慦㄰昵㠳昰㍦㥦㌷㝤㌶㕥ㄱ㍣ㅥっ㡢摤㘳㤱㡣〳攲㐰㠹晡㕡挶㘶〸㜶㤵㕢㈵㐵挷昹ㄶ捡㝥ㄵ㙥㈸慡挸㌷㡡戲愸て敦㉤㌶愷攴㈸㔵挳挰㤰戴㘱扤戵慤㔴㡤㠱挰昳敤㜴ㄴ㔳攳㝥㐶慣㕣㔸㈸搲攵㘸㈱挶っ㘶㐱攴敤㑦㘹扡挲〲户搱㠳昹〱愵㔹搱㌱昸㤵昸昴愵ㄶ㙣㠳戳㈸㐱㤳攰〰㔴昰〳㘷㙢愴㜴㜶搲戸挵ㅣ㐳㑡ち㔶㔰ㅦ昸㌶戸㄰愶挰㜰ㅡ㌶挲㕣㠶换㥢摤戸昵摣㉣晡㥦ㄵ㥡〰㤷㡢〳ㄵ㈲攷㘷㡤㔰㥥ㅣ㠷㐰昹扥收挰搶慡晣〹〸㈶摡㡥㈱攰〲㠹〷㤳㡤愰愵㘳愶㘵㍣㘴㐶㤹㍦〷㥡㍥换㤰捦〸㔸㝢㙦㜸昵㜱㄰㌵㔱㑦㘳㌰㥣㡦搷扡戰㑡搹摤捤挵ち㉣昸㕡愴愸ㅤ㔱㐵改挰㙢㐴愱㡣㈵㉤㐱愹㡥㜷慤㍣搹戸㈸㘲ㅥ昶㈸㈷㘷挰㔵捡搴㍡㘴㘲戸捣㐲㘹攷〴挸攵〴搵ㄸ㉢㤱〳戰㌵㜸〵ㅢ㕢㝢昷㤳晣慦㤵晡摢㡦晤昸改㤲㙤戳㡥㤰㜷㑤㐶㐳昰搱㕤慤㈷㈶搴㙤㜹慣改搸摦晦㜴戰挶㠱㤶攷㥣㍣㕦ㄱ㌴ㅣ㈲昴㙡㐵㔸搴㈵㥡㈷㌰挱㘷㜹㤷〰㜲づ㜱㑦㍣㔷〸㈷㘰搵㠱〲愱㔶ㄵ攳㤲改㠳㡢㡤愶㡤戴ㅤ㘲㥣㔶㐵ㄳ㌱搴㉣㄰挲㉡㥦搴搰㐰㈵㘳改愱〳㑡捣㈰㌹㠴㙡㌱愹挱㌰㑣ㄳ㌱㍦㐴挰攰ㄵ㉣㑦㑡㑥搶昲㥤摡户㐲㉢㔰㘰㡣挴搴㠲㜰㠴攳㠸㡢㜳㥤愷㤴摢㥣攵㠰收㉥敢戹㘶㐳㠱戳㑤㐵㡡〴っ㉡〸慡〳扤挵ㄹ㝣㔹㐶㈴㠲㌳㠴㑢㐴㕦㄰㥡㘳㘵攱㝢愳㌷收昹㈷㘲㥦㐹㐰收搶㉥愸敦扢㌸㝤愳挷ㅣ〷晡户㜳づ㠹㔰ㄹぢつ挱挱㌰〹㉤戵㥢㥤㍦㤶㌲㠵搱㈳戰㌶㈸㤷㠵㝤搹㈰㐴挵昹㐲㈳ㅦ愵㔲㔰㔱㘵㕥㉦㌴ち㘸戸㘴㜰ㄴ㈶て㕣㥢捣愳愰攱挳〹㤸㉥㠹扡〴㕦㑡㔷㥡挴愴㕢〰挲愴搱慣攲扢愱㡡敦㘶㔵昹挲㝣扣收ㄸ摥ㄳ戰㤴㜶ㅥっ㕥㐲ㄶ㘳㉥㉣攰㔵攴㕢㈱愱㘰搴㔸捣てㅢ㡡㠹㠹㈹搸攱戲っ晢㙤㍣て挰㜱㝢挱㑤攲搶攱昱㠳ㅣ㜳挴〹㝦攴㍣㘳㐸㠸㤹㤸㜹㜲㑦〶㌴〷㝢㌶挴㌷っ㑣㈷㝡ㅥ㈷㑦慣㠰ㅡ挳〴㕦〲昵挸㜶㑦㌱㌳㔸㈸挲昸〱扢㍡㉢㠰㕣攴慦㡥ㄸ愶戲挷攲㍡㔱㌵ち愱扡㥦㡣ㄷ㘱戸㠱㝤摣㤵㐸昰摥㕥㠴㘶扤っ㑢㔵㐸慥㐲㌲つ挹㜴㈴㌳㤰捣㐴㜲㌵㤲敦㈳㤹㠵攴ㅡ㈴戳㤱捣㐱攲㐳㔲㡤挴㡦㈴㠰愴〶㐹㄰㐹㉤㤲㍡㈴昵㐸收㈲㘹㐰搲㠸愴〹㐹㌳㤰〲㈷㐱つ㘳㉢㙤㠱㑣㑦㜲攰㉥㥤昵㘰昰㌴㍤〲ㅥ㔱㐸㑦㑢愰ㄶ㤸㐵㤷㘲攴搸攵㥦搵戱㤰ㄹ摥っ敤㤹昱㙡㙦㕦っ㐹昳㉣㘳㜰攴愰〴㌸㕥〰昷㤱戵㍦慥愰㉦捣挷㍥㤸㥣昳㠰ㄴ㌷㠹㌱㔵搱ㄴ㐱㉦ぢ㠱愱㉦挳摢戲㘰戳㑤昱㤱攷〰㤱〵攸慣㌱㤰㜱戰ㄳ㐵㜸攲戸㌲㜷〸㐸㐱づ愹㠴て晡㕥㘷ㄸ㐸㘹㔸㠹㉢㕡ㄹ晣晢搴敢㔲㘲ㄷ㘴攰晤ㄱ㍣㐸㤴㤷ㄲ㡡ㅢ㥢㌸ㄷ〰㤹敡慦昱㔵㔷愲㑡戲昷っ扣晡㑡捡挲ㅦ昸㈶㌵昱扡㉡㕥ㅦ愷昸愰㈱㐶㐵㐹㡣昳㜱敡敤㤶戴㙥戲捤昴㡦敥㕢㤶㥤㜸敢㕦摢㥢ㅥ戴摤戰戸昸捥搵晢挸㔶㤳㤱昹ㅡ㐹㔰㝥㜰㙡㠶㘴愳ㅢ㌶㕣昰ㄳ㘶㠷㐱㉥昸㜱㤳㤱改㠲〹ち㘱㉦㤲昳㕡㈸攵昸㌴搹㐰㝢捣散㜴昸敤晤㤳搷ㅦ㝦搵晦捣敥㌷昶㌷㝦㜱㔱ㅢ㜹搴㘴ㄴ㝣㐹攷捥摥晣㐹攳收㡢㘷摤摦扤㘴㙤㌱㐱㘹敥㐵㜳㈳㥡㠱昴㔰㌶愴㑤㈶攳戳㤳晦戸㘵敢扥㤳晥扢て㕣扥晡㥤搲敥㕣㠲㉡㘱㠵戴㈱ㅢ搲㝡㤳搱㜲愴攱扤攱㈳㙥っ㍥戳敢捤扦㡤慤昹攲㌲㠲㝡㘵㠵㜴㝦㌶愴晢㑣㐶敤捣㕡晦戸㌱晢晤㙢昶㝣搰㤶㝥㕥晡㈷㐱攵戴㐲晡㘹㌶愴戵㈶㠳敥挹㝢敤㠵㈷摥慣摤昶改㉦㑦愵摢慦㤹㐹㔰挳慤㤰敥捡㠶㜴愷挹㤰ぢ摥㌸㤶晣摥挷捤敢扣昶㔷㥦扢戱㈴㑡搰㑣㔸㈱慤挹㠶㜴㥢挹㜸㝤挵㑢つ㡢㤲挷㝣㥢㍡㑥㉤戳㔷散㝣㤶愰慤戱㐲㕡㤵つ改㔶㤳昱㤷㌵㕤愵ㅢ㙥㥤摤㜰敦改扤摥搱㙦㜶㉣㈱㘸戰慣㤰㔶㘶㐳扡搹㘴㍣㜹摦㔳て搵晤散㐸昰挵〴昷攵戳㉦慤摡㑣搰敡㔹㈱摤㘴㜶㌸晥攸ㄵ㤳ㅦㅦ扡慥㝥攵攱㍦㙦挸摢㜱㙡ㄴ戹搱㘴搴㙦㕢㍣晥㥥慤㘳慡㔷ㅥ㜷晥戶戶敤㜸ㄷ㤹㤳〵㈹㥤つ愹摢㘴㤴晥挷ㅦㄴ挶慣慤摢扥㤵㑥摤㔸扣㜷㈱㐱晢㙢㌵愷㔴㌶㈴摤㘴㜴㑣㠸慤ㄸ㝦愰愸㘹㕤㜱搱扡㈳㙤敦㡣㈰㘸挴慤㤰慥换㠶搴㘹㌲摥㝤㝦攳捣㠳㤵ㅦ㔵㍦ㄸ㝦㍤㄰㥥ㅦㄹ㐷搰ㄳ㔸㈱挹搹㤰㈴㤳戱敢㠶搵摣敤ㅤつ㜳ㅦ昸ㅤ晦昹ㅤㅢ㥦㕡㐴搰㥤㔸㈱㠹搹㤰ㄲ㈶攳㔸㘵摤㡦㌶晣昷㜴攳晤㍢摡昶ㅤ㥤昰昲㈳〴㝤㤲ㄵㄲ捤㠶ㄴ㌷ㄹ㙢攵㤳㥦捣扣慡㙤捥㙦㔶慢㍦㔹扡㜷搷挷〴ㅤ㥢ㄵㄲ㥦つ㘹愹挹〸摤㜱㙢挷ㅢ敤㈳㠳㜷慤晥晤挱捦㡡攴〷〸㝡㐷㉢愴㙢戳㈱㉤㌱ㄹ㍦㙣㕥戵攸挳慦㡥戶慣㈹㜷㙥摡㑤㜷㙢〴㕤慣ㄵ搲㘲戳挳㠹㥤㈵敡愱昵㈷㠳㕢昶扦㍤愲㜸昳㡥㝢㐸㥢挹ㄸ㑦㠷㤵扥攵㥥摥昴戲㍥挹改摤户敢㜹㠲㝥摡ち㘹㐱㌶愴戰挹㐸㙤㝡敦扥㔳㠷㤶〶㙥摥昲㑣敢扡㉦户㍦㑢搰搹㕢㈱捤换㠶搴㙡㌲㜶㑣㜹晡慦㔵㘳ㅡ晣てㄷ㥤ㅥ戵昸攷慦㝤㐵㌰㘲戰㐲㙡捡㠶搴㘸㌲收㙤㙣㤹搱㌵扦愱改挵ㄹ捦ㅦ㈸昹挵摥㠳〴挳づ㉢愴晡㙣㐸㜵㈶㈳扡昶㠳㥢摥晦搵ㄶ摦晡つ挲㔷㝦㜸扦㌴㐴㌰㜶戱㐲慡挹㠶ㄴ㌰ㄹ㥢挳愷戶㕦昱㑡搸晦搲搰挹㉢㘲㜷㔵㍥㐱㌰〰戲㐲昲㘵㐳㥡㘳㌲敥㉤搹㍡敡昰ㅦㅦ㘸㜹㔸㌹㕡昴㠸㌰昷㔰㔱㑦攸攴挰㤰攱敡㡣㜸戶摦ㅢ㙥扦戸戰㍣昳愵扤〶㕥捥搳ㄸ㈸收挰㕢㤸㠳〵昳㜶㙥收昹㘱昵㍣㌸攳ㄵ捡㌱ㅢ㘶晤つ㜰〶㐶㔶㠸㠸搷㈷昷㙥㠴㐶㤲ㄹ戴㘱搴ㄷ挴㜵㘴㍣㍤收攵㘱㔴戶㜵昶愷㜳㝥㍣攷㜶㕦摥晦〰㠲㡥攲㉡
A34: Decisioneering:7.3.0.0

Sheet Balanço Patrimonial
C4: 2016 | D4: =C4+1 -> 2017 | E4: =D4+1 -> 2018 | F4: =E4+1 -> 2019 | G4: =F4+1 -> 2020 | H4: =G4+1 -> 2021 | I4: =H4+1 -> 2022 | J4: =I4+1 -> 2023 | K4: =J4+1 -> 2024 | L4: 2025
B5: Ativo Total | C5: =C6+C21 -> 3631176 | D5: =D6+D21 -> 3394299 | E5: =E6+E21 -> 3478337 | F5: =F6+F21 -> 6037092 | G5: =G6+G21 -> 7309647 | H5: =H6+H21 -> 8672626 | I5: =I6+I21 -> 9629594 | J5: =J6+J21 -> 9725565 | ... L5: =L6+L21 -> 9318633
B6: Ativo Circulante | C6: =C7+C11+C13+C14+C16 -> 2144643 | D6: =D7+D11+D13+D14+D16 -> 2125587 | E6: =E7+E11+E13+E14+E16 -> 2195569 | F6: =F7+F11+F13+F14+F16 -> 2999575 | G6: =G7+G11+G13+G14+G16 -> 3519978 | H6: =H7+H11+H13+H14+H16 -> 3929358 | I6: =I7+I11+I13+I14+I16+I10 -> 4753223 | J6: =J7+J11+J13+J14+J16+J10 -> 4441842 | K6: =K7+K11+K13+K14+K16+K10 -> 4993393 | L6: =L7+L11+L13+L14+L16+L10 -> 4559829
B7: Caixa e Equivalentes de Caixa | C7: 489705 | D7: 431759 | E7: 446006 | F7: 447109 | G7: 1509159 | H7: 1050251 | I7: 1674091 | J7: 1155588 | K7: 1403225 | L7: 774521
B8: Caixa Operacional | C8: =(-'DRE + DCF'!C14-'DRE + DCF'!C23-'DRE + DCF'!C95)/24 -> 196789.38 | D8: =(-'DRE + DCF'!D14-'DRE + DCF'!D23-'DRE + DCF'!D95)/24 -> 198442.21 | E8: =(-'DRE + DCF'!E14-'DRE + DCF'!E23-'DRE + DCF'!E95)/24 -> 200913.67 | F8: =(-'DRE + DCF'!F14-'DRE + DCF'!F23-'DRE + DCF'!F95)/24 -> 194499.67 | G8: =(-'DRE + DCF'!G14-'DRE + DCF'!G23-'DRE + DCF'!G95)/24 -> 173032.96 | H8: =(-'DRE + DCF'!H14-'DRE + DCF'!H23-'DRE + DCF'!H95)/24 -> 197077.5 | I8: =(-'DRE + DCF'!I14-'DRE + DCF'!I23-'DRE + DCF'!I95)/24 -> 244278.04 | J8: =(-'DRE + DCF'!J14-'DRE + DCF'!J23-'DRE + DCF'!J95)/24 -> 262354.17 | ... L8: =(-'DRE + DCF'!L14-'DRE + DCF'!L23-'DRE + DCF'!L95)/24 -> 303898.14
B9: Excesso de caixa | C9: =C7+C10-C8 -> 292915.62 | D9: =D7+D10-D8 -> 233316.79 | E9: =E7+E10-E8 -> 245092.33 | F9: =F7+F10-F8 -> 252609.33 | G9: =G7+G10-G8 -> 1336126 | H9: =H7+H10-H8 -> 853173.5 | I9: =I7+I10-I8 -> 1438548 | J9: =J7+J10-J8 -> 1084820.8 | ... L9: =L7+L10-L8 -> 739476.86
B10: Aplicações Financeiras | C10: 0 | D10: 0 | E10: 0 | F10: 0 | G10: 0 | H10: 0 | I10: 8735 | J10: 191587 | K10: 169310 | L10: 268854
B11: Contas a Receber | C11: 1013011 | D11: 1070690 | E11: 1142836 | F11: 1151484 | G11: 1063844 | H11: 1145336 | I11: 1278206 | J11: 1778456 | K11: 1862821 | L11: 1753283
B12: Clientes | C12: 1013011 | D12: 1070690 | E12: 1142836 | F12: 1151484 | G12: 1063844 | H12: 1145336 | I12: 1278206 | J12: 1778456 | K12: 1862821 | L12: 1753283
B13: Estoques | C13: 536579 | D13: 479427 | E13: 490614 | F13: 544717 | G13: 641020 | H13: 849269 | I13: 852033 | J13: 875155 | K13: 1032231 | L13: 1154866
B14: Tributos a Recuperar | C14: 55725 | D14: 72877 | E14: 42847 | F14: 833649 | G14: 282660 | H14: 849115 | I14: 899433 | J14: 388451 | K14: 470354 | L14: 569544
B15: Tributos Correntes a Recuperar | C15: 55725 | D15: 7287 | E15: 42847 | F15: 833649 | G15: 282660 | H15: 849115 | I15: 899433 | J15: 388451 | K15: 470354 | L15: 569544
B16: Outros Ativos Circulantes | C16: 49623 | D16: 70834 | E16: 73266 | F16: 22616 | G16: 23295 | H16: 35387 | I16: 40725 | J16: 52605 | K16: 55452 | L16: =L17 -> 38761
B17: Outros | C17: 49623 | D17: 70834 | E17: 73266 | F17: 22616 | G17: 23295 | H17: 35387 | I17: 40725 | J17: 52605 | K17: 55452 | L17: =L18+L19 -> 38761
B18: Outros Créditos | C18: 13393 | D18: 15968 | E18: 17940 | F18: 21609 | G18: 22933 | H18: 33348 | I18: 39259 | J18: 51884 | K18: 37197 | L18: 36209
B19: Instrumentos Financeiros Derivativos | C19: 35463 | D19: 53835 | E19: 55067 | F19: 651 | G19: 238 | H19: 1535 | I19: 1371 | J19: 721 | K19: 18255 | L19: 2552
B20: Partes Relacionadas | C20: 767 | D20: 1031 | E20: 259 | F20: 356 | G20: 124 | H20: 504 | I20: 95 | J20: 0 | K20: 0 | L20: 0
B21: Ativo Não Circulante | C21: =C22+C31+C35 -> 1486533 | D21: =D22+D31+D35 -> 1268712 | E21: =E22+E31+E35 -> 1282768 | F21: =F22+F31+F35 -> 3037517 | G21: =G22+G31+G35 -> 3789669 | H21: =H22+H31+H35 -> 4743268 | I21: =I22+I31+I35 -> 4876371 | J21: =J22+J31+J35 -> 5283723 | ... L21: =L22+L31+L35 -> 4758804
B22: Ativo Realizável a Longo Prazo | C22: 546237 | D22: 457050 | E22: 448943 | F22: 624950 | G22: 1313046 | H22: 1291014 | I22: 1424314 | J22: 1899582 | K22: 1814076 | L22: 1377087
B23: Aplicações Financeiras | C23: 0 | D23: 0 | E23: 0 | F23: 0 | G23: 0 | H23: 0 | I23: 0 | J23: 0 | K23: 0 | L23: 0
B24: Tributos Diferidos | C24: 440059 | D24: 398811 | E24: 370643 | F24: 0 | G24: 71492 | H24: 378803 | I24: 423049 | J24: 547087 | K24: 530141 | L24: 489748
